Workbook

Sheet Instructions
A1: How this workbook works
A3: 1. Log sheet
A4: Each day, add one new row per camera to the table (just type into the row directly below the last one - the table expands automatically).
A5: Columns: Date, Camera, Wand Count, World Error, Image Error.
A6: The Camera column has a dropdown so names stay consistent.
A8: 2. Daily Summary sheet
A9: Automatically averages World Error and Image Error across all cameras for each date, and counts how many cameras were logged that day (flags red if it isn't 17, so you notice a missed camera). Pre-built with formulas for the next ~150 days - nothing to edit.
A10: Chart: average error trend over time, across the whole rig.
A12: 3. Camera Trend sheet
A13: Pick a camera from the dropdown in the highlighted cell and its own error history over time appears in the table and chart below. Useful for spotting a camera that's drifting or degrading.
A15: 4. Lists sheet
A16: Just holds the camera name list that powers the dropdowns. Hidden by default - unhide it (right-click any sheet tab) if you add or retire a camera.
A18: Cells you edit day-to-day are highlighted in pale yellow. Everything else is a formula and updates itself.

Sheet Lists
A1: Camera
A2: #1 (Vero v2.2)
A3: #2 (Vero v2.2)
A4: #3 (Vero v2.2)
A5: #4 (Vero v2.2)
A6: #5 (Vero v2.2)
A7: #6 (Vero v2.2)
A8: #7 (Vero v2.2)
A9: #8 (Vero v2.2)
A10: #9 (Vero v2.2)
A11: #10 (Vero v2.2)
A12: #11 (Vero v2.2)
... A19: #18 (Vero v2.2)

Sheet Camera Labelling
B2: Cameras in the INB Robotics/Vicon lab are labelled differently to the Nexus software, I've recorded the differences here
B3: For future reference, if this is ever corrected - the files here will need to be corrected
B5: Camera Name | C5: Nexus Software ID | D5: Physical Label | E5: Match
B6: #1 (Vero v2.2) | C6: 1 | D6: 1 | E6: =IF(C6=D6, "Yes", "No") -> Yes
B7: #2 (Vero v2.2) | C7: 2 | D7: 2 | E7: =IF(C7=D7, "Yes", "No") -> Yes
B8: #3 (Vero v2.2) | C8: 3 | D8: 4 | E8: =IF(C8=D8, "Yes", "No") -> No
B9: #4 (Vero v2.2) | C9: 4 | D9: 18 | E9: =IF(C9=D9, "Yes", "No") -> No
B10: #5 (Vero v2.2) | C10: 5 | D10: 5 | E10: =IF(C10=D10, "Yes", "No") -> Yes
B11: #6 (Vero v2.2) | C11: 6 | D11: 6 | E11: =IF(C11=D11, "Yes", "No") -> Yes
B12: #7 (Vero v2.2) | C12: 7 | D12: 7 | E12: =IF(C12=D12, "Yes", "No") -> Yes
B13: #8 (Vero v2.2) | C13: 8 | D13: 8 | E13: =IF(C13=D13, "Yes", "No") -> Yes
B14: #9 (Vero v2.2) | C14: 9 | D14: 14 | E14: =IF(C14=D14, "Yes", "No") -> No
B15: #10 (Vero v2.2) | C15: 10 | D15: 10 | E15: =IF(C15=D15, "Yes", "No") -> Yes
B16: #11 (Vero v2.2) | C16: 11 | D16: 11 | E16: =IF(C16=D16, "Yes", "No") -> Yes
B17: #12 (Vero v2.2) | C17: 12 | D17: 12 | E17: =IF(C17=D17, "Yes", "No") -> Yes
... B23: #18 (Vero v2.2) | C23: 18 | D23: 17 | E23: =IF(C23=D23, "Yes", "No") -> No

Sheet Log
A1: Add new rows below the table - one per camera, each day. | D1: Camera Error (This Day) | F1: Average Errors (This Day) | H1: Beats average?
A2: Date | B2: Camera | C2: Wand Count | D2: World Error | E2: Image Error | F2: World Error (Avg.) | G2: Image Error (Avg.) | H2: World | I2: Image
A3: 46228 | B3: #1 (Vero v2.2) | C3: 2306 | D3: 0.274982 | E3: 0.0793568 | F3: =_xlfn.XLOOKUP(CalibrationLog[[#This Row],[Date]], 'Daily Summary'!A:A, 'Daily Summary'!H:H, "n/a") -> 0.39118376 | G3: =_xlfn.XLOOKUP(CalibrationLog[[#This Row],[Date]], 'Daily Summary'!A:A, 'Daily Summary'!K:K, "n/a") -> 0.0922785 | H3: =IF(CalibrationLog[[#This Row],[Date]]="", "", IF(CalibrationLog[[#This Row],[World Error]]<CalibrationLog[[#This Row],[World Error (Avg.)]], "Yes", "No")) -> Yes | I3: =IF(CalibrationLog[[#This Row],[Date]]="", "", IF(CalibrationLog[[#This Row],[Image Error]]<G3, "Yes", "No")) -> Yes
A4: 46228 | B4: #2 (Vero v2.2) | C4: 2392 | D4: 0.421843 | E4: 0.112306 | F4: =_xlfn.XLOOKUP(CalibrationLog[[#This Row],[Date]], 'Daily Summary'!A:A, 'Daily Summary'!H:H, "n/a") -> 0.39118376 | G4: =_xlfn.XLOOKUP(CalibrationLog[[#This Row],[Date]], 'Daily Summary'!A:A, 'Daily Summary'!K:K, "n/a") -> 0.0922785 | H4: =IF(CalibrationLog[[#This Row],[Date]]="", "", IF(CalibrationLog[[#This Row],[World Error]]<CalibrationLog[[#This Row],[World Error (Avg.)]], "Yes", "No")) -> No | I4: =IF(CalibrationLog[[#This Row],[Date]]="", "", IF(CalibrationLog[[#This Row],[Image Error]]<G4, "Yes", "No")) -> No
A5: 46228 | B5: #3 (Vero v2.2) | C5: 1810 | D5: 0.398584 | E5: 0.0924275 | F5: =_xlfn.XLOOKUP(CalibrationLog[[#This Row],[Date]], 'Daily Summary'!A:A, 'Daily Summary'!H:H, "n/a") -> 0.39118376 | G5: =_xlfn.XLOOKUP(CalibrationLog[[#This Row],[Date]], 'Daily Summary'!A:A, 'Daily Summary'!K:K, "n/a") -> 0.0922785 | H5: =IF(CalibrationLog[[#This Row],[Date]]="", "", IF(CalibrationLog[[#This Row],[World Error]]<CalibrationLog[[#This Row],[World Error (Avg.)]], "Yes", "No")) -> No | I5: =IF(CalibrationLog[[#This Row],[Date]]="", "", IF(CalibrationLog[[#This Row],[Image Error]]<G5, "Yes", "No")) -> No
A6: 46228 | B6: #4 (Vero v2.2) | C6: 2277 | D6: 0.620036 | E6: 0.121579 | F6: =_xlfn.XLOOKUP(CalibrationLog[[#This Row],[Date]], 'Daily Summary'!A:A, 'Daily Summary'!H:H, "n/a") -> 0.39118376 | G6: =_xlfn.XLOOKUP(CalibrationLog[[#This Row],[Date]], 'Daily Summary'!A:A, 'Daily Summary'!K:K, "n/a") -> 0.0922785 | H6: =IF(CalibrationLog[[#This Row],[Date]]="", "", IF(CalibrationLog[[#This Row],[World Error]]<CalibrationLog[[#This Row],[World Error (Avg.)]], "Yes", "No")) -> No | I6: =IF(CalibrationLog[[#This Row],[Date]]="", "", IF(CalibrationLog[[#This Row],[Image Error]]<G6, "Yes", "No")) -> No
A7: 46228 | B7: #5 (Vero v2.2) | C7: 2240 | D7: 0.191893 | E7: 0.0443669 | F7: =_xlfn.XLOOKUP(CalibrationLog[[#This Row],[Date]], 'Daily Summary'!A:A, 'Daily Summary'!H:H, "n/a") -> 0.39118376 | G7: =_xlfn.XLOOKUP(CalibrationLog[[#This Row],[Date]], 'Daily Summary'!A:A, 'Daily Summary'!K:K, "n/a") -> 0.0922785 | H7: =IF(CalibrationLog[[#This Row],[Date]]="", "", IF(CalibrationLog[[#This Row],[World Error]]<CalibrationLog[[#This Row],[World Error (Avg.)]], "Yes", "No")) -> Yes | I7: =IF(CalibrationLog[[#This Row],[Date]]="", "", IF(CalibrationLog[[#This Row],[Image Error]]<G7, "Yes", "No")) -> Yes
A8: 46228 | B8: #6 (Vero v2.2) | C8: 2754 | D8: 0.442235 | E8: 0.0899754 | F8: =_xlfn.XLOOKUP(CalibrationLog[[#This Row],[Date]], 'Daily Summary'!A:A, 'Daily Summary'!H:H, "n/a") -> 0.39118376 | G8: =_xlfn.XLOOKUP(CalibrationLog[[#This Row],[Date]], 'Daily Summary'!A:A, 'Daily Summary'!K:K, "n/a") -> 0.0922785 | H8: =IF(CalibrationLog[[#This Row],[Date]]="", "", IF(CalibrationLog[[#This Row],[World Error]]<CalibrationLog[[#This Row],[World Error (Avg.)]], "Yes", "No")) -> No | I8: =IF(CalibrationLog[[#This Row],[Date]]="", "", IF(CalibrationLog[[#This Row],[Image Error]]<G8, "Yes", "No")) -> Yes
A9: 46228 | B9: #7 (Vero v2.2) | C9: 3007 | D9: 0.509896 | E9: 0.102799 | F9: =_xlfn.XLOOKUP(CalibrationLog[[#This Row],[Date]], 'Daily Summary'!A:A, 'Daily Summary'!H:H, "n/a") -> 0.39118376 | G9: =_xlfn.XLOOKUP(CalibrationLog[[#This Row],[Date]], 'Daily Summary'!A:A, 'Daily Summary'!K:K, "n/a") -> 0.0922785 | H9: =IF(CalibrationLog[[#This Row],[Date]]="", "", IF(CalibrationLog[[#This Row],[World Error]]<CalibrationLog[[#This Row],[World Error (Avg.)]], "Yes", "No")) -> No | I9: =IF(CalibrationLog[[#This Row],[Date]]="", "", IF(CalibrationLog[[#This Row],[Image Error]]<G9, "Yes", "No")) -> No
A10: 46228 | B10: #9 (Vero v2.2) | C10: 2832 | D10: 0.395935 | E10: 0.0795796 | F10: =_xlfn.XLOOKUP(CalibrationLog[[#This Row],[Date]], 'Daily Summary'!A:A, 'Daily Summary'!H:H, "n/a") -> 0.39118376 | G10: =_xlfn.XLOOKUP(CalibrationLog[[#This Row],[Date]], 'Daily Summary'!A:A, 'Daily Summary'!K:K, "n/a") -> 0.0922785 | H10: =IF(CalibrationLog[[#This Row],[Date]]="", "", IF(CalibrationLog[[#This Row],[World Error]]<CalibrationLog[[#This Row],[World Error (Avg.)]], "Yes", "No")) -> No | I10: =IF(CalibrationLog[[#This Row],[Date]]="", "", IF(CalibrationLog[[#This Row],[Image Error]]<G10, "Yes", "No")) -> Yes
A11: 46228 | B11: #10 (Vero v2.2) | C11: 2120 | D11: 0.499606 | E11: 0.132037 | F11: =_xlfn.XLOOKUP(CalibrationLog[[#This Row],[Date]], 'Daily Summary'!A:A, 'Daily Summary'!H:H, "n/a") -> 0.39118376 | G11: =_xlfn.XLOOKUP(CalibrationLog[[#This Row],[Date]], 'Daily Summary'!A:A, 'Daily Summary'!K:K, "n/a") -> 0.0922785 | H11: =IF(CalibrationLog[[#This Row],[Date]]="", "", IF(CalibrationLog[[#This Row],[World Error]]<CalibrationLog[[#This Row],[World Error (Avg.)]], "Yes", "No")) -> No | I11: =IF(CalibrationLog[[#This Row],[Date]]="", "", IF(CalibrationLog[[#This Row],[Image Error]]<G11, "Yes", "No")) -> No
A12: 46228 | B12: #11 (Vero v2.2) | C12: 1471 | D12: 0.130593 | E12: 0.0450561 | F12: =_xlfn.XLOOKUP(CalibrationLog[[#This Row],[Date]], 'Daily Summary'!A:A, 'Daily Summary'!H:H, "n/a") -> 0.39118376 | G12: =_xlfn.XLOOKUP(CalibrationLog[[#This Row],[Date]], 'Daily Summary'!A:A, 'Daily Summary'!K:K, "n/a") -> 0.0922785 | H12: =IF(CalibrationLog[[#This Row],[Date]]="", "", IF(CalibrationLog[[#This Row],[World Error]]<CalibrationLog[[#This Row],[World Error (Avg.)]], "Yes", "No")) -> Yes | I12: =IF(CalibrationLog[[#This Row],[Date]]="", "", IF(CalibrationLog[[#This Row],[Image Error]]<G12, "Yes", "No")) -> Yes
A13: 46228 | B13: #12 (Vero v2.2) | C13: 1657 | D13: 0.428371 | E13: 0.140663 | F13: =_xlfn.XLOOKUP(CalibrationLog[[#This Row],[Date]], 'Daily Summary'!A:A, 'Daily Summary'!H:H, "n/a") -> 0.39118376 | G13: =_xlfn.XLOOKUP(CalibrationLog[[#This Row],[Date]], 'Daily Summary'!A:A, 'Daily Summary'!K:K, "n/a") -> 0.0922785 | H13: =IF(CalibrationLog[[#This Row],[Date]]="", "", IF(CalibrationLog[[#This Row],[World Error]]<CalibrationLog[[#This Row],[World Error (Avg.)]], "Yes", "No")) -> No | I13: =IF(CalibrationLog[[#This Row],[Date]]="", "", IF(CalibrationLog[[#This Row],[Image Error]]<G13, "Yes", "No")) -> No
A14: 46228 | B14: #13 (Vero v2.2) | C14: 1007 | D14: 0.168386 | E14: 0.0424158 | F14: =_xlfn.XLOOKUP(CalibrationLog[[#This Row],[Date]], 'Daily Summary'!A:A, 'Daily Summary'!H:H, "n/a") -> 0.39118376 | G14: =_xlfn.XLOOKUP(CalibrationLog[[#This Row],[Date]], 'Daily Summary'!A:A, 'Daily Summary'!K:K, "n/a") -> 0.0922785 | H14: =IF(CalibrationLog[[#This Row],[Date]]="", "", IF(CalibrationLog[[#This Row],[World Error]]<CalibrationLog[[#This Row],[World Error (Avg.)]], "Yes", "No")) -> Yes | I14: =IF(CalibrationLog[[#This Row],[Date]]="", "", IF(CalibrationLog[[#This Row],[Image Error]]<G14, "Yes", "No")) -> Yes
... A145: 46237 | B145: #18 (Vero v2.2) | C145: 1257 | D145: 0.79733 | E145: 0.15169 | F145: =_xlfn.XLOOKUP(CalibrationLog[[#This Row],[Date]], 'Daily Summary'!A:A, 'Daily Summary'!H:H, "n/a") -> 0.37600283 | G145: =_xlfn.XLOOKUP(CalibrationLog[[#This Row],[Date]], 'Daily Summary'!A:A, 'Daily Summary'!K:K, "n/a") -> 0.0903465 | H145: =IF(CalibrationLog[[#This Row],[Date]]="", "", IF(CalibrationLog[[#This Row],[World Error]]<CalibrationLog[[#This Row],[World Error (Avg.)]], "Yes", "No")) -> No | I145: =IF(CalibrationLog[[#This Row],[Date]]="", "", IF(CalibrationLog[[#This Row],[Image Error]]<G145, "Yes", "No")) -> No
F146: =_xlfn.XLOOKUP(CalibrationLog[[#This Row],[Date]], 'Daily Summary'!A:A, 'Daily Summary'!H:H, "n/a") -> WE Average | G146: =_xlfn.XLOOKUP(CalibrationLog[[#This Row],[Date]], 'Daily Summary'!A:A, 'Daily Summary'!K:K, "n/a") -> IE Average | H146: =IF(CalibrationLog[[#This Row],[Date]]="", "", IF(CalibrationLog[[#This Row],[World Error]]<CalibrationLog[[#This Row],[World Error (Avg.)]], "Yes", "No")) | I146: =IF(CalibrationLog[[#This Row],[Date]]="", "", IF(CalibrationLog[[#This Row],[Image Error]]<G146, "Yes", "No"))
F147: =_xlfn.XLOOKUP(CalibrationLog[[#This Row],[Date]], 'Daily Summary'!A:A, 'Daily Summary'!H:H, "n/a") -> WE Average | G147: =_xlfn.XLOOKUP(CalibrationLog[[#This Row],[Date]], 'Daily Summary'!A:A, 'Daily Summary'!K:K, "n/a") -> IE Average | H147: =IF(CalibrationLog[[#This Row],[Date]]="", "", IF(CalibrationLog[[#This Row],[World Error]]<CalibrationLog[[#This Row],[World Error (Avg.)]], "Yes", "No")) | I147: =IF(CalibrationLog[[#This Row],[Date]]="", "", IF(CalibrationLog[[#This Row],[Image Error]]<G147, "Yes", "No"))
F148: =_xlfn.XLOOKUP(CalibrationLog[[#This Row],[Date]], 'Daily Summary'!A:A, 'Daily Summary'!H:H, "n/a") -> WE Average | G148: =_xlfn.XLOOKUP(CalibrationLog[[#This Row],[Date]], 'Daily Summary'!A:A, 'Daily Summary'!K:K, "n/a") -> IE Average | H148: =IF(CalibrationLog[[#This Row],[Date]]="", "", IF(CalibrationLog[[#This Row],[World Error]]<CalibrationLog[[#This Row],[World Error (Avg.)]], "Yes", "No")) | I148: =IF(CalibrationLog[[#This Row],[Date]]="", "", IF(CalibrationLog[[#This Row],[Image Error]]<G148, "Yes", "No"))
F149: =_xlfn.XLOOKUP(CalibrationLog[[#This Row],[Date]], 'Daily Summary'!A:A, 'Daily Summary'!H:H, "n/a") -> WE Average | G149: =_xlfn.XLOOKUP(CalibrationLog[[#This Row],[Date]], 'Daily Summary'!A:A, 'Daily Summary'!K:K, "n/a") -> IE Average | H149: =IF(CalibrationLog[[#This Row],[Date]]="", "", IF(CalibrationLog[[#This Row],[World Error]]<CalibrationLog[[#This Row],[World Error (Avg.)]], "Yes", "No")) | I149: =IF(CalibrationLog[[#This Row],[Date]]="", "", IF(CalibrationLog[[#This Row],[Image Error]]<G149, "Yes", "No"))
F150: =_xlfn.XLOOKUP(CalibrationLog[[#This Row],[Date]], 'Daily Summary'!A:A, 'Daily Summary'!H:H, "n/a") -> WE Average | G150: =_xlfn.XLOOKUP(CalibrationLog[[#This Row],[Date]], 'Daily Summary'!A:A, 'Daily Summary'!K:K, "n/a") -> IE Average | H150: =IF(CalibrationLog[[#This Row],[Date]]="", "", IF(CalibrationLog[[#This Row],[World Error]]<CalibrationLog[[#This Row],[World Error (Avg.)]], "Yes", "No")) | I150: =IF(CalibrationLog[[#This Row],[Date]]="", "", IF(CalibrationLog[[#This Row],[Image Error]]<G150, "Yes", "No"))
F151: =_xlfn.XLOOKUP(CalibrationLog[[#This Row],[Date]], 'Daily Summary'!A:A, 'Daily Summary'!H:H, "n/a") -> WE Average | G151: =_xlfn.XLOOKUP(CalibrationLog[[#This Row],[Date]], 'Daily Summary'!A:A, 'Daily Summary'!K:K, "n/a") -> IE Average | H151: =IF(CalibrationLog[[#This Row],[Date]]="", "", IF(CalibrationLog[[#This Row],[World Error]]<CalibrationLog[[#This Row],[World Error (Avg.)]], "Yes", "No")) | I151: =IF(CalibrationLog[[#This Row],[Date]]="", "", IF(CalibrationLog[[#This Row],[Image Error]]<G151, "Yes", "No"))
F152: =_xlfn.XLOOKUP(CalibrationLog[[#This Row],[Date]], 'Daily Summary'!A:A, 'Daily Summary'!H:H, "n/a") -> WE Average | G152: =_xlfn.XLOOKUP(CalibrationLog[[#This Row],[Date]], 'Daily Summary'!A:A, 'Daily Summary'!K:K, "n/a") -> IE Average | H152: =IF(CalibrationLog[[#This Row],[Date]]="", "", IF(CalibrationLog[[#This Row],[World Error]]<CalibrationLog[[#This Row],[World Error (Avg.)]], "Yes", "No")) | I152: =IF(CalibrationLog[[#This Row],[Date]]="", "", IF(CalibrationLog[[#This Row],[Image Error]]<G152, "Yes", "No"))
F153: =_xlfn.XLOOKUP(CalibrationLog[[#This Row],[Date]], 'Daily Summary'!A:A, 'Daily Summary'!H:H, "n/a") -> WE Average | G153: =_xlfn.XLOOKUP(CalibrationLog[[#This Row],[Date]], 'Daily Summary'!A:A, 'Daily Summary'!K:K, "n/a") -> IE Average | H153: =IF(CalibrationLog[[#This Row],[Date]]="", "", IF(CalibrationLog[[#This Row],[World Error]]<CalibrationLog[[#This Row],[World Error (Avg.)]], "Yes", "No")) | I153: =IF(CalibrationLog[[#This Row],[Date]]="", "", IF(CalibrationLog[[#This Row],[Image Error]]<G153, "Yes", "No"))
F154: =_xlfn.XLOOKUP(CalibrationLog[[#This Row],[Date]], 'Daily Summary'!A:A, 'Daily Summary'!H:H, "n/a") -> WE Average | G154: =_xlfn.XLOOKUP(CalibrationLog[[#This Row],[Date]], 'Daily Summary'!A:A, 'Daily Summary'!K:K, "n/a") -> IE Average | H154: =IF(CalibrationLog[[#This Row],[Date]]="", "", IF(CalibrationLog[[#This Row],[World Error]]<CalibrationLog[[#This Row],[World Error (Avg.)]], "Yes", "No")) | I154: =IF(CalibrationLog[[#This Row],[Date]]="", "", IF(CalibrationLog[[#This Row],[Image Error]]<G154, "Yes", "No"))
F155: =_xlfn.XLOOKUP(CalibrationLog[[#This Row],[Date]], 'Daily Summary'!A:A, 'Daily Summary'!H:H, "n/a") -> WE Average | G155: =_xlfn.XLOOKUP(CalibrationLog[[#This Row],[Date]], 'Daily Summary'!A:A, 'Daily Summary'!K:K, "n/a") -> IE Average | H155: =IF(CalibrationLog[[#This Row],[Date]]="", "", IF(CalibrationLog[[#This Row],[World Error]]<CalibrationLog[[#This Row],[World Error (Avg.)]], "Yes", "No")) | I155: =IF(CalibrationLog[[#This Row],[Date]]="", "", IF(CalibrationLog[[#This Row],[Image Error]]<G155, "Yes", "No"))
F156: =_xlfn.XLOOKUP(CalibrationLog[[#This Row],[Date]], 'Daily Summary'!A:A, 'Daily Summary'!H:H, "n/a") -> WE Average | G156: =_xlfn.XLOOKUP(CalibrationLog[[#This Row],[Date]], 'Daily Summary'!A:A, 'Daily Summary'!K:K, "n/a") -> IE Average | H156: =IF(CalibrationLog[[#This Row],[Date]]="", "", IF(CalibrationLog[[#This Row],[World Error]]<CalibrationLog[[#This Row],[World Error (Avg.)]], "Yes", "No")) | I156: =IF(CalibrationLog[[#This Row],[Date]]="", "", IF(CalibrationLog[[#This Row],[Image Error]]<G156, "Yes", "No"))
F157: =_xlfn.XLOOKUP(CalibrationLog[[#This Row],[Date]], 'Daily Summary'!A:A, 'Daily Summary'!H:H, "n/a") -> WE Average | G157: =_xlfn.XLOOKUP(CalibrationLog[[#This Row],[Date]], 'Daily Summary'!A:A, 'Daily Summary'!K:K, "n/a") -> IE Average | H157: =IF(CalibrationLog[[#This Row],[Date]]="", "", IF(CalibrationLog[[#This Row],[World Error]]<CalibrationLog[[#This Row],[World Error (Avg.)]], "Yes", "No")) | I157: =IF(CalibrationLog[[#This Row],[Date]]="", "", IF(CalibrationLog[[#This Row],[Image Error]]<G157, "Yes", "No"))
... F229: =_xlfn.XLOOKUP(CalibrationLog[[#This Row],[Date]], 'Daily Summary'!A:A, 'Daily Summary'!H:H, "n/a") -> WE Average | G229: =_xlfn.XLOOKUP(CalibrationLog[[#This Row],[Date]], 'Daily Summary'!A:A, 'Daily Summary'!K:K, "n/a") -> IE Average | H229: =IF(CalibrationLog[[#This Row],[Date]]="", "", IF(CalibrationLog[[#This Row],[World Error]]<CalibrationLog[[#This Row],[World Error (Avg.)]], "Yes", "No")) | I229: =IF(CalibrationLog[[#This Row],[Date]]="", "", IF(CalibrationLog[[#This Row],[Image Error]]<G229, "Yes", "No"))

Sheet Daily Summary
A1: Date | B1: Starting Temperature | C1: Cameras Logged | D1: Starting Time | E1: Min Wand Count Setting | F1: Avg Wand Count | G1: Count as Proportion | H1: World Error | K1: Image Error | N1: Notes on daily calibration attempt
H2: WE Average | I2: Lowest WE | J2: Highest WE | K2: IE Average | L2: Lowest IE | M2: Highest IE
A3: 46228 | B3: 23.5 | C3: =COUNTIFS(Log!$A:$A,$A3) -> 17 | D3: 0.85833333 | E3: 1000 | F3: =IF(AND(A3<>"", B3<>""), IFERROR(AVERAGEIFS(Log!$C:$C,Log!$A:$A,$A3),""), "") -> 2045.4118 | G3: =IF(AND(F3<>"", E3<>""), F3/E3, "") -> 2.0454118 | H3: =IF(AND(A3<>"", B3<>""), IFERROR(AVERAGEIFS(Log!$D:$D,Log!$A:$A,$A3),""), "") -> 0.39118376 | I3: =IF(AND(A3<>"",B3<>""),IFERROR(_xlfn.MINIFS(Log!$D:$D,Log!$A:$A,$A3),""),"") -> 0.130593 | J3: =IF(AND(A3<>"",B3<>""),IFERROR(_xlfn.MAXIFS(Log!$D:$D,Log!$A:$A,$A3),""),"") -> 0.647959 | K3: =IF(AND(A3<>"", B3<>""), IFERROR(AVERAGEIFS(Log!$E:$E,Log!$A:$A,$A3),""), "") -> 0.0922785 | L3: =IF(AND(A3<>"", B3<>""), IFERROR(_xlfn.MINIFS(Log!$E:$E,Log!$A:$A,$A3),""), "") -> 0.0424158 | M3: =IF(AND(A3<>"", B3<>""), IFERROR(_xlfn.MAXIFS(Log!$E:$E,Log!$A:$A,$A3),""), "") -> 0.147318 | N3: Camera 8 not enabled by mistake, no masking or marker removal attempted - attempting to establish baselines
A4: =A3+1 -> 46229 | C4: =COUNTIFS(Log!$A:$A,$A4) -> 0 | F4: =IF(AND(A4<>"", B4<>""), IFERROR(AVERAGEIFS(Log!$C:$C,Log!$A:$A,$A4),""), "") | G4: =IF(AND(F4<>"", E4<>""), F4/E4, "") | H4: =IF(AND(A4<>"", B4<>""), IFERROR(AVERAGEIFS(Log!$D:$D,Log!$A:$A,$A4),""), "") | I4: =IF(AND(A4<>"",B4<>""),IFERROR(_xlfn.MINIFS(Log!$D:$D,Log!$A:$A,$A4),""),"") | J4: =IF(AND(A4<>"",B4<>""),IFERROR(_xlfn.MAXIFS(Log!$D:$D,Log!$A:$A,$A4),""),"") | K4: =IF(AND(A4<>"", B4<>""), IFERROR(AVERAGEIFS(Log!$E:$E,Log!$A:$A,$A4),""), "") | L4: =IF(AND(A4<>"", B4<>""), IFERROR(_xlfn.MINIFS(Log!$E:$E,Log!$A:$A,$A4),""), "") | M4: =IF(AND(A4<>"", B4<>""), IFERROR(_xlfn.MAXIFS(Log!$E:$E,Log!$A:$A,$A4),""), "")
A5: =A4+1 -> 46230 | B5: 23.5 | C5: =COUNTIFS(Log!$A:$A,$A5) -> 18 | D5: 0.60138889 | E5: 1000 | F5: =IF(AND(A5<>"", B5<>""), IFERROR(AVERAGEIFS(Log!$C:$C,Log!$A:$A,$A5),""), "") -> 1582.8333 | G5: =IF(AND(F5<>"", E5<>""), F5/E5, "") -> 1.5828333 | H5: =IF(AND(A5<>"", B5<>""), IFERROR(AVERAGEIFS(Log!$D:$D,Log!$A:$A,$A5),""), "") -> 0.38041772 | I5: =IF(AND(A5<>"",B5<>""),IFERROR(_xlfn.MINIFS(Log!$D:$D,Log!$A:$A,$A5),""),"") -> 0.162101 | J5: =IF(AND(A5<>"",B5<>""),IFERROR(_xlfn.MAXIFS(Log!$D:$D,Log!$A:$A,$A5),""),"") -> 0.610344 | K5: =IF(AND(A5<>"", B5<>""), IFERROR(AVERAGEIFS(Log!$E:$E,Log!$A:$A,$A5),""), "") -> 0.091966633 | L5: =IF(AND(A5<>"", B5<>""), IFERROR(_xlfn.MINIFS(Log!$E:$E,Log!$A:$A,$A5),""), "") -> 0.0446854 | M5: =IF(AND(A5<>"", B5<>""), IFERROR(_xlfn.MAXIFS(Log!$E:$E,Log!$A:$A,$A5),""), "") -> 0.143442 | N5: Did not create a box with markers, scattered randomly, adjusted auto detect tolerance for set volume down to 2mm
A6: =A5+1 -> 46231 | B6: 24.5 | C6: =COUNTIFS(Log!$A:$A,$A6) -> 18 | D6: 0.50694444 | E6: 1000 | F6: =IF(AND(A6<>"", B6<>""), IFERROR(AVERAGEIFS(Log!$C:$C,Log!$A:$A,$A6),""), "") -> 1833.0556 | G6: =IF(AND(F6<>"", E6<>""), F6/E6, "") -> 1.8330556 | H6: =IF(AND(A6<>"", B6<>""), IFERROR(AVERAGEIFS(Log!$D:$D,Log!$A:$A,$A6),""), "") -> 0.35087828 | I6: =IF(AND(A6<>"",B6<>""),IFERROR(_xlfn.MINIFS(Log!$D:$D,Log!$A:$A,$A6),""),"") -> 0.157855 | J6: =IF(AND(A6<>"",B6<>""),IFERROR(_xlfn.MAXIFS(Log!$D:$D,Log!$A:$A,$A6),""),"") -> 0.556807 | K6: =IF(AND(A6<>"", B6<>""), IFERROR(AVERAGEIFS(Log!$E:$E,Log!$A:$A,$A6),""), "") -> 0.084730411 | L6: =IF(AND(A6<>"", B6<>""), IFERROR(_xlfn.MINIFS(Log!$E:$E,Log!$A:$A,$A6),""), "") -> 0.0478596 | M6: =IF(AND(A6<>"", B6<>""), IFERROR(_xlfn.MAXIFS(Log!$E:$E,Log!$A:$A,$A6),""), "") -> 0.146714 | N6: Scattered markers randomly in the volume, completely reset calibration and masking beforehand, manually masked reflective pipe in camera 5. Modified approach with wand to push in/pull back and wave widely/shortly rather than fixating on figure 8
A7: =A6+1 -> 46232 | B7: 25.5 | C7: =COUNTIFS(Log!$A:$A,$A7) -> 18 | D7: 0.82291667 | E7: 1000 | F7: =IF(AND(A7<>"", B7<>""), IFERROR(AVERAGEIFS(Log!$C:$C,Log!$A:$A,$A7),""), "") -> 2014.2222 | G7: =IF(AND(F7<>"", E7<>""), F7/E7, "") -> 2.0142222 | H7: =IF(AND(A7<>"", B7<>""), IFERROR(AVERAGEIFS(Log!$D:$D,Log!$A:$A,$A7),""), "") -> 0.36980917 | I7: =IF(AND(A7<>"",B7<>""),IFERROR(_xlfn.MINIFS(Log!$D:$D,Log!$A:$A,$A7),""),"") -> 0.184608 | J7: =IF(AND(A7<>"",B7<>""),IFERROR(_xlfn.MAXIFS(Log!$D:$D,Log!$A:$A,$A7),""),"") -> 0.569174 | K7: =IF(AND(A7<>"", B7<>""), IFERROR(AVERAGEIFS(Log!$E:$E,Log!$A:$A,$A7),""), "") -> 0.088881683 | L7: =IF(AND(A7<>"", B7<>""), IFERROR(_xlfn.MINIFS(Log!$E:$E,Log!$A:$A,$A7),""), "") -> 0.0593812 | M7: =IF(AND(A7<>"", B7<>""), IFERROR(_xlfn.MAXIFS(Log!$E:$E,Log!$A:$A,$A7),""), "") -> 0.136459 | N7: Mostly focused on fixing the calibration data pollution bug from sample data (camera IDs reorganised) but sweeping movements around the main volume, with markers scattered in clusters no box outline
A8: =A7+1 -> 46233 | B8: 24.5 | C8: =COUNTIFS(Log!$A:$A,$A8) -> 18 | D8: 0.53333333 | E8: 1000 | F8: =IF(AND(A8<>"", B8<>""), IFERROR(AVERAGEIFS(Log!$C:$C,Log!$A:$A,$A8),""), "") -> 1931.5556 | G8: =IF(AND(F8<>"", E8<>""), F8/E8, "") -> 1.9315556 | H8: =IF(AND(A8<>"", B8<>""), IFERROR(AVERAGEIFS(Log!$D:$D,Log!$A:$A,$A8),""), "") -> 0.32767978 | I8: =IF(AND(A8<>"",B8<>""),IFERROR(_xlfn.MINIFS(Log!$D:$D,Log!$A:$A,$A8),""),"") -> 0.211716 | J8: =IF(AND(A8<>"",B8<>""),IFERROR(_xlfn.MAXIFS(Log!$D:$D,Log!$A:$A,$A8),""),"") -> 0.454062 | K8: =IF(AND(A8<>"", B8<>""), IFERROR(AVERAGEIFS(Log!$E:$E,Log!$A:$A,$A8),""), "") -> 0.079198328 | L8: =IF(AND(A8<>"", B8<>""), IFERROR(_xlfn.MINIFS(Log!$E:$E,Log!$A:$A,$A8),""), "") -> 0.0509483 | M8: =IF(AND(A8<>"", B8<>""), IFERROR(_xlfn.MAXIFS(Log!$E:$E,Log!$A:$A,$A8),""), "") -> 0.122413 | N8: After calibration modified level of the L-Frame as floor wasn't level, so this may affect volume capture in future
A9: 46234 | B9: 24.5 | C9: =COUNTIFS(Log!$A:$A,#REF!) -> 0 | D9: 0.58333333 | E9: 1500 | F9: =IF(AND(A9<>"", B9<>""), IFERROR(AVERAGEIFS(Log!$C:$C,Log!$A:$A,$A9),""), "") -> 2650.3889 | G9: =IF(AND(F9<>"", E9<>""), F9/E9, "") -> 1.7669259 | H9: =IF(AND(A9<>"", B9<>""), IFERROR(AVERAGEIFS(Log!$D:$D,Log!$A:$A,$A9),""), "") -> 0.391708 | I9: =IF(AND(A9<>"",B9<>""),IFERROR(_xlfn.MINIFS(Log!$D:$D,Log!$A:$A,$A9),""),"") -> 0.163774 | J9: =IF(AND(A9<>"",B9<>""),IFERROR(_xlfn.MAXIFS(Log!$D:$D,Log!$A:$A,$A9),""),"") -> 0.616092 | K9: =IF(AND(A9<>"", B9<>""), IFERROR(AVERAGEIFS(Log!$E:$E,Log!$A:$A,$A9),""), "") -> 0.09618615 | L9: =IF(AND(A9<>"", B9<>""), IFERROR(_xlfn.MINIFS(Log!$E:$E,Log!$A:$A,$A9),""), "") -> 0.0520276 | M9: =IF(AND(A9<>"", B9<>""), IFERROR(_xlfn.MAXIFS(Log!$E:$E,Log!$A:$A,$A9),""), "") -> 0.202345 | N9: Following 2 wand count errors increased auto stop min frames to 1500 and spread time more equally in volume - using technique guidance from active wand v4 (away from body, large circles, facing camera, no turning wand keep parallel to yourself, watch for objects) Worsening world and image errors! To repeat on 1-2 tests to confirm
A10: 46235 | B10: 24 | C10: =COUNTIFS(Log!$A:$A,$A10) -> 18 | D10: 0.74097222 | E10: 1500 | F10: =IF(AND(A10<>"", B10<>""), IFERROR(AVERAGEIFS(Log!$C:$C,Log!$A:$A,$A10),""), "") -> 2360.4444 | G10: =IF(AND(F10<>"", E10<>""), F10/E10, "") -> 1.5736296 | H10: =IF(AND(A10<>"", B10<>""), IFERROR(AVERAGEIFS(Log!$D:$D,Log!$A:$A,$A10),""), "") -> 0.55296411 | I10: =IF(AND(A10<>"",B10<>""),IFERROR(_xlfn.MINIFS(Log!$D:$D,Log!$A:$A,$A10),""),"") -> 0.204627 | J10: =IF(AND(A10<>"",B10<>""),IFERROR(_xlfn.MAXIFS(Log!$D:$D,Log!$A:$A,$A10),""),"") -> 1.47159 | K10: =IF(AND(A10<>"", B10<>""), IFERROR(AVERAGEIFS(Log!$E:$E,Log!$A:$A,$A10),""), "") -> 0.12669717 | L10: =IF(AND(A10<>"", B10<>""), IFERROR(_xlfn.MINIFS(Log!$E:$E,Log!$A:$A,$A10),""), "") -> 0.0548533 | M10: =IF(AND(A10<>"", B10<>""), IFERROR(_xlfn.MAXIFS(Log!$E:$E,Log!$A:$A,$A10),""), "") -> 0.310464 | N10: Minor wand wave not according to technique (folding wave) but otherwise going left/right and keeping away from body. Some camera error outliers and ghost markers during floor plane calibration.
A11: 46237 | B11: 24 | C11: =COUNTIFS(Log!$A:$A,$A11) -> 18 | D11: 0.46597222 | E11: 1000 | F11: =IF(AND(A11<>"", B11<>""), IFERROR(AVERAGEIFS(Log!$C:$C,Log!$A:$A,$A11),""), "") -> 2116.6111 | G11: =IF(AND(F11<>"", E11<>""), F11/E11, "") -> 2.1166111 | H11: =IF(AND(A11<>"", B11<>""), IFERROR(AVERAGEIFS(Log!$D:$D,Log!$A:$A,$A11),""), "") -> 0.37600283 | I11: =IF(AND(A11<>"",B11<>""),IFERROR(_xlfn.MINIFS(Log!$D:$D,Log!$A:$A,$A11),""),"") -> 0.179206 | J11: =IF(AND(A11<>"",B11<>""),IFERROR(_xlfn.MAXIFS(Log!$D:$D,Log!$A:$A,$A11),""),"") -> 0.79733 | K11: =IF(AND(A11<>"", B11<>""), IFERROR(AVERAGEIFS(Log!$E:$E,Log!$A:$A,$A11),""), "") -> 0.0903465 | L11: =IF(AND(A11<>"", B11<>""), IFERROR(_xlfn.MINIFS(Log!$E:$E,Log!$A:$A,$A11),""), "") -> 0.0426844 | M11: =IF(AND(A11<>"", B11<>""), IFERROR(_xlfn.MAXIFS(Log!$E:$E,Log!$A:$A,$A11),""), "") -> 0.15169 | N11: Reverted wand wave technique - waving in figure 8 Opting to put clusters of 3 in volume corners and spacing out pairs elsewhere in centre of volume floor plane
C12: =COUNTIFS(Log!$A:$A,$A12) -> 0 | F12: =IF(AND(A12<>"", B12<>""), IFERROR(AVERAGEIFS(Log!$C:$C,Log!$A:$A,$A12),""), "") | G12: =IF(AND(F12<>"", E12<>""), F12/E12, "") | H12: =IF(AND(A12<>"", B12<>""), IFERROR(AVERAGEIFS(Log!$D:$D,Log!$A:$A,$A12),""), "") | I12: =IF(AND(A12<>"",B12<>""),IFERROR(_xlfn.MINIFS(Log!$D:$D,Log!$A:$A,$A12),""),"") | J12: =IF(AND(A12<>"",B12<>""),IFERROR(_xlfn.MAXIFS(Log!$D:$D,Log!$A:$A,$A12),""),"") | K12: =IF(AND(A12<>"", B12<>""), IFERROR(AVERAGEIFS(Log!$E:$E,Log!$A:$A,$A12),""), "") | L12: =IF(AND(A12<>"", B12<>""), IFERROR(_xlfn.MINIFS(Log!$E:$E,Log!$A:$A,$A12),""), "") | M12: =IF(AND(A12<>"", B12<>""), IFERROR(_xlfn.MAXIFS(Log!$E:$E,Log!$A:$A,$A12),""), "")
C13: =COUNTIFS(Log!$A:$A,$A13) -> 0 | F13: =IF(AND(A13<>"", B13<>""), IFERROR(AVERAGEIFS(Log!$C:$C,Log!$A:$A,$A13),""), "") | G13: =IF(AND(F13<>"", E13<>""), F13/E13, "") | H13: =IF(AND(A13<>"", B13<>""), IFERROR(AVERAGEIFS(Log!$D:$D,Log!$A:$A,$A13),""), "") | I13: =IF(AND(A13<>"",B13<>""),IFERROR(_xlfn.MINIFS(Log!$D:$D,Log!$A:$A,$A13),""),"") | J13: =IF(AND(A13<>"",B13<>""),IFERROR(_xlfn.MAXIFS(Log!$D:$D,Log!$A:$A,$A13),""),"") | K13: =IF(AND(A13<>"", B13<>""), IFERROR(AVERAGEIFS(Log!$E:$E,Log!$A:$A,$A13),""), "") | L13: =IF(AND(A13<>"", B13<>""), IFERROR(_xlfn.MINIFS(Log!$E:$E,Log!$A:$A,$A13),""), "") | M13: =IF(AND(A13<>"", B13<>""), IFERROR(_xlfn.MAXIFS(Log!$E:$E,Log!$A:$A,$A13),""), "")
C14: =COUNTIFS(Log!$A:$A,$A14) -> 0 | F14: =IF(AND(A14<>"", B14<>""), IFERROR(AVERAGEIFS(Log!$C:$C,Log!$A:$A,$A14),""), "") | G14: =IF(AND(F14<>"", E14<>""), F14/E14, "") | H14: =IF(AND(A14<>"", B14<>""), IFERROR(AVERAGEIFS(Log!$D:$D,Log!$A:$A,$A14),""), "") | I14: =IF(AND(A14<>"",B14<>""),IFERROR(_xlfn.MINIFS(Log!$D:$D,Log!$A:$A,$A14),""),"") | K14: =IF(AND(A14<>"", B14<>""), IFERROR(AVERAGEIFS(Log!$E:$E,Log!$A:$A,$A14),""), "") | L14: =IF(AND(A14<>"", B14<>""), IFERROR(_xlfn.MINIFS(Log!$E:$E,Log!$A:$A,$A14),""), "") | M14: =IF(AND(A14<>"", B14<>""), IFERROR(_xlfn.MAXIFS(Log!$E:$E,Log!$A:$A,$A14),""), "")
C15: =COUNTIFS(Log!$A:$A,$A15) -> 0 | F15: =IF(AND(A15<>"", B15<>""), IFERROR(AVERAGEIFS(Log!$C:$C,Log!$A:$A,$A15),""), "") | G15: =IF(AND(F15<>"", E15<>""), F15/E15, "") | H15: =IF(AND(A15<>"", B15<>""), IFERROR(AVERAGEIFS(Log!$D:$D,Log!$A:$A,$A15),""), "") | I15: =IF(AND(A15<>"",B15<>""),IFERROR(_xlfn.MINIFS(Log!$D:$D,Log!$A:$A,$A15),""),"") | J15: =IF(AND(A15<>"",B15<>""),IFERROR(_xlfn.MAXIFS(Log!$D:$D,Log!$A:$A,$A15),""),"") | K15: =IF(AND(A15<>"", B15<>""), IFERROR(AVERAGEIFS(Log!$E:$E,Log!$A:$A,$A15),""), "") | L15: =IF(AND(A15<>"", B15<>""), IFERROR(_xlfn.MINIFS(Log!$E:$E,Log!$A:$A,$A15),""), "") | M15: =IF(AND(A15<>"", B15<>""), IFERROR(_xlfn.MAXIFS(Log!$E:$E,Log!$A:$A,$A15),""), "")
C16: =COUNTIFS(Log!$A:$A,$A16) -> 0 | F16: =IF(AND(A16<>"", B16<>""), IFERROR(AVERAGEIFS(Log!$C:$C,Log!$A:$A,$A16),""), "") | G16: =IF(AND(F16<>"", E16<>""), F16/E16, "") | H16: =IF(AND(A16<>"", B16<>""), IFERROR(AVERAGEIFS(Log!$D:$D,Log!$A:$A,$A16),""), "") | I16: =IF(AND(A16<>"",B16<>""),IFERROR(_xlfn.MINIFS(Log!$D:$D,Log!$A:$A,$A16),""),"") | J16: =IF(AND(A16<>"",B16<>""),IFERROR(_xlfn.MAXIFS(Log!$D:$D,Log!$A:$A,$A16),""),"") | K16: =IF(AND(A16<>"", B16<>""), IFERROR(AVERAGEIFS(Log!$E:$E,Log!$A:$A,$A16),""), "") | L16: =IF(AND(A16<>"", B16<>""), IFERROR(_xlfn.MINIFS(Log!$E:$E,Log!$A:$A,$A16),""), "") | M16: =IF(AND(A16<>"", B16<>""), IFERROR(_xlfn.MAXIFS(Log!$E:$E,Log!$A:$A,$A16),""), "")
C17: =COUNTIFS(Log!$A:$A,$A17) -> 0 | F17: =IF(AND(A17<>"", B17<>""), IFERROR(AVERAGEIFS(Log!$C:$C,Log!$A:$A,$A17),""), "") | G17: =IF(AND(F17<>"", E17<>""), F17/E17, "") | H17: =IF(AND(A17<>"", B17<>""), IFERROR(AVERAGEIFS(Log!$D:$D,Log!$A:$A,$A17),""), "") | I17: =IF(AND(A17<>"",B17<>""),IFERROR(_xlfn.MINIFS(Log!$D:$D,Log!$A:$A,$A17),""),"") | J17: =IF(AND(A17<>"",B17<>""),IFERROR(_xlfn.MAXIFS(Log!$D:$D,Log!$A:$A,$A17),""),"") | K17: =IF(AND(A17<>"", B17<>""), IFERROR(AVERAGEIFS(Log!$E:$E,Log!$A:$A,$A17),""), "") | L17: =IF(AND(A17<>"", B17<>""), IFERROR(_xlfn.MINIFS(Log!$E:$E,Log!$A:$A,$A17),""), "") | M17: =IF(AND(A17<>"", B17<>""), IFERROR(_xlfn.MAXIFS(Log!$E:$E,Log!$A:$A,$A17),""), "")
C18: =COUNTIFS(Log!$A:$A,$A18) -> 0 | F18: =IF(AND(A18<>"", B18<>""), IFERROR(AVERAGEIFS(Log!$C:$C,Log!$A:$A,$A18),""), "") | G18: =IF(AND(F18<>"", E18<>""), F18/E18, "") | H18: =IF(AND(A18<>"", B18<>""), IFERROR(AVERAGEIFS(Log!$D:$D,Log!$A:$A,$A18),""), "") | I18: =IF(AND(A18<>"",B18<>""),IFERROR(_xlfn.MINIFS(Log!$D:$D,Log!$A:$A,$A18),""),"") | J18: =IF(AND(A18<>"",B18<>""),IFERROR(_xlfn.MAXIFS(Log!$D:$D,Log!$A:$A,$A18),""),"") | K18: =IF(AND(A18<>"", B18<>""), IFERROR(AVERAGEIFS(Log!$E:$E,Log!$A:$A,$A18),""), "") | L18: =IF(AND(A18<>"", B18<>""), IFERROR(_xlfn.MINIFS(Log!$E:$E,Log!$A:$A,$A18),""), "") | M18: =IF(AND(A18<>"", B18<>""), IFERROR(_xlfn.MAXIFS(Log!$E:$E,Log!$A:$A,$A18),""), "")
C19: =COUNTIFS(Log!$A:$A,$A19) -> 0 | F19: =IF(AND(A19<>"", B19<>""), IFERROR(AVERAGEIFS(Log!$C:$C,Log!$A:$A,$A19),""), "") | G19: =IF(AND(F19<>"", E19<>""), F19/E19, "") | H19: =IF(AND(A19<>"", B19<>""), IFERROR(AVERAGEIFS(Log!$D:$D,Log!$A:$A,$A19),""), "") | I19: =IF(AND(A19<>"",B19<>""),IFERROR(_xlfn.MINIFS(Log!$D:$D,Log!$A:$A,$A19),""),"") | J19: =IF(AND(A19<>"",B19<>""),IFERROR(_xlfn.MAXIFS(Log!$D:$D,Log!$A:$A,$A19),""),"") | K19: =IF(AND(A19<>"", B19<>""), IFERROR(AVERAGEIFS(Log!$E:$E,Log!$A:$A,$A19),""), "") | L19: =IF(AND(A19<>"", B19<>""), IFERROR(_xlfn.MINIFS(Log!$E:$E,Log!$A:$A,$A19),""), "") | M19: =IF(AND(A19<>"", B19<>""), IFERROR(_xlfn.MAXIFS(Log!$E:$E,Log!$A:$A,$A19),""), "")
C20: =COUNTIFS(Log!$A:$A,$A20) -> 0 | F20: =IF(AND(A20<>"", B20<>""), IFERROR(AVERAGEIFS(Log!$C:$C,Log!$A:$A,$A20),""), "") | G20: =IF(AND(F20<>"", E20<>""), F20/E20, "") | H20: =IF(AND(A20<>"", B20<>""), IFERROR(AVERAGEIFS(Log!$D:$D,Log!$A:$A,$A20),""), "") | I20: =IF(AND(A20<>"",B20<>""),IFERROR(_xlfn.MINIFS(Log!$D:$D,Log!$A:$A,$A20),""),"") | J20: =IF(AND(A20<>"",B20<>""),IFERROR(_xlfn.MAXIFS(Log!$D:$D,Log!$A:$A,$A20),""),"") | K20: =IF(AND(A20<>"", B20<>""), IFERROR(AVERAGEIFS(Log!$E:$E,Log!$A:$A,$A20),""), "") | L20: =IF(AND(A20<>"", B20<>""), IFERROR(_xlfn.MINIFS(Log!$E:$E,Log!$A:$A,$A20),""), "") | M20: =IF(AND(A20<>"", B20<>""), IFERROR(_xlfn.MAXIFS(Log!$E:$E,Log!$A:$A,$A20),""), "")
C21: =COUNTIFS(Log!$A:$A,$A21) -> 0 | F21: =IF(AND(A21<>"", B21<>""), IFERROR(AVERAGEIFS(Log!$C:$C,Log!$A:$A,$A21),""), "") | G21: =IF(AND(F21<>"", E21<>""), F21/E21, "") | H21: =IF(AND(A21<>"", B21<>""), IFERROR(AVERAGEIFS(Log!$D:$D,Log!$A:$A,$A21),""), "") | I21: =IF(AND(A21<>"",B21<>""),IFERROR(_xlfn.MINIFS(Log!$D:$D,Log!$A:$A,$A21),""),"") | J21: =IF(AND(A21<>"",B21<>""),IFERROR(_xlfn.MAXIFS(Log!$D:$D,Log!$A:$A,$A21),""),"") | K21: =IF(AND(A21<>"", B21<>""), IFERROR(AVERAGEIFS(Log!$E:$E,Log!$A:$A,$A21),""), "") | L21: =IF(AND(A21<>"", B21<>""), IFERROR(_xlfn.MINIFS(Log!$E:$E,Log!$A:$A,$A21),""), "") | M21: =IF(AND(A21<>"", B21<>""), IFERROR(_xlfn.MAXIFS(Log!$E:$E,Log!$A:$A,$A21),""), "")
C22: =COUNTIFS(Log!$A:$A,$A22) -> 0 | F22: =IF(AND(A22<>"", B22<>""), IFERROR(AVERAGEIFS(Log!$C:$C,Log!$A:$A,$A22),""), "") | G22: =IF(AND(F22<>"", E22<>""), F22/E22, "") | H22: =IF(AND(A22<>"", B22<>""), IFERROR(AVERAGEIFS(Log!$D:$D,Log!$A:$A,$A22),""), "") | I22: =IF(AND(A22<>"",B22<>""),IFERROR(_xlfn.MINIFS(Log!$D:$D,Log!$A:$A,$A22),""),"") | J22: =IF(AND(A22<>"",B22<>""),IFERROR(_xlfn.MAXIFS(Log!$D:$D,Log!$A:$A,$A22),""),"") | K22: =IF(AND(A22<>"", B22<>""), IFERROR(AVERAGEIFS(Log!$E:$E,Log!$A:$A,$A22),""), "") | L22: =IF(AND(A22<>"", B22<>""), IFERROR(_xlfn.MINIFS(Log!$E:$E,Log!$A:$A,$A22),""), "") | M22: =IF(AND(A22<>"", B22<>""), IFERROR(_xlfn.MAXIFS(Log!$E:$E,Log!$A:$A,$A22),""), "")
C23: =COUNTIFS(Log!$A:$A,$A23) -> 0 | F23: =IF(AND(A23<>"", B23<>""), IFERROR(AVERAGEIFS(Log!$C:$C,Log!$A:$A,$A23),""), "") | G23: =IF(AND(F23<>"", E23<>""), F23/E23, "") | H23: =IF(AND(A23<>"", B23<>""), IFERROR(AVERAGEIFS(Log!$D:$D,Log!$A:$A,$A23),""), "") | I23: =IF(AND(A23<>"",B23<>""),IFERROR(_xlfn.MINIFS(Log!$D:$D,Log!$A:$A,$A23),""),"") | J23: =IF(AND(A23<>"",B23<>""),IFERROR(_xlfn.MAXIFS(Log!$D:$D,Log!$A:$A,$A23),""),"") | K23: =IF(AND(A23<>"", B23<>""), IFERROR(AVERAGEIFS(Log!$E:$E,Log!$A:$A,$A23),""), "") | L23: =IF(AND(A23<>"", B23<>""), IFERROR(_xlfn.MINIFS(Log!$E:$E,Log!$A:$A,$A23),""), "") | M23: =IF(AND(A23<>"", B23<>""), IFERROR(_xlfn.MAXIFS(Log!$E:$E,Log!$A:$A,$A23),""), "")
C24: =COUNTIFS(Log!$A:$A,$A24) -> 0 | F24: =IF(AND(A24<>"", B24<>""), IFERROR(AVERAGEIFS(Log!$C:$C,Log!$A:$A,$A24),""), "") | G24: =IF(AND(F24<>"", E24<>""), F24/E24, "") | H24: =IF(AND(A24<>"", B24<>""), IFERROR(AVERAGEIFS(Log!$D:$D,Log!$A:$A,$A24),""), "") | I24: =IF(AND(A24<>"",B24<>""),IFERROR(_xlfn.MINIFS(Log!$D:$D,Log!$A:$A,$A24),""),"") | J24: =IF(AND(A24<>"",B24<>""),IFERROR(_xlfn.MAXIFS(Log!$D:$D,Log!$A:$A,$A24),""),"") | K24: =IF(AND(A24<>"", B24<>""), IFERROR(AVERAGEIFS(Log!$E:$E,Log!$A:$A,$A24),""), "") | L24: =IF(AND(A24<>"", B24<>""), IFERROR(_xlfn.MINIFS(Log!$E:$E,Log!$A:$A,$A24),""), "") | M24: =IF(AND(A24<>"", B24<>""), IFERROR(_xlfn.MAXIFS(Log!$E:$E,Log!$A:$A,$A24),""), "")
C25: =COUNTIFS(Log!$A:$A,$A25) -> 0 | F25: =IF(AND(A25<>"", B25<>""), IFERROR(AVERAGEIFS(Log!$C:$C,Log!$A:$A,$A25),""), "") | G25: =IF(AND(F25<>"", E25<>""), F25/E25, "") | H25: =IF(AND(A25<>"", B25<>""), IFERROR(AVERAGEIFS(Log!$D:$D,Log!$A:$A,$A25),""), "") | I25: =IF(AND(A25<>"",B25<>""),IFERROR(_xlfn.MINIFS(Log!$D:$D,Log!$A:$A,$A25),""),"") | J25: =IF(AND(A25<>"",B25<>""),IFERROR(_xlfn.MAXIFS(Log!$D:$D,Log!$A:$A,$A25),""),"") | K25: =IF(AND(A25<>"", B25<>""), IFERROR(AVERAGEIFS(Log!$E:$E,Log!$A:$A,$A25),""), "") | L25: =IF(AND(A25<>"", B25<>""), IFERROR(_xlfn.MINIFS(Log!$E:$E,Log!$A:$A,$A25),""), "") | M25: =IF(AND(A25<>"", B25<>""), IFERROR(_xlfn.MAXIFS(Log!$E:$E,Log!$A:$A,$A25),""), "")
C26: =COUNTIFS(Log!$A:$A,$A26) -> 0 | F26: =IF(AND(A26<>"", B26<>""), IFERROR(AVERAGEIFS(Log!$C:$C,Log!$A:$A,$A26),""), "") | G26: =IF(AND(F26<>"", E26<>""), F26/E26, "") | H26: =IF(AND(A26<>"", B26<>""), IFERROR(AVERAGEIFS(Log!$D:$D,Log!$A:$A,$A26),""), "") | I26: =IF(AND(A26<>"",B26<>""),IFERROR(_xlfn.MINIFS(Log!$D:$D,Log!$A:$A,$A26),""),"") | J26: =IF(AND(A26<>"",B26<>""),IFERROR(_xlfn.MAXIFS(Log!$D:$D,Log!$A:$A,$A26),""),"") | K26: =IF(AND(A26<>"", B26<>""), IFERROR(AVERAGEIFS(Log!$E:$E,Log!$A:$A,$A26),""), "") | L26: =IF(AND(A26<>"", B26<>""), IFERROR(_xlfn.MINIFS(Log!$E:$E,Log!$A:$A,$A26),""), "") | M26: =IF(AND(A26<>"", B26<>""), IFERROR(_xlfn.MAXIFS(Log!$E:$E,Log!$A:$A,$A26),""), "")
... C57: =COUNTIFS(Log!$A:$A,$A57) -> 0 | F57: =IF(AND(A57<>"", B57<>""), IFERROR(AVERAGEIFS(Log!$C:$C,Log!$A:$A,$A57),""), "") | G57: =IF(AND(F57<>"", E57<>""), F57/E57, "") | H57: =IF(AND(A57<>"", B57<>""), IFERROR(AVERAGEIFS(Log!$D:$D,Log!$A:$A,$A57),""), "") | I57: =IF(AND(A57<>"",B57<>""),IFERROR(_xlfn.MINIFS(Log!$D:$D,Log!$A:$A,$A57),""),"") | J57: =IF(AND(A57<>"",B57<>""),IFERROR(_xlfn.MAXIFS(Log!$D:$D,Log!$A:$A,$A57),""),"") | K57: =IF(AND(A57<>"", B57<>""), IFERROR(AVERAGEIFS(Log!$E:$E,Log!$A:$A,$A57),""), "") | L57: =IF(AND(A57<>"", B57<>""), IFERROR(_xlfn.MINIFS(Log!$E:$E,Log!$A:$A,$A57),""), "") | M57: =IF(AND(A57<>"", B57<>""), IFERROR(_xlfn.MAXIFS(Log!$E:$E,Log!$A:$A,$A57),""), "")
F58: =IF(AND(A58<>"", B58<>""), IFERROR(AVERAGEIFS(Log!$C:$C,Log!$A:$A,$A58),""), "") | G58: =IF(AND(F58<>"", E58<>""), F58/E58, "") | H58: =IF(AND(A58<>"", B58<>""), IFERROR(AVERAGEIFS(Log!$D:$D,Log!$A:$A,$A58),""), "") | I58: =IF(AND(A58<>"",B58<>""),IFERROR(_xlfn.MINIFS(Log!$D:$D,Log!$A:$A,$A58),""),"") | J58: =IF(AND(A58<>"",B58<>""),IFERROR(_xlfn.MAXIFS(Log!$D:$D,Log!$A:$A,$A58),""),"") | K58: =IF(AND(A58<>"", B58<>""), IFERROR(AVERAGEIFS(Log!$E:$E,Log!$A:$A,$A58),""), "") | L58: =IF(AND(A58<>"", B58<>""), IFERROR(_xlfn.MINIFS(Log!$E:$E,Log!$A:$A,$A58),""), "") | M58: =IF(AND(A58<>"", B58<>""), IFERROR(_xlfn.MAXIFS(Log!$E:$E,Log!$A:$A,$A58),""), "")
F59: =IF(AND(A59<>"", B59<>""), IFERROR(AVERAGEIFS(Log!$C:$C,Log!$A:$A,$A59),""), "") | G59: =IF(AND(F59<>"", E59<>""), F59/E59, "") | H59: =IF(AND(A59<>"", B59<>""), IFERROR(AVERAGEIFS(Log!$D:$D,Log!$A:$A,$A59),""), "") | I59: =IF(AND(A59<>"",B59<>""),IFERROR(_xlfn.MINIFS(Log!$D:$D,Log!$A:$A,$A59),""),"") | J59: =IF(AND(A59<>"",B59<>""),IFERROR(_xlfn.MAXIFS(Log!$D:$D,Log!$A:$A,$A59),""),"") | K59: =IF(AND(A59<>"", B59<>""), IFERROR(AVERAGEIFS(Log!$E:$E,Log!$A:$A,$A59),""), "") | L59: =IF(AND(A59<>"", B59<>""), IFERROR(_xlfn.MINIFS(Log!$E:$E,Log!$A:$A,$A59),""), "") | M59: =IF(AND(A59<>"", B59<>""), IFERROR(_xlfn.MAXIFS(Log!$E:$E,Log!$A:$A,$A59),""), "")
F60: =IF(AND(A60<>"", B60<>""), IFERROR(AVERAGEIFS(Log!$C:$C,Log!$A:$A,$A60),""), "") | G60: =IF(AND(F60<>"", E60<>""), F60/E60, "") | H60: =IF(AND(A60<>"", B60<>""), IFERROR(AVERAGEIFS(Log!$D:$D,Log!$A:$A,$A60),""), "") | I60: =IF(AND(A60<>"",B60<>""),IFERROR(_xlfn.MINIFS(Log!$D:$D,Log!$A:$A,$A60),""),"") | J60: =IF(AND(A60<>"",B60<>""),IFERROR(_xlfn.MAXIFS(Log!$D:$D,Log!$A:$A,$A60),""),"") | K60: =IF(AND(A60<>"", B60<>""), IFERROR(AVERAGEIFS(Log!$E:$E,Log!$A:$A,$A60),""), "") | L60: =IF(AND(A60<>"", B60<>""), IFERROR(_xlfn.MINIFS(Log!$E:$E,Log!$A:$A,$A60),""), "") | M60: =IF(AND(A60<>"", B60<>""), IFERROR(_xlfn.MAXIFS(Log!$E:$E,Log!$A:$A,$A60),""), "")
F61: =IF(AND(A61<>"", B61<>""), IFERROR(AVERAGEIFS(Log!$C:$C,Log!$A:$A,$A61),""), "") | G61: =IF(AND(F61<>"", E61<>""), F61/E61, "") | H61: =IF(AND(A61<>"", B61<>""), IFERROR(AVERAGEIFS(Log!$D:$D,Log!$A:$A,$A61),""), "") | I61: =IF(AND(A61<>"",B61<>""),IFERROR(_xlfn.MINIFS(Log!$D:$D,Log!$A:$A,$A61),""),"") | J61: =IF(AND(A61<>"",B61<>""),IFERROR(_xlfn.MAXIFS(Log!$D:$D,Log!$A:$A,$A61),""),"") | K61: =IF(AND(A61<>"", B61<>""), IFERROR(AVERAGEIFS(Log!$E:$E,Log!$A:$A,$A61),""), "") | L61: =IF(AND(A61<>"", B61<>""), IFERROR(_xlfn.MINIFS(Log!$E:$E,Log!$A:$A,$A61),""), "") | M61: =IF(AND(A61<>"", B61<>""), IFERROR(_xlfn.MAXIFS(Log!$E:$E,Log!$A:$A,$A61),""), "")
F62: =IF(AND(A62<>"", B62<>""), IFERROR(AVERAGEIFS(Log!$C:$C,Log!$A:$A,$A62),""), "") | G62: =IF(AND(F62<>"", E62<>""), F62/E62, "") | H62: =IF(AND(A62<>"", B62<>""), IFERROR(AVERAGEIFS(Log!$D:$D,Log!$A:$A,$A62),""), "") | I62: =IF(AND(A62<>"",B62<>""),IFERROR(_xlfn.MINIFS(Log!$D:$D,Log!$A:$A,$A62),""),"") | J62: =IF(AND(A62<>"",B62<>""),IFERROR(_xlfn.MAXIFS(Log!$D:$D,Log!$A:$A,$A62),""),"") | K62: =IF(AND(A62<>"", B62<>""), IFERROR(AVERAGEIFS(Log!$E:$E,Log!$A:$A,$A62),""), "") | L62: =IF(AND(A62<>"", B62<>""), IFERROR(_xlfn.MINIFS(Log!$E:$E,Log!$A:$A,$A62),""), "") | M62: =IF(AND(A62<>"", B62<>""), IFERROR(_xlfn.MAXIFS(Log!$E:$E,Log!$A:$A,$A62),""), "")

Sheet Camera Error Trend
A1: Select camera: | C1: #4 (Vero v2.2) | H1: ALL TIME CAMERA ERRORS | J1: ALL TIME AVERAGES | L1: PERFORMANCE
A2: Errors marked red if worse than daily average, green if better | H2: World Error | I2: Image Error | J2: World Error | K2: Image Error | L2: World Error | M2: Image Error
A3: Date | B3: Temp | C3: =_xlfn.CONCAT("Camera ", C1, " Error") -> Camera #4 (Vero v2.2) Error | E3: AVERAGES FOR THIS DAY | H3: =IFERROR(AVERAGEIFS(Log!$D:$D, Log!$B:$B,$C$1),"") -> 0.53255337 | I3: =IFERROR(AVERAGEIFS(Log!$E:$E, Log!$B:$B,$C$1),"") -> 0.10561092 | J3: =AVERAGE(Log!$D:$D) -> 0.39259022 | K3: =AVERAGE(Log!$E:$E) -> 0.093796212 | L3: =J3/H3 -> 0.73718474 | M3: =K3/I3 -> 0.88812982
C4: World Error | D4: Image Error | E4: World Error | F4: Image Error
A5: 46228 | B5: =_xlfn.XLOOKUP($A5, 'Daily Summary'!A:A, 'Daily Summary'!B:B) -> 23.5 | C5: =IFERROR(AVERAGEIFS(Log!$D:$D,Log!$A:$A,$A5,Log!$B:$B,$C$1),"") -> 0.620036 | D5: =IFERROR(AVERAGEIFS(Log!$E:$E,Log!$A:$A,$A5,Log!$B:$B,$C$1),"") -> 0.121579 | E5: ='Daily Summary'!H3 -> 0.39118376 | F5: ='Daily Summary'!K3 -> 0.0922785
A6: =A5+1 -> 46229 | B6: =_xlfn.XLOOKUP($A6, 'Daily Summary'!A:A, 'Daily Summary'!B:B) -> 0 | C6: =IFERROR(AVERAGEIFS(Log!$D:$D,Log!$A:$A,$A6,Log!$B:$B,$C$1),"") | D6: =IFERROR(AVERAGEIFS(Log!$E:$E,Log!$A:$A,$A6,Log!$B:$B,$C$1),"") | E6: ='Daily Summary'!H4 | F6: ='Daily Summary'!K4
A7: =A6+1 -> 46230 | B7: =_xlfn.XLOOKUP($A7, 'Daily Summary'!A:A, 'Daily Summary'!B:B) -> 23.5 | C7: =IFERROR(AVERAGEIFS(Log!$D:$D,Log!$A:$A,$A7,Log!$B:$B,$C$1),"") -> 0.610344 | D7: =IFERROR(AVERAGEIFS(Log!$E:$E,Log!$A:$A,$A7,Log!$B:$B,$C$1),"") -> 0.120907 | E7: ='Daily Summary'!H5 -> 0.38041772 | F7: ='Daily Summary'!K5 -> 0.091966633
A8: =A7+1 -> 46231 | B8: =_xlfn.XLOOKUP($A8, 'Daily Summary'!A:A, 'Daily Summary'!B:B) -> 24.5 | C8: =IFERROR(AVERAGEIFS(Log!$D:$D,Log!$A:$A,$A8,Log!$B:$B,$C$1),"") -> 0.553865 | D8: =IFERROR(AVERAGEIFS(Log!$E:$E,Log!$A:$A,$A8,Log!$B:$B,$C$1),"") -> 0.109685 | E8: ='Daily Summary'!H6 -> 0.35087828 | F8: ='Daily Summary'!K6 -> 0.084730411
A9: =A8+1 -> 46232 | B9: =_xlfn.XLOOKUP($A9, 'Daily Summary'!A:A, 'Daily Summary'!B:B) -> 25.5 | C9: =IFERROR(AVERAGEIFS(Log!$D:$D,Log!$A:$A,$A9,Log!$B:$B,$C$1),"") -> 0.569174 | D9: =IFERROR(AVERAGEIFS(Log!$E:$E,Log!$A:$A,$A9,Log!$B:$B,$C$1),"") -> 0.112651 | E9: ='Daily Summary'!H7 -> 0.36980917 | F9: ='Daily Summary'!K7 -> 0.088881683
A10: =A9+1 -> 46233 | B10: =_xlfn.XLOOKUP($A10, 'Daily Summary'!A:A, 'Daily Summary'!B:B) -> 24.5 | C10: =IFERROR(AVERAGEIFS(Log!$D:$D,Log!$A:$A,$A10,Log!$B:$B,$C$1),"") -> 0.454062 | D10: =IFERROR(AVERAGEIFS(Log!$E:$E,Log!$A:$A,$A10,Log!$B:$B,$C$1),"") -> 0.0898851 | E10: ='Daily Summary'!H8 -> 0.32767978 | F10: ='Daily Summary'!K8 -> 0.079198328
A11: =A10+1 -> 46234 | B11: =_xlfn.XLOOKUP($A11, 'Daily Summary'!A:A, 'Daily Summary'!B:B) -> 24.5 | C11: =IFERROR(AVERAGEIFS(Log!$D:$D,Log!$A:$A,$A11,Log!$B:$B,$C$1),"") -> 0.53664 | D11: =IFERROR(AVERAGEIFS(Log!$E:$E,Log!$A:$A,$A11,Log!$B:$B,$C$1),"") -> 0.106142 | E11: ='Daily Summary'!H9 -> 0.391708 | F11: ='Daily Summary'!K9 -> 0.09618615
B12: =_xlfn.XLOOKUP($A12, 'Daily Summary'!A:A, 'Daily Summary'!B:B) -> 0 | C12: =IFERROR(AVERAGEIFS(Log!$D:$D,Log!$A:$A,$A12,Log!$B:$B,$C$1),"") | D12: =IFERROR(AVERAGEIFS(Log!$E:$E,Log!$A:$A,$A12,Log!$B:$B,$C$1),"") | E12: ='Daily Summary'!H10 -> 0.55296411 | F12: ='Daily Summary'!K10 -> 0.12669717
B13: =_xlfn.XLOOKUP($A13, 'Daily Summary'!A:A, 'Daily Summary'!B:B) -> 0 | C13: =IFERROR(AVERAGEIFS(Log!$D:$D,Log!$A:$A,$A13,Log!$B:$B,$C$1),"") | D13: =IFERROR(AVERAGEIFS(Log!$E:$E,Log!$A:$A,$A13,Log!$B:$B,$C$1),"") | E13: ='Daily Summary'!H11 -> 0.37600283 | F13: ='Daily Summary'!K11 -> 0.0903465
B14: =_xlfn.XLOOKUP($A14, 'Daily Summary'!A:A, 'Daily Summary'!B:B) -> 0 | C14: =IFERROR(AVERAGEIFS(Log!$D:$D,Log!$A:$A,$A14,Log!$B:$B,$C$1),"") | D14: =IFERROR(AVERAGEIFS(Log!$E:$E,Log!$A:$A,$A14,Log!$B:$B,$C$1),"") | E14: ='Daily Summary'!H12 | F14: ='Daily Summary'!K12
B15: =_xlfn.XLOOKUP($A15, 'Daily Summary'!A:A, 'Daily Summary'!B:B) -> 0 | C15: =IFERROR(AVERAGEIFS(Log!$D:$D,Log!$A:$A,$A15,Log!$B:$B,$C$1),"") | D15: =IFERROR(AVERAGEIFS(Log!$E:$E,Log!$A:$A,$A15,Log!$B:$B,$C$1),"") | E15: ='Daily Summary'!H13 | F15: ='Daily Summary'!K13
B16: =_xlfn.XLOOKUP($A16, 'Daily Summary'!A:A, 'Daily Summary'!B:B) -> 0 | C16: =IFERROR(AVERAGEIFS(Log!$D:$D,Log!$A:$A,$A16,Log!$B:$B,$C$1),"") | D16: =IFERROR(AVERAGEIFS(Log!$E:$E,Log!$A:$A,$A16,Log!$B:$B,$C$1),"") | E16: ='Daily Summary'!H14 | F16: ='Daily Summary'!K14
B17: =_xlfn.XLOOKUP($A17, 'Daily Summary'!A:A, 'Daily Summary'!B:B) -> 0 | C17: =IFERROR(AVERAGEIFS(Log!$D:$D,Log!$A:$A,$A17,Log!$B:$B,$C$1),"") | D17: =IFERROR(AVERAGEIFS(Log!$E:$E,Log!$A:$A,$A17,Log!$B:$B,$C$1),"") | E17: ='Daily Summary'!H14 | F17: ='Daily Summary'!K14
B18: =_xlfn.XLOOKUP($A18, 'Daily Summary'!A:A, 'Daily Summary'!B:B) -> 0 | C18: =IFERROR(AVERAGEIFS(Log!$D:$D,Log!$A:$A,$A18,Log!$B:$B,$C$1),"") | D18: =IFERROR(AVERAGEIFS(Log!$E:$E,Log!$A:$A,$A18,Log!$B:$B,$C$1),"") | E18: ='Daily Summary'!H15 | F18: ='Daily Summary'!K15
B19: =_xlfn.XLOOKUP($A19, 'Daily Summary'!A:A, 'Daily Summary'!B:B) -> 0 | C19: =IFERROR(AVERAGEIFS(Log!$D:$D,Log!$A:$A,$A19,Log!$B:$B,$C$1),"") | D19: =IFERROR(AVERAGEIFS(Log!$E:$E,Log!$A:$A,$A19,Log!$B:$B,$C$1),"") | E19: ='Daily Summary'!H16 | F19: ='Daily Summary'!K16
B20: =_xlfn.XLOOKUP($A20, 'Daily Summary'!A:A, 'Daily Summary'!B:B) -> 0 | C20: =IFERROR(AVERAGEIFS(Log!$D:$D,Log!$A:$A,$A20,Log!$B:$B,$C$1),"") | D20: =IFERROR(AVERAGEIFS(Log!$E:$E,Log!$A:$A,$A20,Log!$B:$B,$C$1),"") | E20: ='Daily Summary'!H17 | F20: ='Daily Summary'!K17
B21: =_xlfn.XLOOKUP($A21, 'Daily Summary'!A:A, 'Daily Summary'!B:B) -> 0 | C21: =IFERROR(AVERAGEIFS(Log!$D:$D,Log!$A:$A,$A21,Log!$B:$B,$C$1),"") | D21: =IFERROR(AVERAGEIFS(Log!$E:$E,Log!$A:$A,$A21,Log!$B:$B,$C$1),"") | E21: ='Daily Summary'!H18 | F21: ='Daily Summary'!K18
B22: =_xlfn.XLOOKUP($A22, 'Daily Summary'!A:A, 'Daily Summary'!B:B) -> 0 | C22: =IFERROR(AVERAGEIFS(Log!$D:$D,Log!$A:$A,$A22,Log!$B:$B,$C$1),"") | D22: =IFERROR(AVERAGEIFS(Log!$E:$E,Log!$A:$A,$A22,Log!$B:$B,$C$1),"") | E22: ='Daily Summary'!H19 | F22: ='Daily Summary'!K19
B23: =_xlfn.XLOOKUP($A23, 'Daily Summary'!A:A, 'Daily Summary'!B:B) -> 0 | C23: =IFERROR(AVERAGEIFS(Log!$D:$D,Log!$A:$A,$A23,Log!$B:$B,$C$1),"") | D23: =IFERROR(AVERAGEIFS(Log!$E:$E,Log!$A:$A,$A23,Log!$B:$B,$C$1),"") | E23: ='Daily Summary'!H20 | F23: ='Daily Summary'!K20
B24: =_xlfn.XLOOKUP($A24, 'Daily Summary'!A:A, 'Daily Summary'!B:B) -> 0 | C24: =IFERROR(AVERAGEIFS(Log!$D:$D,Log!$A:$A,$A24,Log!$B:$B,$C$1),"") | D24: =IFERROR(AVERAGEIFS(Log!$E:$E,Log!$A:$A,$A24,Log!$B:$B,$C$1),"") | E24: ='Daily Summary'!H21 | F24: ='Daily Summary'!K21
B25: =_xlfn.XLOOKUP($A25, 'Daily Summary'!A:A, 'Daily Summary'!B:B) -> 0 | C25: =IFERROR(AVERAGEIFS(Log!$D:$D,Log!$A:$A,$A25,Log!$B:$B,$C$1),"") | D25: =IFERROR(AVERAGEIFS(Log!$E:$E,Log!$A:$A,$A25,Log!$B:$B,$C$1),"") | E25: ='Daily Summary'!H22 | F25: ='Daily Summary'!K22
B26: =_xlfn.XLOOKUP($A26, 'Daily Summary'!A:A, 'Daily Summary'!B:B) -> 0 | C26: =IFERROR(AVERAGEIFS(Log!$D:$D,Log!$A:$A,$A26,Log!$B:$B,$C$1),"") | D26: =IFERROR(AVERAGEIFS(Log!$E:$E,Log!$A:$A,$A26,Log!$B:$B,$C$1),"") | E26: ='Daily Summary'!H23 | F26: ='Daily Summary'!K23
B27: =_xlfn.XLOOKUP($A27, 'Daily Summary'!A:A, 'Daily Summary'!B:B) -> 0 | C27: =IFERROR(AVERAGEIFS(Log!$D:$D,Log!$A:$A,$A27,Log!$B:$B,$C$1),"") | D27: =IFERROR(AVERAGEIFS(Log!$E:$E,Log!$A:$A,$A27,Log!$B:$B,$C$1),"") | E27: ='Daily Summary'!H24 | F27: ='Daily Summary'!K24
B28: =_xlfn.XLOOKUP($A28, 'Daily Summary'!A:A, 'Daily Summary'!B:B) -> 0 | C28: =IFERROR(AVERAGEIFS(Log!$D:$D,Log!$A:$A,$A28,Log!$B:$B,$C$1),"") | D28: =IFERROR(AVERAGEIFS(Log!$E:$E,Log!$A:$A,$A28,Log!$B:$B,$C$1),"") | E28: ='Daily Summary'!H25 | F28: ='Daily Summary'!K25
... B58: =_xlfn.XLOOKUP($A58, 'Daily Summary'!A:A, 'Daily Summary'!B:B) -> 0 | C58: =IFERROR(AVERAGEIFS(Log!$D:$D,Log!$A:$A,$A58,Log!$B:$B,$C$1),"") | D58: =IFERROR(AVERAGEIFS(Log!$E:$E,Log!$A:$A,$A58,Log!$B:$B,$C$1),"") | E58: ='Daily Summary'!H55 | F58: ='Daily Summary'!K55
C59: =IFERROR(AVERAGEIFS(Log!$D:$D,Log!$A:$A,$A59,Log!$B:$B,$C$1),"") | D59: =IFERROR(AVERAGEIFS(Log!$E:$E,Log!$A:$A,$A59,Log!$B:$B,$C$1),"") | E59: ='Daily Summary'!H56 | F59: ='Daily Summary'!K56
C60: =IFERROR(AVERAGEIFS(Log!$D:$D,Log!$A:$A,$A60,Log!$B:$B,$C$1),"") | D60: =IFERROR(AVERAGEIFS(Log!$E:$E,Log!$A:$A,$A60,Log!$B:$B,$C$1),"") | E60: ='Daily Summary'!H57 | F60: ='Daily Summary'!K57

Sheet Camera Performance Trends
A1: Camera | B1: Marked red if worse than global average | D1: How many days is camera better than avg. | F1: How many days camera is worse than avg. | H1: % of total days camera beats the average | L1: GLOBAL AVERAGE OF ERROR
B2: AVERAGE CAMERA ERRORS | D2: WIN RATE (vs average) | F2: LOSS RATE (vs average) | H2: WIN RATE as Percentage | J2: Evaluation | L2: World Error | M2: Image Error
B3: World Error | C3: Image Error | D3: World Error | E3: Image Error | F3: World Error | G3: Image Error | H3: World Error | I3: Image Error | L3: =AVERAGE(B4:B21) -> 0.39137705 | M3: =AVERAGE(C4:C21) -> 0.093601634
A4: #1 (Vero v2.2) | B4: =_xlfn.LET( _xlpm.cam, $A4, _xlpm.errSum, SUMIFS(Log!$D:$D, Log!$B:$B, _xlpm.cam, Log!$D:$D, "<>"), _xlpm.errCount, COUNTIFS(Log!$B:$B, _xlpm.cam, Log!$D:$D, "<>"), IF(_xlpm.errCount=0, "", _xlpm.errSum/_xlpm.errCount) ) -> 0.32408188 | C4: =_xlfn.LET( _xlpm.cam, $A4, _xlpm.errSum, SUMIFS(Log!$E:$E, Log!$B:$B, _xlpm.cam, Log!$E:$E, "<>"), _xlpm.errCount, COUNTIFS(Log!$B:$B, _xlpm.cam, Log!$E:$E, "<>"), IF(_xlpm.errCount=0, "", _xlpm.errSum/_xlpm.errCount) ) -> 0.091985325 | D4: =COUNTIFS(Log!$B:$B, $A4, Log!$H:$H, "Yes") -> 6 | E4: =COUNTIFS(Log!$B:$B, $A4, Log!$I:$I, "Yes") -> 5 | F4: =COUNTIFS(Log!$B:$B, $A4, Log!$H:$H, "No") -> 2 | G4: =COUNTIFS(Log!$B:$B, $A4, Log!$I:$I, "No") -> 3 | H4: =D4/COUNT(_xlfn.UNIQUE(Log!$A$3:$A$281)) -> 0.75 | I4: =E4/COUNT(_xlfn.UNIQUE(Log!$A$3:$A$281)) -> 0.625
A5: #2 (Vero v2.2) | B5: =_xlfn.LET( _xlpm.cam, $A5, _xlpm.errSum, SUMIFS(Log!$D:$D, Log!$B:$B, _xlpm.cam, Log!$D:$D, "<>"), _xlpm.errCount, COUNTIFS(Log!$B:$B, _xlpm.cam, Log!$D:$D, "<>"), IF(_xlpm.errCount=0, "", _xlpm.errSum/_xlpm.errCount) ) -> 0.434523 | C5: =_xlfn.LET( _xlpm.cam, $A5, _xlpm.errSum, SUMIFS(Log!$E:$E, Log!$B:$B, _xlpm.cam, Log!$E:$E, "<>"), _xlpm.errCount, COUNTIFS(Log!$B:$B, _xlpm.cam, Log!$E:$E, "<>"), IF(_xlpm.errCount=0, "", _xlpm.errSum/_xlpm.errCount) ) -> 0.11552837 | D5: =COUNTIFS(Log!$B:$B, $A5, Log!$H:$H, "Yes") -> 1 | E5: =COUNTIFS(Log!$B:$B, $A5, Log!$I:$I, "Yes") -> 0 | F5: =COUNTIFS(Log!$B:$B, $A5, Log!$H:$H, "No") -> 7 | G5: =COUNTIFS(Log!$B:$B, $A5, Log!$I:$I, "No") -> 8 | H5: =D5/COUNT(_xlfn.UNIQUE(Log!$A$3:$A$281)) -> 0.125 | I5: =E5/COUNT(_xlfn.UNIQUE(Log!$A$3:$A$281)) -> 0
A6: #3 (Vero v2.2) | B6: =_xlfn.LET( _xlpm.cam, $A6, _xlpm.errSum, SUMIFS(Log!$D:$D, Log!$B:$B, _xlpm.cam, Log!$D:$D, "<>"), _xlpm.errCount, COUNTIFS(Log!$B:$B, _xlpm.cam, Log!$D:$D, "<>"), IF(_xlpm.errCount=0, "", _xlpm.errSum/_xlpm.errCount) ) -> 0.43415475 | C6: =_xlfn.LET( _xlpm.cam, $A6, _xlpm.errSum, SUMIFS(Log!$E:$E, Log!$B:$B, _xlpm.cam, Log!$E:$E, "<>"), _xlpm.errCount, COUNTIFS(Log!$B:$B, _xlpm.cam, Log!$E:$E, "<>"), IF(_xlpm.errCount=0, "", _xlpm.errSum/_xlpm.errCount) ) -> 0.10269324 | D6: =COUNTIFS(Log!$B:$B, $A6, Log!$H:$H, "Yes") -> 2 | E6: =COUNTIFS(Log!$B:$B, $A6, Log!$I:$I, "Yes") -> 2 | F6: =COUNTIFS(Log!$B:$B, $A6, Log!$H:$H, "No") -> 6 | G6: =COUNTIFS(Log!$B:$B, $A6, Log!$I:$I, "No") -> 6 | H6: =D6/COUNT(_xlfn.UNIQUE(Log!$A$3:$A$281)) -> 0.25 | I6: =E6/COUNT(_xlfn.UNIQUE(Log!$A$3:$A$281)) -> 0.25
A7: #4 (Vero v2.2) | B7: =_xlfn.LET( _xlpm.cam, $A7, _xlpm.errSum, SUMIFS(Log!$D:$D, Log!$B:$B, _xlpm.cam, Log!$D:$D, "<>"), _xlpm.errCount, COUNTIFS(Log!$B:$B, _xlpm.cam, Log!$D:$D, "<>"), IF(_xlpm.errCount=0, "", _xlpm.errSum/_xlpm.errCount) ) -> 0.53255337 | C7: =_xlfn.LET( _xlpm.cam, $A7, _xlpm.errSum, SUMIFS(Log!$E:$E, Log!$B:$B, _xlpm.cam, Log!$E:$E, "<>"), _xlpm.errCount, COUNTIFS(Log!$B:$B, _xlpm.cam, Log!$E:$E, "<>"), IF(_xlpm.errCount=0, "", _xlpm.errSum/_xlpm.errCount) ) -> 0.10561092 | D7: =COUNTIFS(Log!$B:$B, $A7, Log!$H:$H, "Yes") -> 1 | E7: =COUNTIFS(Log!$B:$B, $A7, Log!$I:$I, "Yes") -> 1 | F7: =COUNTIFS(Log!$B:$B, $A7, Log!$H:$H, "No") -> 7 | G7: =COUNTIFS(Log!$B:$B, $A7, Log!$I:$I, "No") -> 7 | H7: =D7/COUNT(_xlfn.UNIQUE(Log!$A$3:$A$281)) -> 0.125 | I7: =E7/COUNT(_xlfn.UNIQUE(Log!$A$3:$A$281)) -> 0.125
A8: #5 (Vero v2.2) | B8: =_xlfn.LET( _xlpm.cam, $A8, _xlpm.errSum, SUMIFS(Log!$D:$D, Log!$B:$B, _xlpm.cam, Log!$D:$D, "<>"), _xlpm.errCount, COUNTIFS(Log!$B:$B, _xlpm.cam, Log!$D:$D, "<>"), IF(_xlpm.errCount=0, "", _xlpm.errSum/_xlpm.errCount) ) -> 0.27774037 | C8: =_xlfn.LET( _xlpm.cam, $A8, _xlpm.errSum, SUMIFS(Log!$E:$E, Log!$B:$B, _xlpm.cam, Log!$E:$E, "<>"), _xlpm.errCount, COUNTIFS(Log!$B:$B, _xlpm.cam, Log!$E:$E, "<>"), IF(_xlpm.errCount=0, "", _xlpm.errSum/_xlpm.errCount) ) -> 0.066344875 | D8: =COUNTIFS(Log!$B:$B, $A8, Log!$H:$H, "Yes") -> 8 | E8: =COUNTIFS(Log!$B:$B, $A8, Log!$I:$I, "Yes") -> 8 | F8: =COUNTIFS(Log!$B:$B, $A8, Log!$H:$H, "No") -> 0 | G8: =COUNTIFS(Log!$B:$B, $A8, Log!$I:$I, "No") -> 0 | H8: =D8/COUNT(_xlfn.UNIQUE(Log!$A$3:$A$281)) -> 1 | I8: =E8/COUNT(_xlfn.UNIQUE(Log!$A$3:$A$281)) -> 1
A9: #6 (Vero v2.2) | B9: =_xlfn.LET( _xlpm.cam, $A9, _xlpm.errSum, SUMIFS(Log!$D:$D, Log!$B:$B, _xlpm.cam, Log!$D:$D, "<>"), _xlpm.errCount, COUNTIFS(Log!$B:$B, _xlpm.cam, Log!$D:$D, "<>"), IF(_xlpm.errCount=0, "", _xlpm.errSum/_xlpm.errCount) ) -> 0.52327425 | C9: =_xlfn.LET( _xlpm.cam, $A9, _xlpm.errSum, SUMIFS(Log!$E:$E, Log!$B:$B, _xlpm.cam, Log!$E:$E, "<>"), _xlpm.errCount, COUNTIFS(Log!$B:$B, _xlpm.cam, Log!$E:$E, "<>"), IF(_xlpm.errCount=0, "", _xlpm.errSum/_xlpm.errCount) ) -> 0.1100429 | D9: =COUNTIFS(Log!$B:$B, $A9, Log!$H:$H, "Yes") -> 2 | E9: =COUNTIFS(Log!$B:$B, $A9, Log!$I:$I, "Yes") -> 6 | F9: =COUNTIFS(Log!$B:$B, $A9, Log!$H:$H, "No") -> 6 | G9: =COUNTIFS(Log!$B:$B, $A9, Log!$I:$I, "No") -> 2 | H9: =D9/COUNT(_xlfn.UNIQUE(Log!$A$3:$A$281)) -> 0.25 | I9: =E9/COUNT(_xlfn.UNIQUE(Log!$A$3:$A$281)) -> 0.75
A10: #7 (Vero v2.2) | B10: =_xlfn.LET( _xlpm.cam, $A10, _xlpm.errSum, SUMIFS(Log!$D:$D, Log!$B:$B, _xlpm.cam, Log!$D:$D, "<>"), _xlpm.errCount, COUNTIFS(Log!$B:$B, _xlpm.cam, Log!$D:$D, "<>"), IF(_xlpm.errCount=0, "", _xlpm.errSum/_xlpm.errCount) ) -> 0.46815687 | C10: =_xlfn.LET( _xlpm.cam, $A10, _xlpm.errSum, SUMIFS(Log!$E:$E, Log!$B:$B, _xlpm.cam, Log!$E:$E, "<>"), _xlpm.errCount, COUNTIFS(Log!$B:$B, _xlpm.cam, Log!$E:$E, "<>"), IF(_xlpm.errCount=0, "", _xlpm.errSum/_xlpm.errCount) ) -> 0.097598962 | D10: =COUNTIFS(Log!$B:$B, $A10, Log!$H:$H, "Yes") -> 2 | E10: =COUNTIFS(Log!$B:$B, $A10, Log!$I:$I, "Yes") -> 3 | F10: =COUNTIFS(Log!$B:$B, $A10, Log!$H:$H, "No") -> 6 | G10: =COUNTIFS(Log!$B:$B, $A10, Log!$I:$I, "No") -> 5 | H10: =D10/COUNT(_xlfn.UNIQUE(Log!$A$3:$A$281)) -> 0.25 | I10: =E10/COUNT(_xlfn.UNIQUE(Log!$A$3:$A$281)) -> 0.375
A11: #8 (Vero v2.2) | B11: =_xlfn.LET( _xlpm.cam, $A11, _xlpm.errSum, SUMIFS(Log!$D:$D, Log!$B:$B, _xlpm.cam, Log!$D:$D, "<>"), _xlpm.errCount, COUNTIFS(Log!$B:$B, _xlpm.cam, Log!$D:$D, "<>"), IF(_xlpm.errCount=0, "", _xlpm.errSum/_xlpm.errCount) ) -> 0.21789343 | C11: =_xlfn.LET( _xlpm.cam, $A11, _xlpm.errSum, SUMIFS(Log!$E:$E, Log!$B:$B, _xlpm.cam, Log!$E:$E, "<>"), _xlpm.errCount, COUNTIFS(Log!$B:$B, _xlpm.cam, Log!$E:$E, "<>"), IF(_xlpm.errCount=0, "", _xlpm.errSum/_xlpm.errCount) ) -> 0.065777 | D11: =COUNTIFS(Log!$B:$B, $A11, Log!$H:$H, "Yes") -> 7 | E11: =COUNTIFS(Log!$B:$B, $A11, Log!$I:$I, "Yes") -> 7 | F11: =COUNTIFS(Log!$B:$B, $A11, Log!$H:$H, "No") -> 0 | G11: =COUNTIFS(Log!$B:$B, $A11, Log!$I:$I, "No") -> 0 | H11: =D11/COUNT(_xlfn.UNIQUE(Log!$A$3:$A$281)) -> 0.875 | I11: =E11/COUNT(_xlfn.UNIQUE(Log!$A$3:$A$281)) -> 0.875 | L11: Note: camera 8 was mistakenly not included in 1st day win rate could be 1 higher
A12: #9 (Vero v2.2) | B12: =_xlfn.LET( _xlpm.cam, $A12, _xlpm.errSum, SUMIFS(Log!$D:$D, Log!$B:$B, _xlpm.cam, Log!$D:$D, "<>"), _xlpm.errCount, COUNTIFS(Log!$B:$B, _xlpm.cam, Log!$D:$D, "<>"), IF(_xlpm.errCount=0, "", _xlpm.errSum/_xlpm.errCount) ) -> 0.52183663 | C12: =_xlfn.LET( _xlpm.cam, $A12, _xlpm.errSum, SUMIFS(Log!$E:$E, Log!$B:$B, _xlpm.cam, Log!$E:$E, "<>"), _xlpm.errCount, COUNTIFS(Log!$B:$B, _xlpm.cam, Log!$E:$E, "<>"), IF(_xlpm.errCount=0, "", _xlpm.errSum/_xlpm.errCount) ) -> 0.10166336 | D12: =COUNTIFS(Log!$B:$B, $A12, Log!$H:$H, "Yes") -> 0 | E12: =COUNTIFS(Log!$B:$B, $A12, Log!$I:$I, "Yes") -> 6 | F12: =COUNTIFS(Log!$B:$B, $A12, Log!$H:$H, "No") -> 8 | G12: =COUNTIFS(Log!$B:$B, $A12, Log!$I:$I, "No") -> 2 | H12: =D12/COUNT(_xlfn.UNIQUE(Log!$A$3:$A$281)) -> 0 | I12: =E12/COUNT(_xlfn.UNIQUE(Log!$A$3:$A$281)) -> 0.75
A13: #10 (Vero v2.2) | B13: =_xlfn.LET( _xlpm.cam, $A13, _xlpm.errSum, SUMIFS(Log!$D:$D, Log!$B:$B, _xlpm.cam, Log!$D:$D, "<>"), _xlpm.errCount, COUNTIFS(Log!$B:$B, _xlpm.cam, Log!$D:$D, "<>"), IF(_xlpm.errCount=0, "", _xlpm.errSum/_xlpm.errCount) ) -> 0.43146163 | C13: =_xlfn.LET( _xlpm.cam, $A13, _xlpm.errSum, SUMIFS(Log!$E:$E, Log!$B:$B, _xlpm.cam, Log!$E:$E, "<>"), _xlpm.errCount, COUNTIFS(Log!$B:$B, _xlpm.cam, Log!$E:$E, "<>"), IF(_xlpm.errCount=0, "", _xlpm.errSum/_xlpm.errCount) ) -> 0.11597657 | D13: =COUNTIFS(Log!$B:$B, $A13, Log!$H:$H, "Yes") -> 3 | E13: =COUNTIFS(Log!$B:$B, $A13, Log!$I:$I, "Yes") -> 3 | F13: =COUNTIFS(Log!$B:$B, $A13, Log!$H:$H, "No") -> 5 | G13: =COUNTIFS(Log!$B:$B, $A13, Log!$I:$I, "No") -> 5 | H13: =D13/COUNT(_xlfn.UNIQUE(Log!$A$3:$A$281)) -> 0.375 | I13: =E13/COUNT(_xlfn.UNIQUE(Log!$A$3:$A$281)) -> 0.375
A14: #11 (Vero v2.2) | B14: =_xlfn.LET( _xlpm.cam, $A14, _xlpm.errSum, SUMIFS(Log!$D:$D, Log!$B:$B, _xlpm.cam, Log!$D:$D, "<>"), _xlpm.errCount, COUNTIFS(Log!$B:$B, _xlpm.cam, Log!$D:$D, "<>"), IF(_xlpm.errCount=0, "", _xlpm.errSum/_xlpm.errCount) ) -> 0.35101187 | C14: =_xlfn.LET( _xlpm.cam, $A14, _xlpm.errSum, SUMIFS(Log!$E:$E, Log!$B:$B, _xlpm.cam, Log!$E:$E, "<>"), _xlpm.errCount, COUNTIFS(Log!$B:$B, _xlpm.cam, Log!$E:$E, "<>"), IF(_xlpm.errCount=0, "", _xlpm.errSum/_xlpm.errCount) ) -> 0.11641033 | D14: =COUNTIFS(Log!$B:$B, $A14, Log!$H:$H, "Yes") -> 3 | E14: =COUNTIFS(Log!$B:$B, $A14, Log!$I:$I, "Yes") -> 2 | F14: =COUNTIFS(Log!$B:$B, $A14, Log!$H:$H, "No") -> 5 | G14: =COUNTIFS(Log!$B:$B, $A14, Log!$I:$I, "No") -> 6 | H14: =D14/COUNT(_xlfn.UNIQUE(Log!$A$3:$A$281)) -> 0.375 | I14: =E14/COUNT(_xlfn.UNIQUE(Log!$A$3:$A$281)) -> 0.25
