Workbook

Sheet WIP
A1: How this workbook works
A3: 1. Log sheet | C3: UPDATE THIS TAB
A4: Each day, add one new row per camera to the table (just type into the row directly below the last one - the table expands automatically). | C4: VERY OUT OF DATE
A5: Columns: Date, Camera, Wand Count, World Error, Image Error.
A6: The Camera column has a dropdown so names stay consistent. | D6: HIDDEN SHEETS
D7: Data-Lists
A8: 2. Daily Summary sheet
A9: Automatically averages World Error and Image Error across all cameras for each date, and counts how many cameras were logged that day (flags red if it isn't 17, so you notice a missed camera). Pre-built with formulas for the next ~150 days - nothing to edit. | D9: Sheets
A10: Chart: average error trend over time, across the whole rig. | D10: Labelling
D11: Log
A12: 3. Camera Trend sheet | D12: Recap Pages | E12: Daily, Trial, Error
A13: Pick a camera from the dropdown in the highlighted cell and its own error history over time appears in the table and chart below. Useful for spotting a camera that's drifting or degrading. | D13: Daily Trends
D14: Daily Performance
A15: 4. Lists sheet | D15: Daily Error Rates
A16: Just holds the camera name list that powers the dropdowns. Hidden by default - unhide it (right-click any sheet tab) if you add or retire a camera. | D16: Problem Cameras
A18: Cells you edit day-to-day are highlighted in pale yellow. Everything else is a formula and updates itself. | D18: Sheets should have own to-dos

Sheet Data-Lists
A1: The spreadsheet relies on this information don't tinker with it if you aren't prepared to fix it afterwards! Bolded entries are hardcoded. Other entries are formulas or lookups.
A2: Camera | B2: Daily Tracking Dates | C2: Key Category | D2: =CONCATENATE("Subkeys (", $C$4, ")") -> Subkeys (Error) | E2: =CONCATENATE("Subkeys (", $C$5, ")") -> Subkeys (Trial) | F2: Wand Wave Type
A3: #1 (Vero v2.2) | B3: {=_xlfn.CHOOSECOLS(_xlfn.UNIQUE(_xlfn._xlws.FILTER(Log!$A3:$C5000,Log!$A3:$A5000="Daily")),3)} -> 46228 | C3: Daily | D3: {=_xlfn._xlws.SORT(_xlfn.UNIQUE(_xlfn._xlws.FILTER(Log!B3:B5000, Log!A3:A5000=C4)))} -> 03/08-error1 | E3: {=_xlfn._xlws.SORT(_xlfn.UNIQUE(_xlfn._xlws.FILTER(Log!B3:B5000, Log!A3:A5000=C5)))} -> auto-stop-1000-base | F3: {=Legend!$G$10:$G50} -> A
A4: #2 (Vero v2.2) | B4: 46230 | C4: Error | D4: 03/08-error2 | E4: auto-stop-1000-v2 | F4: B
A5: #3 (Vero v2.2) | B5: 46231 | C5: Trial | D5: 20/08-error1 | E5: auto-stop-1000-v3 | F5: C
A6: #4 (Vero v2.2) | B6: 46232 | D6: 31/07-error1 | E6: auto-stop-1500-v1 | F6: D
A7: #5 (Vero v2.2) | B7: 46233 | D7: 31/07-error2 | E7: auto-stop-1500-v2 | F7: E
A8: #6 (Vero v2.2) | B8: 46234 | D8: cannot-set-volume | E8: auto-stop-2000-v1 | F8: F
A9: #7 (Vero v2.2) | B9: 46235 | D9: didn't-set-volume | E9: auto-stop-2000-v2 | F9: G
A10: #8 (Vero v2.2) | B10: 46237 | D10: no-reset-grayscale-all | E10: reflection-trial-2 | F10: H
A11: #9 (Vero v2.2) | B11: 46238 | E11: shelf-baseline | F11: I
A12: #10 (Vero v2.2) | B12: 46239 | E12: shelf-trial | F12: 0
A13: #11 (Vero v2.2) | B13: 46240 | E13: speed_cam11_fast_1 | F13: 0
A14: #12 (Vero v2.2) | B14: 46242 | E14: speed_cam11_fast_2 | F14: 0
A15: #13 (Vero v2.2) | B15: 46244 | E15: speed_cam11_fast_3 | F15: 0
A16: #14 (Vero v2.2) | B16: 46245 | E16: speed_cam11_slow_1 | F16: 0
A17: #15 (Vero v2.2) | B17: 46246 | E17: speed_cam11_slow_2 | F17: 0
A18: #16 (Vero v2.2) | B18: 46247 | E18: speed_cam11_slow_3 | F18: 0
A19: #17 (Vero v2.2) | B19: 46248 | E19: Wand-Wave-A1 | F19: 0
A20: #18 (Vero v2.2) | B20: 46251 | E20: Wand-Wave-A2 | F20: 0
B21: 46251 | E21: Wand-Wave-A3 | F21: 0
B22: 46251 | E22: Wand-Wave-A4 | F22: 0
B23: 46252 | E23: Wand-Wave-B1 | F23: 0
B24: 46253 | E24: Wand-Wave-B2 | F24: 0
B25: 46254 | E25: Wand-Wave-B3 | F25: 0
B26: 46255 | E26: Wand-Wave-B4 | F26: 0
E27: Wand-Wave-C1 | F27: 0
E28: Wand-Wave-C2 | F28: 0
E29: Wand-Wave-C3 | F29: 0
E30: Wand-Wave-C4 | F30: 0
E31: Wand-Wave-D1 | F31: 0
E32: Wand-Wave-D2 | F32: 0
E33: Wand-Wave-D3 | F33: 0
E34: Wand-Wave-D4 | F34: 0
E35: Wand-Wave-E1 | F35: 0
E36: Wand-Wave-E2 | F36: 0
E37: Wand-Wave-E3 | F37: 0
E38: Wand-Wave-E4 | F38: 0
... E43: Wand-Wave-G1 | F43: 0
E44: Wand-Wave-G2
...

Sheet Legend
A1: Sheet legend to identify the colours and labels used throughout the sheet
B3: Cameras in the INB Robotics/Vicon lab are labelled differently to the Nexus software, I've recorded the differences here. If this ever changes, correct this and keep record for data.
B4: Camera Name | C4: Nexus Software ID | D4: Physical Label | E4: Match | G4: HEADER COLOURS
B5: #1 (Vero v2.2) | C5: 1 | D5: 1 | E5: =IF(C5=D5, "Yes", "No") -> Yes | H5: Data should be input in this column.
B6: #2 (Vero v2.2) | C6: 2 | D6: 2 | E6: =IF(C6=D6, "Yes", "No") -> Yes | H6: Choose data value from dropdown!
B7: #3 (Vero v2.2) | C7: 3 | D7: 4 | E7: =IF(C7=D7, "Yes", "No") -> No | H7: Automatic formula - do not modify this column.
B8: #4 (Vero v2.2) | C8: 4 | D8: 18 | E8: =IF(C8=D8, "Yes", "No") -> No
B9: #5 (Vero v2.2) | C9: 5 | D9: 5 | E9: =IF(C9=D9, "Yes", "No") -> Yes | G9: Wand Techniques (documented by motion capture on 13/08/2026)
B10: #6 (Vero v2.2) | C10: 6 | D10: 6 | E10: =IF(C10=D10, "Yes", "No") -> Yes | G10: A | H10: Waving in figure 8, slowly - as though you're pushing water - pushing downards whilst walking around the room in a square
B11: #7 (Vero v2.2) | C11: 7 | D11: 7 | E11: =IF(C11=D11, "Yes", "No") -> Yes | G11: B | H11: As technique A except - bringing the wand in and out by stretching arm, and stooping/lunging as moving (in order to vary distance from the body)
B12: #8 (Vero v2.2) | C12: 8 | D12: 8 | E12: =IF(C12=D12, "Yes", "No") -> Yes | G12: C | H12: Guidance from active wand v4 (away from body, half circles, facing camera, no turning wand keep parallel to yourself, watch for objects)
B13: #9 (Vero v2.2) | C13: 9 | D13: 14 | E13: =IF(C13=D13, "Yes", "No") -> No | G13: D | H13: Figure 8 with the wand facing up - reccommended by the Vicon trainer during system installation
B14: #10 (Vero v2.2) | C14: 10 | D14: 10 | E14: =IF(C14=D14, "Yes", "No") -> Yes | G14: E | H14: Spinning the wand extended from body (rotating around center 360deg holding wand in middle but spinning it)
B15: #11 (Vero v2.2) | C15: 11 | D15: 11 | E15: =IF(C15=D15, "Yes", "No") -> Yes | G15: F | H15: Wave wand up and down (chopping axe motion, AWIR2 docs)
B16: #12 (Vero v2.2) | C16: 12 | D16: 12 | E16: =IF(C16=D16, "Yes", "No") -> Yes | G16: G | H16: Circling the wand extended from body (hold forward & draw circle, rotating around center 360deg holding handle - full circle vs C semi-circle)
B17: #13 (Vero v2.2) | C17: 13 | D17: 13 | E17: =IF(C17=D17, "Yes", "No") -> Yes | G17: H | H17: New technique after wand wave experiment - not captured yet - per technique D except wider figure 8 and more vertical/horizontal movement, held further away from user body to prevent occlusion.
B18: #14 (Vero v2.2) | C18: 14 | D18: 14 | E18: =IF(C18=D18, "Yes", "No") -> Yes | G18: I | H18: New technique after wand wave experiment - not captured yet - per technique H except attempting to paint space, turning body profile to prevent occlusion, and starting from inside of volume.
B19: #15 (Vero v2.2) | C19: 15 | D19: 15 | E19: =IF(C19=D19, "Yes", "No") -> Yes
B20: #16 (Vero v2.2) | C20: 16 | D20: 16 | E20: =IF(C20=D20, "Yes", "No") -> Yes
B21: #17 (Vero v2.2) | C21: 17 | D21: 3 | E21: =IF(C21=D21, "Yes", "No") -> No
B22: #18 (Vero v2.2) | C22: 18 | D22: 17 | E22: =IF(C22=D22, "Yes", "No") -> No

Sheet Log
A1: Instructions - Input Vicon Nexus error sets after any new calibration. Refer to header key tables for more info. | F1: Error (Camera Entry)
A2: Key 1 (Category) | B2: Key 2 (Precision) | C2: Date | D2: Camera | E2: Frame Count | F2: World Error | G2: Image Error
A3: Daily | B3: n/a | C3: 46228 | D3: #1 (Vero v2.2) | E3: 2306 | F3: 0.274982 | G3: 0.0793568
A4: Daily | B4: n/a | C4: 46228 | D4: #2 (Vero v2.2) | E4: 2392 | F4: 0.421843 | G4: 0.112306
A5: Daily | B5: n/a | C5: 46228 | D5: #3 (Vero v2.2) | E5: 1810 | F5: 0.398584 | G5: 0.0924275
A6: Daily | B6: n/a | C6: 46228 | D6: #4 (Vero v2.2) | E6: 2277 | F6: 0.620036 | G6: 0.121579
A7: Daily | B7: n/a | C7: 46228 | D7: #5 (Vero v2.2) | E7: 2240 | F7: 0.191893 | G7: 0.0443669
A8: Daily | B8: n/a | C8: 46228 | D8: #6 (Vero v2.2) | E8: 2754 | F8: 0.442235 | G8: 0.0899754
A9: Daily | B9: n/a | C9: 46228 | D9: #7 (Vero v2.2) | E9: 3007 | F9: 0.509896 | G9: 0.102799
A10: Daily | B10: n/a | C10: 46228 | D10: #9 (Vero v2.2) | E10: 2832 | F10: 0.395935 | G10: 0.0795796
A11: Daily | B11: n/a | C11: 46228 | D11: #10 (Vero v2.2) | E11: 2120 | F11: 0.499606 | G11: 0.132037
A12: Daily | B12: n/a | C12: 46228 | D12: #11 (Vero v2.2) | E12: 1471 | F12: 0.130593 | G12: 0.0450561
A13: Daily | B13: n/a | C13: 46228 | D13: #12 (Vero v2.2) | E13: 1657 | F13: 0.428371 | G13: 0.140663
A14: Daily | B14: n/a | C14: 46228 | D14: #13 (Vero v2.2) | E14: 1007 | F14: 0.168386 | G14: 0.0424158
... A1027: Trial | B1027: Wand-Wave-G4 | C1027: 46246 | D1027: #18 (Vero v2.2) | E1027: 1442 | F1027: 0.431939 | G1027: 0.083982
A1028: Daily | B1028: =IF($A1028="Daily", "n/a", "") -> n/a | C1028: 46247 | D1028: #1 (Vero v2.2) | E1028: 2333 | F1028: 0.405133 | G1028: 0.113922
A1029: Daily | B1029: =IF($A1029="Daily", "n/a", "") -> n/a | C1029: 46247 | D1029: #2 (Vero v2.2) | E1029: 1823 | F1029: 0.45546 | G1029: 0.120023
A1030: Daily | B1030: =IF($A1030="Daily", "n/a", "") -> n/a | C1030: 46247 | D1030: #3 (Vero v2.2) | E1030: 1149 | F1030: 0.377453 | G1030: 0.0885529
A1031: Daily | B1031: =IF($A1031="Daily", "n/a", "") -> n/a | C1031: 46247 | D1031: #4 (Vero v2.2) | E1031: 1864 | F1031: 0.450706 | G1031: 0.0891205
A1032: Daily | B1032: =IF($A1032="Daily", "n/a", "") -> n/a | C1032: 46247 | D1032: #5 (Vero v2.2) | E1032: 1421 | F1032: 0.217182 | G1032: 0.0516624
A1033: Daily | B1033: =IF($A1033="Daily", "n/a", "") -> n/a | C1033: 46247 | D1033: #6 (Vero v2.2) | E1033: 1542 | F1033: 0.353803 | G1033: 0.0743878
A1034: Daily | B1034: =IF($A1034="Daily", "n/a", "") -> n/a | C1034: 46247 | D1034: #7 (Vero v2.2) | E1034: 1458 | F1034: 0.353749 | G1034: 0.07398
A1035: Daily | B1035: =IF($A1035="Daily", "n/a", "") -> n/a | C1035: 46247 | D1035: #8 (Vero v2.2) | E1035: 1092 | F1035: 0.182155 | G1035: 0.0552003
A1036: Daily | B1036: =IF($A1036="Daily", "n/a", "") -> n/a | C1036: 46247 | D1036: #9 (Vero v2.2) | E1036: 2428 | F1036: 0.536396 | G1036: 0.104331
A1037: Daily | B1037: =IF($A1037="Daily", "n/a", "") -> n/a | C1037: 46247 | D1037: #10 (Vero v2.2) | E1037: 1369 | F1037: 0.388751 | G1037: 0.105559
A1038: Daily | B1038: =IF($A1038="Daily", "n/a", "") -> n/a | C1038: 46247 | D1038: #11 (Vero v2.2) | E1038: 1535 | F1038: 0.381734 | G1038: 0.12531
A1039: Daily | B1039: =IF($A1039="Daily", "n/a", "") -> n/a | C1039: 46247 | D1039: #12 (Vero v2.2) | E1039: 2256 | F1039: 0.18396 | G1039: 0.0566614
... A1045: Daily | B1045: =IF($A1045="Daily", "n/a", "") -> n/a | C1045: 46247 | D1045: #18 (Vero v2.2) | E1045: 1133 | F1045: 0.37192 | G1045: 0.0748058
A1046: Error | B1046: cannot-set-volume | C1046: 46248 | D1046: #1 (Vero v2.2) | E1046: 1484 | F1046: 0.514719 | G1046: 0.144732
A1047: Error | B1047: cannot-set-volume | C1047: 46248 | D1047: #2 (Vero v2.2) | E1047: 1290 | F1047: 0.517445 | G1047: 0.136305
A1048: Error | B1048: cannot-set-volume | C1048: 46248 | D1048: #3 (Vero v2.2) | E1048: 1093 | F1048: 0.503747 | G1048: 0.11812
A1049: Error | B1049: cannot-set-volume | C1049: 46248 | D1049: #4 (Vero v2.2) | E1049: 1834 | F1049: 0.473553 | G1049: 0.0936151
A1050: Error | B1050: cannot-set-volume | C1050: 46248 | D1050: #5 (Vero v2.2) | E1050: 1247 | F1050: 0.305897 | G1050: 0.072731
A1051: Error | B1051: cannot-set-volume | C1051: 46248 | D1051: #6 (Vero v2.2) | E1051: 1230 | F1051: 0.418566 | G1051: 0.0880348
A1052: Error | B1052: cannot-set-volume | C1052: 46248 | D1052: #7 (Vero v2.2) | E1052: 1058 | F1052: 0.451663 | G1052: 0.0944804
A1053: Error | B1053: cannot-set-volume | C1053: 46248 | D1053: #8 (Vero v2.2) | E1053: 1367 | F1053: 0.216456 | G1053: 0.065589
A1054: Error | B1054: cannot-set-volume | C1054: 46248 | D1054: #9 (Vero v2.2) | E1054: 1961 | F1054: 0.61155 | G1054: 0.118918
A1055: Error | B1055: cannot-set-volume | C1055: 46248 | D1055: #10 (Vero v2.2) | E1055: 2148 | F1055: 0.393646 | G1055: 0.106936
A1056: Error | B1056: cannot-set-volume | C1056: 46248 | D1056: #11 (Vero v2.2) | E1056: 1200 | F1056: 0.3096 | G1056: 0.101543
A1057: Error | B1057: cannot-set-volume | C1057: 46248 | D1057: #12 (Vero v2.2) | E1057: 1803 | F1057: 0.483261 | G1057: 0.148862
...

Sheet Sets
A1: Key 1 (Category) | B1: Key 2 (Precision) | C1: Date | D1: Starting Temperature | E1: Starting Time | F1: Wand Technique | G1: Auto-Stop Setting | H1: Notes on daily calibration attempt | I1: Other notes - error results, experiment process, etc. | J1: Other notes to combine | K1: Mean Frame Count | L1: Frame Ratio (% of Auto-Stop) | M1: Highest Frame Count | N1: Lowest Frame Count | O1: Most Frames (Camera ID) | P1: Least Frames (Camera ID) | Q1: Mean World Error | R1: Lowest World Error | S1: Highest World Error | T1: Mean Image Error | U1: Lowest Image Error | V1: Highest Image Error | W1: All-Time Mean Values | Y1: Dates auto-populate from data-lists tab (apply to all daily sheets). Data keys & config settings must be manually entered. Other data will automatically populate by formula and apply conditional formatting. | CQ1: All-Time Mean Values
A2: {=_xlfn.CHOOSECOLS(_xlfn.UNIQUE(Log!$A3:$C3000),1, 2, 3)} -> Daily | B2: n/a | C2: 46228 | D2: 23.5 | E2: 0.85833333 | F2: A | G2: 1000 | H2: Camera 8 not enabled by mistake -- may wish to disregard results, no manual masking or marker removal attempted - attempting to establish baselines | W2: 0.41503633 | X2: 0.099319293 | CQ2: 0.41503633 | CR2: 0.099319293 | CT2: FOR CHART
A3: Daily | B3: n/a | C3: 46230 | D3: 23.5 | E3: 0.60138889 | F3: A | G3: 1000 | H3: Did not create a box with markers, scattered randomly, adjusted auto detect tolerance for set volume down to 2mm | W3: 0.41503633 | X3: 0.099319293 | CQ3: 0.41503633 | CR3: 0.099319293 | CT3: DO NOT TOUCH
A4: Daily | B4: n/a | C4: 46231 | D4: 24.5 | E4: 0.50694444 | F4: B | G4: 1000 | H4: Scattered markers randomly in the volume, completely reset calibration and masking beforehand, manually masked reflective pipe in camera 5. | W4: 0.41503633 | X4: 0.099319293 | CQ4: 0.41503633 | CR4: 0.099319293
A5: Daily | B5: n/a | C5: 46232 | D5: 25.5 | E5: 0.82291667 | F5: A | G5: 1000 | H5: Mostly focused on fixing the calibration data pollution bug from sample data (camera IDs reorganised) but sweeping movements around the main volume, with markers scattered in clusters no box outline | W5: 0.41503633 | X5: 0.099319293 | CQ5: 0.41503633 | CR5: 0.099319293
A6: Daily | B6: n/a | C6: 46233 | D6: 24.5 | E6: 0.53333333 | F6: A | G6: 1000 | H6: After calibration modified level of the L-Frame as floor wasn't level, so this may affect volume capture in future | W6: 0.41503633 | X6: 0.099319293 | CQ6: 0.41503633 | CR6: 0.099319293
A7: Error | B7: 31/07-error1 | C7: 46234 | D7: 23.5 | E7: 0.85833333 | F7: C | G7: 1000 | H7: No swish/figure 8, followed active wand v4 docs which suggested keeping wand away from body due to occlusion, and facing cameras. Waved in mostly large (sometimes small) circles | I7: People kept coming in room, interrupting calibration attempts - along with poor wand wave & previous wand level modification could not set volume | W7: 0.41503633 | X7: 0.099319293 | CQ7: 0.41503633 | CR7: 0.099319293
A8: Error | B8: 31/07-error2 | C8: 46234 | D8: 23.5 | E8: 0.60138889 | F8: C | G8: 1000 | I8: todo - check calibration data for camera relativity | W8: 0.41503633 | X8: 0.099319293 | CQ8: 0.41503633 | CR8: 0.099319293
A9: Daily | B9: n/a | C9: 46234 | D9: 24.5 | E9: 0.58333333 | F9: C | G9: 1500 | H9: Missing XCP File! Following 2 wand count errors increased auto stop min frames to 1500 and spread time more equally in volume. Worsening world and image errors! To repeat on 1-2 tests to confirm | W9: 0.41503633 | X9: 0.099319293 | CQ9: 0.41503633 | CR9: 0.099319293
A10: Daily | B10: n/a | C10: 46235 | D10: 24 | E10: 0.74097222 | F10: C | G10: 1500 | H10: Minor wand wave not according to technique (folding wave) but otherwise going left/right and keeping away from body. Some camera error outliers and ghost markers during floor plane calibration. | W10: 0.41503633 | X10: 0.099319293 | CQ10: 0.41503633 | CR10: 0.099319293
A11: Error | B11: 03/08-error1 | C11: 46237 | D11: 24.5 | E11: 0.50694444 | F11: C | G11: 1000 | H11: Wand wave technique is semi-radial extended from body but facing/relative degree° equal to facing (rocking side to side drawing a semi-circle basically) with some squatting or bending down | I11: Camera 4 not relative to rest | W11: 0.41503633 | X11: 0.099319293 | CQ11: 0.41503633 | CR11: 0.099319293
A12: Error | B12: 03/08-error2 | C12: 46237 | D12: 25.5 | E12: 0.82291667 | F12: C | G12: 1000 | H12: Wand wave technique as above | I12: Camera 5 not relative to rest | W12: 0.41503633 | X12: 0.099319293 | CQ12: 0.41503633 | CR12: 0.099319293
A13: Daily | B13: n/a | C13: 46237 | D13: 24 | E13: 0.46597222 | F13: A | G13: 1000 | H13: Reverted wand wave technique after 2 calibration errors Opting to put clusters of 3 in volume corners and spacing out pairs elsewhere in centre of volume floor plane | W13: 0.41503633 | X13: 0.099319293 | CQ13: 0.41503633 | CR13: 0.099319293
A14: Daily | B14: n/a | C14: 46238 | D14: 24.5 | E14: 0.52083333 | F14: A | G14: 1000 | H14: No box; markers were in a rough isoclees triangle shape outline, of 4x clusters of 3 markers, no issue | W14: 0.41503633 | X14: 0.099319293 | CQ14: 0.41503633 | CR14: 0.099319293
A15: Daily | B15: n/a | C15: 46239 | D15: 25 | E15: 0.59305556 | F15: A | G15: 1000 | H15: 9 Markers, in 3 clusters of 3 -- two clusters spaced from origin, one in a far corner. This caused floor plane error for furthest markers so added a 4th cluster in opposite far corner, which fixed it. Documented in note '2026-08-05 Marker Cluster Layout (v1)' | W15: 0.41503633 | X15: 0.099319293 | CQ15: 0.41503633 | CR15: 0.099319293
A16: Daily | B16: n/a | C16: 46240 | D16: 25 | E16: 0.47569444 | F16: A | G16: 1000 | H16: 3 clusters of markers in each corner (4 sets) | W16: 0.41503633 | X16: 0.099319293 | CQ16: 0.41503633 | CR16: 0.099319293
A17: Trial | B17: shelf-baseline | C17: 46240 | D17: 25 | E17: 0.64722222 | F17: A | G17: 1000 | H17: Figure 8 waving, no floor plane setting as just interested in calibration data | I17: Determine the calibration impact of the reflective metal shelving at the edge of the volume space | J17: Calibration health degraded. Culprit may be that a reflective shelf may have still been caught in view of a camera | W17: 0.41503633 | X17: 0.099319293 | CQ17: 0.41503633 | CR17: 0.099319293
A18: Trial | B18: shelf-trial | C18: 46240 | D18: 25 | E18: 0.66041667 | F18: A | G18: 1000 | W18: 0.41503633 | X18: 0.099319293 | CQ18: 0.41503633 | CR18: 0.099319293
A19: Daily | B19: n/a | C19: 46242 | D19: 24.5 | E19: 0.62361111 | F19: A | G19: 1000 | H19: Using as experiment base-set (duplicated for auto-stop-base) as immediately before so maintaining '3 clusters of markers in each corner (4 sets)' and wave technique A as controls | W19: 0.41503633 | X19: 0.099319293 | CQ19: 0.41503633 | CR19: 0.099319293
A20: Trial | B20: auto-stop-1000-base | C20: 46242 | D20: 24.5 | E20: 0.62361111 | F20: A | G20: 1000 | H20: Using daily calibration as base-set (duplicated from 08/08/2026) as immediately before so maintaining '3 clusters of markers in each corner (4 sets)' and wave technique A as controls. Environment unchanged but masked cameras at start of each wand wave to prevent light change impact. Did not set floor plane as just interested in calibration data. Minor mistake in 1000v2 where a camera was still trying to calibrate - didn't notice and had to get up again to fix. Repeated trial for bias check. | I20: Investigate effectiveness of auto-stop and wand frames on calibration health | J20: see calibration notes.md, but rough findings are more frames = faster calibration, longer taken in wand wave, better camera health. auto-stop 2000 = 3m feedback, 2:25 wand wave auto-stop 1500 = 3-5m feedback, 1:57 wand wave auto-stop 1000 = 3-6m feedback, 1:32 wand wave Worth looking at problem camera health specifically as disproprtionate wand wave time spent focused on these auto-stop-2000-v1 has relative camera error (cam 5) | W20: 0.41503633 | X20: 0.099319293 | CQ20: 0.41503633 | CR20: 0.099319293
A21: Trial | B21: auto-stop-2000-v1 | C21: 46242 | D21: 24.5 | E21: 0.63680556 | F21: A | G21: 2000 | W21: 0.41503633 | X21: 0.099319293 | CQ21: 0.41503633 | CR21: 0.099319293
A22: Trial | B22: auto-stop-2000-v2 | C22: 46242 | D22: 24.5 | E22: 0.65625 | F22: A | G22: 2000 | W22: 0.41503633 | X22: 0.099319293 | CQ22: 0.41503633 | CR22: 0.099319293
A23: Trial | B23: auto-stop-1500-v1 | C23: 46242 | D23: 24.5 | E23: 0.65902778 | F23: A | G23: 1500 | W23: 0.41503633 | X23: 0.099319293 | CQ23: 0.41503633 | CR23: 0.099319293
A24: Trial | B24: auto-stop-1500-v2 | C24: 46242 | D24: 24.5 | E24: 0.65902778 | F24: A | G24: 1500 | W24: 0.41503633 | X24: 0.099319293 | CQ24: 0.41503633 | CR24: 0.099319293
A25: Trial | B25: auto-stop-1000-v2 | C25: 46242 | D25: 24.5 | E25: 0.65902778 | F25: A | G25: 1000 | W25: 0.41503633 | X25: 0.099319293 | CQ25: 0.41503633 | CR25: 0.099319293
A26: Trial | B26: auto-stop-1000-v3 | C26: 46242 | D26: 24.5 | E26: 0.68958333 | F26: A | G26: 1000
A27: Daily | B27: n/a | C27: 46244 | D27: 24 | E27: 0.52777778 | F27: D | G27: 1000
A28: Daily | B28: n/a | C28: 46245 | D28: 24 | E28: 0.42777778 | F28: E | G28: 1000 | H28: Markers in 4x cluters of 3 around volume origin (creating a rough box)
A29: Error | B29: didn't-set-volume | C29: 46246 | D29: 24.5 | E29: 0.45277778 | F29: F | G29: 1000 | I29: Calibrated out of daily habit and moved on to wand-wave trial resume before setting origin/plane in volume as wasn't needed, then environment was changed and calibrations were stale
A30: Daily | B30: n/a | C30: 46246 | D30: 25 | E30: 0.61597222 | F30: G | G30: 1000 | H30: Markers in 4x cluters of 3 closely around volume origin (creating a rough box)
A31: Trial | B31: Wand-Wave-A1 | C31: 46245 | D31: 24 | E31: 0.47361111 | F31: A | G31: 1000 | H31: same volume walking strategy out round volume from workstation (walking anticlockwise), walking the exterior before moving inwards and then back outwards to focus on problem/uncalibrated cameras setting mask before each trial to ensure environment isn't changing due to sunlight no floor plane or origin setting - purely interested in camera health manually saving wand wave visual data after calibration & checking 3d perspective for relative calibration | I31: Determine the most effective wand waving technique for camera health & tracking improvement | J31: See markdown notes
A32: Trial | B32: Wand-Wave-A2 | C32: 46245 | D32: 24 | E32: 0.48472222 | F32: A | G32: 1000
A33: Trial | B33: Wand-Wave-A3 | C33: 46245 | D33: 24 | E33: 0.49513889 | F33: A | G33: 1000
A34: Trial | B34: Wand-Wave-A4 | C34: 46246 | D34: 25 | E34: 0.46180556 | F34: A | G34: 1000 | I34: 0.058333333
A35: Trial | B35: Wand-Wave-B1 | C35: 46245 | D35: 24 | E35: 0.52152778 | F35: B | G35: 1000
A36: Trial | B36: Wand-Wave-B2 | C36: 46245 | D36: 24 | E36: 0.52430556 | F36: B | G36: 1000
A37: Trial | B37: Wand-Wave-B3 | C37: 46245 | D37: 24 | E37: 0.56666667 | F37: B | G37: 1000
A38: Trial | B38: Wand-Wave-B4 | C38: 46246 | D38: 25 | E38: 0.46736111 | F38: B | G38: 1000 | I38: 0.065972222
A39: Trial | B39: Wand-Wave-C1 | C39: 46245 | D39: 24 | E39: 0.57430556 | F39: C | G39: 1000
A40: Trial | B40: Wand-Wave-C2 | C40: 46245 | D40: 24 | E40: 0.57777778 | F40: C | G40: 1000
...

Sheet Problem Cameras
A1: Calibrations earlier to 31/07/26 discarded error data & predate error tracking tabs
A2: Camera Bumping Error Count | F2: 12 | H2: 1 | I2: 1 | J2: 4 | L2: 7 | O2: 3 | P2: 8 | R2: 1
A3: Date | B3: Camera by ID | C3: {=LEFT(TRANSPOSE('[1]Data-Lists'!A4:A21), 3)} -> #1 | D3: #2 | E3: #3 | F3: #4 | G3: #5 | H3: #6 | I3: #7 | J3: #8 | K3: #9 | L3: #10 | M3: #11 | N3: #12 | O3: #13 | P3: #14 | Q3: #15 | R3: #16 | S3: #17 | T3: #18
A4: {=_xlfn.UNIQUE(_xlfn._xlws.FILTER([1]Log!$C:$C, ([1]Log!$B:B="n/a") * ([1]Log!$A:$A="Daily")))} -> 46228
A5: 46230 | W5: KEY
A6: 46231 | V6: x | W6: Relative position calibration error
A7: 46232 | W7: Auto-stop straggler
A8: 46233
A9: 46234 | G9: 1 | I9: 2
A10: 46235
A11: 46237 | F11: 1 | G11: 1
A12: 46238
A13: 46239
A14: 46240 | V14: {=_xlfn.TEXTSPLIT("Note: Need to explore earlier: calibrations for relative errors!", , ":")} -> Note
A15: 46242 | G15: 1 | V15: Need to explore earlier
A16: 46244 | V16: calibrations for relative errors!
A17: 46245
A18: 46246
A19: 46247
A20: 46248
A21: 46251
A22: 46252
A23: 46253
A24: 46254
A25: 46255
