Workbook

Sheet WIP
A1: DO NOT USE THIS SPREADSHEET, IT IS DEPRECATED AND KEPT ONLY AS REFERENCE FOR FINAL DATA REPRESENTATIONS
A2: How this workbook works
A4: 1. Log sheet | C4: UPDATE THIS TAB
A5: Each day, add one new row per camera to the table (just type into the row directly below the last one - the table expands automatically). | C5: VERY OUT OF DATE
A6: Columns: Date, Camera, Wand Count, World Error, Image Error.
A7: The Camera column has a dropdown so names stay consistent. | D7: HIDDEN SHEETS
D8: Data-Lists
A9: 2. Daily Summary sheet
A10: Automatically averages World Error and Image Error across all cameras for each date, and counts how many cameras were logged that day (flags red if it isn't 17, so you notice a missed camera). Pre-built with formulas for the next ~150 days - nothing to edit. | D10: Sheets
A11: Chart: average error trend over time, across the whole rig. | D11: Labelling
D12: Log
A13: 3. Camera Trend sheet | D13: Recap Pages | E13: Daily, Trial, Error
A14: Pick a camera from the dropdown in the highlighted cell and its own error history over time appears in the table and chart below. Useful for spotting a camera that's drifting or degrading. | D14: Daily Trends
D15: Daily Performance
A16: 4. Lists sheet | D16: Daily Error Rates
A17: Just holds the camera name list that powers the dropdowns. Hidden by default - unhide it (right-click any sheet tab) if you add or retire a camera. | D17: Problem Cameras
A19: Cells you edit day-to-day are highlighted in pale yellow. Everything else is a formula and updates itself. | D19: Sheets should have own to-dos

Sheet Data-Lists
A1: DO NOT USE THIS SPREADSHEET, IT IS DEPRECATED AND KEPT ONLY AS REFERENCE FOR FINAL DATA REPRESENTATIONS
A2: The spreadsheet relies on this information don't tinker with it if you aren't prepared to fix it afterwards! Bolded entries are hardcoded. Other entries are formulas or lookups.
A3: Camera | B3: Daily Tracking Dates | C3: Key Category | D3: =CONCATENATE("Subkeys (", $C$5, ")") -> Subkeys (Error) | E3: =CONCATENATE("Subkeys (", $C$6, ")") -> Subkeys (Trial) | F3: Wand Wave Type
A4: #1 (Vero v2.2) | B4: {=_xlfn.CHOOSECOLS(_xlfn.UNIQUE(_xlfn._xlws.FILTER(Log!$A:$C,Log!$A:$A="Daily")),3)} -> 46228 | C4: Daily | D4: {=_xlfn._xlws.SORT(_xlfn.UNIQUE(_xlfn._xlws.FILTER(Log!B4:B9963, Log!A4:A9963=C5)))} -> 03/08-error1 | E4: {=_xlfn._xlws.SORT(_xlfn.UNIQUE(_xlfn._xlws.FILTER(Log!B4:B9963, Log!A4:A9963=C6)))} -> auto-stop-1000-base | F4: {=Legend!$G$11:$G51} -> A
A5: #2 (Vero v2.2) | B5: 46230 | C5: Error | D5: 03/08-error2 | E5: auto-stop-1000-v2 | F5: B
A6: #3 (Vero v2.2) | B6: 46231 | C6: Trial | D6: 20/08-error1 | E6: auto-stop-1000-v3 | F6: C
A7: #4 (Vero v2.2) | B7: 46232 | D7: 31/07-error1 | E7: auto-stop-1500-v1 | F7: D
A8: #5 (Vero v2.2) | B8: 46233 | D8: 31/07-error2 | E8: auto-stop-1500-v2 | F8: E
A9: #6 (Vero v2.2) | B9: 46234 | D9: cannot-set-volume | E9: auto-stop-2000-v1 | F9: F
A10: #7 (Vero v2.2) | B10: 46235 | D10: didn't-set-volume | E10: auto-stop-2000-v2 | F10: G
A11: #8 (Vero v2.2) | B11: 46237 | D11: no-reset-grayscale-all | E11: reflection-trial-2 | F11: H
A12: #9 (Vero v2.2) | B12: 46238 | E12: shelf-baseline | F12: I
A13: #10 (Vero v2.2) | B13: 46239 | E13: shelf-trial | F13: 0
A14: #11 (Vero v2.2) | B14: 46240 | E14: speed_cam11_fast_1 | F14: 0
A15: #12 (Vero v2.2) | B15: 46242 | E15: speed_cam11_fast_2 | F15: 0
A16: #13 (Vero v2.2) | B16: 46244 | E16: speed_cam11_fast_3 | F16: 0
A17: #14 (Vero v2.2) | B17: 46245 | E17: speed_cam11_slow_1 | F17: 0
A18: #15 (Vero v2.2) | B18: 46246 | E18: speed_cam11_slow_2 | F18: 0
A19: #16 (Vero v2.2) | B19: 46247 | E19: speed_cam11_slow_3 | F19: 0
A20: #17 (Vero v2.2) | B20: 46248 | E20: Wand-Wave-A1 | F20: 0
A21: #18 (Vero v2.2) | B21: 46251 | E21: Wand-Wave-A2 | F21: 0
B22: 46251 | E22: Wand-Wave-A3 | F22: 0
B23: 46251 | E23: Wand-Wave-A4 | F23: 0
B24: 46252 | E24: Wand-Wave-B1 | F24: 0
B25: 46253 | E25: Wand-Wave-B2 | F25: 0
B26: 46254 | E26: Wand-Wave-B3 | F26: 0
B27: 46255 | E27: Wand-Wave-B4 | F27: 0
E28: Wand-Wave-C1 | F28: 0
E29: Wand-Wave-C2 | F29: 0
E30: Wand-Wave-C3 | F30: 0
E31: Wand-Wave-C4 | F31: 0
E32: Wand-Wave-D1 | F32: 0
E33: Wand-Wave-D2 | F33: 0
E34: Wand-Wave-D3 | F34: 0
E35: Wand-Wave-D4 | F35: 0
E36: Wand-Wave-E1 | F36: 0
E37: Wand-Wave-E2 | F37: 0
E38: Wand-Wave-E3 | F38: 0
E39: Wand-Wave-E4 | F39: 0
... E44: Wand-Wave-G1 | F44: 0
...

Sheet Legend
A1: DO NOT USE THIS SPREADSHEET, IT IS DEPRECATED AND KEPT ONLY AS REFERENCE FOR FINAL DATA REPRESENTATIONS
A2: Sheet legend to identify the colours and labels used throughout the sheet
B4: Cameras in the INB Robotics/Vicon lab are labelled differently to the Nexus software, I've recorded the differences here. If this ever changes, correct this and keep record for data.
B5: Camera Name | C5: Nexus Software ID | D5: Physical Label | E5: Match | G5: HEADER COLOURS
B6: #1 (Vero v2.2) | C6: 1 | D6: 1 | E6: =IF(C6=D6, "Yes", "No") -> Yes | H6: Data should be input in this column.
B7: #2 (Vero v2.2) | C7: 2 | D7: 2 | E7: =IF(C7=D7, "Yes", "No") -> Yes | H7: Choose data value from dropdown!
B8: #3 (Vero v2.2) | C8: 3 | D8: 4 | E8: =IF(C8=D8, "Yes", "No") -> No | H8: Automatic formula - do not modify this column.
B9: #4 (Vero v2.2) | C9: 4 | D9: 18 | E9: =IF(C9=D9, "Yes", "No") -> No
B10: #5 (Vero v2.2) | C10: 5 | D10: 5 | E10: =IF(C10=D10, "Yes", "No") -> Yes | G10: Wand Techniques (documented by motion capture on 13/08/2026)
B11: #6 (Vero v2.2) | C11: 6 | D11: 6 | E11: =IF(C11=D11, "Yes", "No") -> Yes | G11: A | H11: Waving in figure 8, slowly - as though you're pushing water - pushing downards whilst walking around the room in a square
B12: #7 (Vero v2.2) | C12: 7 | D12: 7 | E12: =IF(C12=D12, "Yes", "No") -> Yes | G12: B | H12: As technique A except - bringing the wand in and out by stretching arm, and stooping/lunging as moving (in order to vary distance from the body)
B13: #8 (Vero v2.2) | C13: 8 | D13: 8 | E13: =IF(C13=D13, "Yes", "No") -> Yes | G13: C | H13: Guidance from active wand v4 (away from body, half circles, facing camera, no turning wand keep parallel to yourself, watch for objects)
B14: #9 (Vero v2.2) | C14: 9 | D14: 14 | E14: =IF(C14=D14, "Yes", "No") -> No | G14: D | H14: Figure 8 with the wand facing up - reccommended by the Vicon trainer during system installation
B15: #10 (Vero v2.2) | C15: 10 | D15: 10 | E15: =IF(C15=D15, "Yes", "No") -> Yes | G15: E | H15: Spinning the wand extended from body (rotating around center 360deg holding wand in middle but spinning it)
B16: #11 (Vero v2.2) | C16: 11 | D16: 11 | E16: =IF(C16=D16, "Yes", "No") -> Yes | G16: F | H16: Wave wand up and down (chopping axe motion, AWIR2 docs)
B17: #12 (Vero v2.2) | C17: 12 | D17: 12 | E17: =IF(C17=D17, "Yes", "No") -> Yes | G17: G | H17: Circling the wand extended from body (hold forward & draw circle, rotating around center 360deg holding handle - full circle vs C semi-circle)
B18: #13 (Vero v2.2) | C18: 13 | D18: 13 | E18: =IF(C18=D18, "Yes", "No") -> Yes | G18: H | H18: New technique after wand wave experiment - not captured yet - per technique D except wider figure 8 and more vertical/horizontal movement, held further away from user body to prevent occlusion.
B19: #14 (Vero v2.2) | C19: 14 | D19: 14 | E19: =IF(C19=D19, "Yes", "No") -> Yes | G19: I | H19: New technique after wand wave experiment - not captured yet - per technique H except attempting to paint space, turning body profile to prevent occlusion, and starting from inside of volume.
B20: #15 (Vero v2.2) | C20: 15 | D20: 15 | E20: =IF(C20=D20, "Yes", "No") -> Yes
B21: #16 (Vero v2.2) | C21: 16 | D21: 16 | E21: =IF(C21=D21, "Yes", "No") -> Yes
B22: #17 (Vero v2.2) | C22: 17 | D22: 3 | E22: =IF(C22=D22, "Yes", "No") -> No
B23: #18 (Vero v2.2) | C23: 18 | D23: 17 | E23: =IF(C23=D23, "Yes", "No") -> No

Sheet Log
A1: DO NOT USE THIS SPREADSHEET, IT IS DEPRECATED AND KEPT ONLY AS REFERENCE FOR FINAL DATA REPRESENTATIONS
A2: Instructions - Input Vicon Nexus error sets after any new calibration. Refer to header key tables for more info. | F2: Error (Camera Entry)
A3: Key 1 (Category) | B3: Key 2 (Precision) | C3: Date | D3: Camera | E3: Frame Count | F3: World Error | G3: Image Error
A4: Daily | B4: n/a | C4: 46228 | D4: #1 (Vero v2.2) | E4: 2306 | F4: 0.274982 | G4: 0.0793568
A5: Daily | B5: n/a | C5: 46228 | D5: #2 (Vero v2.2) | E5: 2392 | F5: 0.421843 | G5: 0.112306
A6: Daily | B6: n/a | C6: 46228 | D6: #3 (Vero v2.2) | E6: 1810 | F6: 0.398584 | G6: 0.0924275
A7: Daily | B7: n/a | C7: 46228 | D7: #4 (Vero v2.2) | E7: 2277 | F7: 0.620036 | G7: 0.121579
A8: Daily | B8: n/a | C8: 46228 | D8: #5 (Vero v2.2) | E8: 2240 | F8: 0.191893 | G8: 0.0443669
A9: Daily | B9: n/a | C9: 46228 | D9: #6 (Vero v2.2) | E9: 2754 | F9: 0.442235 | G9: 0.0899754
A10: Daily | B10: n/a | C10: 46228 | D10: #7 (Vero v2.2) | E10: 3007 | F10: 0.509896 | G10: 0.102799
A11: Daily | B11: n/a | C11: 46228 | D11: #9 (Vero v2.2) | E11: 2832 | F11: 0.395935 | G11: 0.0795796
A12: Daily | B12: n/a | C12: 46228 | D12: #10 (Vero v2.2) | E12: 2120 | F12: 0.499606 | G12: 0.132037
A13: Daily | B13: n/a | C13: 46228 | D13: #11 (Vero v2.2) | E13: 1471 | F13: 0.130593 | G13: 0.0450561
A14: Daily | B14: n/a | C14: 46228 | D14: #12 (Vero v2.2) | E14: 1657 | F14: 0.428371 | G14: 0.140663
A15: Daily | B15: n/a | C15: 46228 | D15: #13 (Vero v2.2) | E15: 1007 | F15: 0.168386 | G15: 0.0424158
... A1028: Trial | B1028: Wand-Wave-G4 | C1028: 46246 | D1028: #18 (Vero v2.2) | E1028: 1442 | F1028: 0.431939 | G1028: 0.083982
A1029: Daily | B1029: =IF($A1029="Daily", "n/a", "") -> n/a | C1029: 46247 | D1029: #1 (Vero v2.2) | E1029: 2333 | F1029: 0.405133 | G1029: 0.113922
A1030: Daily | B1030: =IF($A1030="Daily", "n/a", "") -> n/a | C1030: 46247 | D1030: #2 (Vero v2.2) | E1030: 1823 | F1030: 0.45546 | G1030: 0.120023
A1031: Daily | B1031: =IF($A1031="Daily", "n/a", "") -> n/a | C1031: 46247 | D1031: #3 (Vero v2.2) | E1031: 1149 | F1031: 0.377453 | G1031: 0.0885529
A1032: Daily | B1032: =IF($A1032="Daily", "n/a", "") -> n/a | C1032: 46247 | D1032: #4 (Vero v2.2) | E1032: 1864 | F1032: 0.450706 | G1032: 0.0891205
A1033: Daily | B1033: =IF($A1033="Daily", "n/a", "") -> n/a | C1033: 46247 | D1033: #5 (Vero v2.2) | E1033: 1421 | F1033: 0.217182 | G1033: 0.0516624
A1034: Daily | B1034: =IF($A1034="Daily", "n/a", "") -> n/a | C1034: 46247 | D1034: #6 (Vero v2.2) | E1034: 1542 | F1034: 0.353803 | G1034: 0.0743878
A1035: Daily | B1035: =IF($A1035="Daily", "n/a", "") -> n/a | C1035: 46247 | D1035: #7 (Vero v2.2) | E1035: 1458 | F1035: 0.353749 | G1035: 0.07398
A1036: Daily | B1036: =IF($A1036="Daily", "n/a", "") -> n/a | C1036: 46247 | D1036: #8 (Vero v2.2) | E1036: 1092 | F1036: 0.182155 | G1036: 0.0552003
A1037: Daily | B1037: =IF($A1037="Daily", "n/a", "") -> n/a | C1037: 46247 | D1037: #9 (Vero v2.2) | E1037: 2428 | F1037: 0.536396 | G1037: 0.104331
A1038: Daily | B1038: =IF($A1038="Daily", "n/a", "") -> n/a | C1038: 46247 | D1038: #10 (Vero v2.2) | E1038: 1369 | F1038: 0.388751 | G1038: 0.105559
A1039: Daily | B1039: =IF($A1039="Daily", "n/a", "") -> n/a | C1039: 46247 | D1039: #11 (Vero v2.2) | E1039: 1535 | F1039: 0.381734 | G1039: 0.12531
A1040: Daily | B1040: =IF($A1040="Daily", "n/a", "") -> n/a | C1040: 46247 | D1040: #12 (Vero v2.2) | E1040: 2256 | F1040: 0.18396 | G1040: 0.0566614
... A1046: Daily | B1046: =IF($A1046="Daily", "n/a", "") -> n/a | C1046: 46247 | D1046: #18 (Vero v2.2) | E1046: 1133 | F1046: 0.37192 | G1046: 0.0748058
A1047: Error | B1047: cannot-set-volume | C1047: 46248 | D1047: #1 (Vero v2.2) | E1047: 1484 | F1047: 0.514719 | G1047: 0.144732
A1048: Error | B1048: cannot-set-volume | C1048: 46248 | D1048: #2 (Vero v2.2) | E1048: 1290 | F1048: 0.517445 | G1048: 0.136305
A1049: Error | B1049: cannot-set-volume | C1049: 46248 | D1049: #3 (Vero v2.2) | E1049: 1093 | F1049: 0.503747 | G1049: 0.11812
A1050: Error | B1050: cannot-set-volume | C1050: 46248 | D1050: #4 (Vero v2.2) | E1050: 1834 | F1050: 0.473553 | G1050: 0.0936151
A1051: Error | B1051: cannot-set-volume | C1051: 46248 | D1051: #5 (Vero v2.2) | E1051: 1247 | F1051: 0.305897 | G1051: 0.072731
A1052: Error | B1052: cannot-set-volume | C1052: 46248 | D1052: #6 (Vero v2.2) | E1052: 1230 | F1052: 0.418566 | G1052: 0.0880348
A1053: Error | B1053: cannot-set-volume | C1053: 46248 | D1053: #7 (Vero v2.2) | E1053: 1058 | F1053: 0.451663 | G1053: 0.0944804
A1054: Error | B1054: cannot-set-volume | C1054: 46248 | D1054: #8 (Vero v2.2) | E1054: 1367 | F1054: 0.216456 | G1054: 0.065589
A1055: Error | B1055: cannot-set-volume | C1055: 46248 | D1055: #9 (Vero v2.2) | E1055: 1961 | F1055: 0.61155 | G1055: 0.118918
A1056: Error | B1056: cannot-set-volume | C1056: 46248 | D1056: #10 (Vero v2.2) | E1056: 2148 | F1056: 0.393646 | G1056: 0.106936
A1057: Error | B1057: cannot-set-volume | C1057: 46248 | D1057: #11 (Vero v2.2) | E1057: 1200 | F1057: 0.3096 | G1057: 0.101543
...

Sheet Daily IE
A1: DO NOT USE THIS SPREADSHEET, IT IS DEPRECATED AND KEPT ONLY AS REFERENCE FOR FINAL DATA REPRESENTATIONS
A2: Date | B2: Median | C2: This grid (below) records flat image error (IE) per camera, the grid to the right records (camera IE/session median) and highlights outliers (2.5x spread from median ratio) | U2: Parameters (Recorded from WE sheet) | W2: =_xlfn.QUARTILE.INC(W6:W201,3)-_xlfn.QUARTILE.INC(W6:W201,1) -> 0.28301409 | X2: =_xlfn.QUARTILE.INC(X6:X201,3)-_xlfn.QUARTILE.INC(X6:X201,1) -> 0.18719346 | Y2: =_xlfn.QUARTILE.INC(Y6:Y201,3)-_xlfn.QUARTILE.INC(Y6:Y201,1) -> 0.14568575 | Z2: =_xlfn.QUARTILE.INC(Z6:Z201,3)-_xlfn.QUARTILE.INC(Z6:Z201,1) -> 0.17077196 | AA2: =_xlfn.QUARTILE.INC(AA6:AA201,3)-_xlfn.QUARTILE.INC(AA6:AA201,1) -> 0.19233957 | AB2: =_xlfn.QUARTILE.INC(AB6:AB201,3)-_xlfn.QUARTILE.INC(AB6:AB201,1) -> 0.14783131 | AC2: =_xlfn.QUARTILE.INC(AC6:AC201,3)-_xlfn.QUARTILE.INC(AC6:AC201,1) -> 0.13626575 | AD2: =_xlfn.QUARTILE.INC(AD6:AD201,3)-_xlfn.QUARTILE.INC(AD6:AD201,1) -> 0.2787191 | ... AN2: =_xlfn.QUARTILE.INC(AN6:AN201,3)-_xlfn.QUARTILE.INC(AN6:AN201,1) -> 0.25907142
C3: {=MEDIAN(_xlfn._xlws.FILTER(C$6:C$302, ISNUMBER(C$6:C$302)))} -> 0.108634 | D3: {=MEDIAN(_xlfn._xlws.FILTER(D$6:D$302, ISNUMBER(D$6:D$302)))} -> 0.111233 | E3: {=MEDIAN(_xlfn._xlws.FILTER(E$6:E$302, ISNUMBER(E$6:E$302)))} -> 0.113829 | F3: {=MEDIAN(_xlfn._xlws.FILTER(F$6:F$302, ISNUMBER(F$6:F$302)))} -> 0.1103125 | G3: {=MEDIAN(_xlfn._xlws.FILTER(G$6:G$302, ISNUMBER(G$6:G$302)))} -> 0.07170265 | H3: {=MEDIAN(_xlfn._xlws.FILTER(H$6:H$302, ISNUMBER(H$6:H$302)))} -> 0.09796465 | I3: {=MEDIAN(_xlfn._xlws.FILTER(I$6:I$302, ISNUMBER(I$6:I$302)))} -> 0.1021595 | J3: {=MEDIAN(_xlfn._xlws.FILTER(J$6:J$302, ISNUMBER(J$6:J$302)))} -> 0.0724495 | ... T3: {=MEDIAN(_xlfn._xlws.FILTER(T$6:T$302, ISNUMBER(T$6:T$302)))} -> 0.10575 | W3: Spread above Baselines below | X3: Session Ratio Grid (by Median) Captures whether a particular session or camera was misperforming by dividing image error by the median | AN3: Spread above Baselines below
B4: Camera | C4: {=TRANSPOSE('Data-Lists'!$A$4:$A$21)} -> #1 (Vero v2.2) | D4: #2 (Vero v2.2) | E4: #3 (Vero v2.2) | F4: #4 (Vero v2.2) | G4: #5 (Vero v2.2) | H4: #6 (Vero v2.2) | I4: #7 (Vero v2.2) | J4: #8 (Vero v2.2) | K4: #9 (Vero v2.2) | L4: #10 (Vero v2.2) | M4: #11 (Vero v2.2) | N4: #12 (Vero v2.2) | O4: #13 (Vero v2.2) | P4: #14 (Vero v2.2) | Q4: #15 (Vero v2.2) | R4: #16 (Vero v2.2) | S4: #17 (Vero v2.2) | T4: #18 (Vero v2.2) | W4: =MEDIAN(W6:W202) -> 1.1165315 | X4: =MEDIAN(X6:X202) -> 1.1609111 | Y4: =MEDIAN(Y6:Y202) -> 1.1860317 | Z4: =MEDIAN(Z6:Z202) -> 1.1629962 | AA4: =MEDIAN(AA6:AA202) -> 0.79586558 | AB4: =MEDIAN(AB6:AB202) -> 1.0164964 | AC4: =MEDIAN(AC6:AC202) -> 1.0799218 | AD4: =MEDIAN(AD6:AD202) -> 0.84386403 | ... AN4: =MEDIAN(AN6:AN202) -> 1.1608232
B5: Session Median | C5: =VALUE(RIGHT(LEFT(C$4,3),2)) -> 1 | D5: =VALUE(RIGHT(LEFT(D$4,3),2)) -> 2 | E5: =VALUE(RIGHT(LEFT(E$4,3),2)) -> 3 | F5: =VALUE(RIGHT(LEFT(F$4,3),2)) -> 4 | G5: =VALUE(RIGHT(LEFT(G$4,3),2)) -> 5 | H5: =VALUE(RIGHT(LEFT(H$4,3),2)) -> 6 | I5: =VALUE(RIGHT(LEFT(I$4,3),2)) -> 7 | J5: =VALUE(RIGHT(LEFT(J$4,3),2)) -> 8 | ... T5: =VALUE(RIGHT(LEFT(T$4,3),2)) -> 18 | U5: Technique | V5: Auto-Stop | W5: =_xlfn.CONCAT("Cam ", LEFT(C$4,3)) -> Cam #1 | X5: =_xlfn.CONCAT("Cam ", LEFT(D$4,3)) -> Cam #2 | Y5: =_xlfn.CONCAT("Cam ", LEFT(E$4,3)) -> Cam #3 | Z5: =_xlfn.CONCAT("Cam ", LEFT(F$4,3)) -> Cam #4 | AA5: =_xlfn.CONCAT("Cam ", LEFT(G$4,3)) -> Cam #5 | AB5: =_xlfn.CONCAT("Cam ", LEFT(H$4,3)) -> Cam #6 | AC5: =_xlfn.CONCAT("Cam ", LEFT(I$4,3)) -> Cam #7 | AD5: =_xlfn.CONCAT("Cam ", LEFT(J$4,3)) -> Cam #8 | ... AN5: =_xlfn.CONCAT("Cam ", LEFT(T$4,3)) -> Cam #18 | AO5: Sanity
A6: {=_xlfn.UNIQUE(_xlfn._xlws.FILTER(Log!$C:$C, (Log!$B:B="n/a") * (Log!$A:$A="Daily")))} -> 46228 | B6: =IF($A6<>"", MEDIAN($C6:$T6), "") -> 0.0924275 | C6: {=IF($A6<>"", IFERROR(_xlfn._xlws.FILTER(Log!$G:$G, (Log!$A:$A="Daily") * (Log!$C:$C=$A6) * (Log!$D:$D=C$4)), "Unknown"), "")} -> 0.0793568 | D6: {=IF($A6<>"", IFERROR(_xlfn._xlws.FILTER(Log!$G:$G, (Log!$A:$A="Daily") * (Log!$C:$C=$A6) * (Log!$D:$D=D$4)), "Unknown"), "")} -> 0.112306 | E6: {=IF($A6<>"", IFERROR(_xlfn._xlws.FILTER(Log!$G:$G, (Log!$A:$A="Daily") * (Log!$C:$C=$A6) * (Log!$D:$D=E$4)), "Unknown"), "")} -> 0.0924275 | F6: {=IF($A6<>"", IFERROR(_xlfn._xlws.FILTER(Log!$G:$G, (Log!$A:$A="Daily") * (Log!$C:$C=$A6) * (Log!$D:$D=F$4)), "Unknown"), "")} -> 0.121579 | G6: {=IF($A6<>"", IFERROR(_xlfn._xlws.FILTER(Log!$G:$G, (Log!$A:$A="Daily") * (Log!$C:$C=$A6) * (Log!$D:$D=G$4)), "Unknown"), "")} -> 0.0443669 | H6: {=IF($A6<>"", IFERROR(_xlfn._xlws.FILTER(Log!$G:$G, (Log!$A:$A="Daily") * (Log!$C:$C=$A6) * (Log!$D:$D=H$4)), "Unknown"), "")} -> 0.0899754 | I6: {=IF($A6<>"", IFERROR(_xlfn._xlws.FILTER(Log!$G:$G, (Log!$A:$A="Daily") * (Log!$C:$C=$A6) * (Log!$D:$D=I$4)), "Unknown"), "")} -> 0.102799 | J6: {=IF($A6<>"", IFERROR(_xlfn._xlws.FILTER(Log!$G:$G, (Log!$A:$A="Daily") * (Log!$C:$C=$A6) * (Log!$D:$D=J$4)), "Unknown"), "")} -> Unknown | ... T6: {=IF($A6<>"", IFERROR(_xlfn._xlws.FILTER(Log!$G:$G, (Log!$A:$A="Daily") * (Log!$C:$C=$A6) * (Log!$D:$D=T$4)), "Unknown"), "")} -> 0.109931 | U6: {=_xlfn._xlws.FILTER('Daily WE'!F:F, ('Daily WE'!$B:$B="n/a") * ('Daily WE'!$C:$C ='Daily IE'!$A6))} -> A | V6: {=_xlfn._xlws.FILTER('Daily WE'!G:G, ('Daily WE'!$B:$B="n/a") * ('Daily WE'!$C:$C ='Daily IE'!$A6))} -> 1000 | W6: =IF(ISBLANK($A6), "", IF(ISNUMBER(C6), C6/$B6, "Unknown")) -> 0.8585843 | X6: =IF(ISBLANK($A6), "", IF(ISNUMBER(D6), D6/$B6, "Unknown")) -> 1.2150713 | Y6: =IF(ISBLANK($A6), "", IF(ISNUMBER(E6), E6/$B6, "Unknown")) -> 1 | Z6: =IF(ISBLANK($A6), "", IF(ISNUMBER(F6), F6/$B6, "Unknown")) -> 1.3153986 | AA6: =IF(ISBLANK($A6), "", IF(ISNUMBER(G6), G6/$B6, "Unknown")) -> 0.48001839 | AB6: =IF(ISBLANK($A6), "", IF(ISNUMBER(H6), H6/$B6, "Unknown")) -> 0.97347002 | AC6: =IF(ISBLANK($A6), "", IF(ISNUMBER(I6), I6/$B6, "Unknown")) -> 1.1122123 | AD6: =IF(ISBLANK($A6), "", IF(ISNUMBER(J6), J6/$B6, "Unknown")) -> Unknown | ... AN6: =IF(ISBLANK($A6), "", IF(ISNUMBER(T6), T6/$B6, "Unknown")) -> 1.1893755 | AO6: =IF(ISBLANK(U6), "", IF(ISNUMBER(U6), U6/$B6, "Unknown")) -> Unknown
A7: 46230 | B7: =IF($A7<>"", MEDIAN($C7:$T7), "") -> 0.0959111 | C7: {=IF($A7<>"", IFERROR(_xlfn._xlws.FILTER(Log!$G:$G, (Log!$A:$A="Daily") * (Log!$C:$C=$A7) * (Log!$D:$D=C$4)), "Unknown"), "")} -> 0.10861 | D7: {=IF($A7<>"", IFERROR(_xlfn._xlws.FILTER(Log!$G:$G, (Log!$A:$A="Daily") * (Log!$C:$C=$A7) * (Log!$D:$D=D$4)), "Unknown"), "")} -> 0.10678 | E7: {=IF($A7<>"", IFERROR(_xlfn._xlws.FILTER(Log!$G:$G, (Log!$A:$A="Daily") * (Log!$C:$C=$A7) * (Log!$D:$D=E$4)), "Unknown"), "")} -> 0.0987412 | F7: {=IF($A7<>"", IFERROR(_xlfn._xlws.FILTER(Log!$G:$G, (Log!$A:$A="Daily") * (Log!$C:$C=$A7) * (Log!$D:$D=F$4)), "Unknown"), "")} -> 0.120907 | G7: {=IF($A7<>"", IFERROR(_xlfn._xlws.FILTER(Log!$G:$G, (Log!$A:$A="Daily") * (Log!$C:$C=$A7) * (Log!$D:$D=G$4)), "Unknown"), "")} -> 0.0670923 | H7: {=IF($A7<>"", IFERROR(_xlfn._xlws.FILTER(Log!$G:$G, (Log!$A:$A="Daily") * (Log!$C:$C=$A7) * (Log!$D:$D=H$4)), "Unknown"), "")} -> 0.0736085 | I7: {=IF($A7<>"", IFERROR(_xlfn._xlws.FILTER(Log!$G:$G, (Log!$A:$A="Daily") * (Log!$C:$C=$A7) * (Log!$D:$D=I$4)), "Unknown"), "")} -> 0.076716 | J7: {=IF($A7<>"", IFERROR(_xlfn._xlws.FILTER(Log!$G:$G, (Log!$A:$A="Daily") * (Log!$C:$C=$A7) * (Log!$D:$D=J$4)), "Unknown"), "")} -> 0.0491185 | ... T7: {=IF($A7<>"", IFERROR(_xlfn._xlws.FILTER(Log!$G:$G, (Log!$A:$A="Daily") * (Log!$C:$C=$A7) * (Log!$D:$D=T$4)), "Unknown"), "")} -> 0.114508 | U7: {=_xlfn._xlws.FILTER('Daily WE'!F:F, ('Daily WE'!$B:$B="n/a") * ('Daily WE'!$C:$C ='Daily IE'!$A7))} -> A | V7: {=_xlfn._xlws.FILTER('Daily WE'!G:G, ('Daily WE'!$B:$B="n/a") * ('Daily WE'!$C:$C ='Daily IE'!$A7))} -> 1000 | W7: =IF(ISBLANK($A7), "", IF(ISNUMBER(C7), C7/$B7, "Unknown")) -> 1.1324028 | X7: =IF(ISBLANK($A7), "", IF(ISNUMBER(D7), D7/$B7, "Unknown")) -> 1.1133226 | Y7: =IF(ISBLANK($A7), "", IF(ISNUMBER(E7), E7/$B7, "Unknown")) -> 1.0295075 | Z7: =IF(ISBLANK($A7), "", IF(ISNUMBER(F7), F7/$B7, "Unknown")) -> 1.2606153 | AA7: =IF(ISBLANK($A7), "", IF(ISNUMBER(G7), G7/$B7, "Unknown")) -> 0.69952592 | AB7: =IF(ISBLANK($A7), "", IF(ISNUMBER(H7), H7/$B7, "Unknown")) -> 0.76746591 | AC7: =IF(ISBLANK($A7), "", IF(ISNUMBER(I7), I7/$B7, "Unknown")) -> 0.79986571 | AD7: =IF(ISBLANK($A7), "", IF(ISNUMBER(J7), J7/$B7, "Unknown")) -> 0.51212529 | ... AN7: =IF(ISBLANK($A7), "", IF(ISNUMBER(T7), T7/$B7, "Unknown")) -> 1.1938973 | AO7: {=MEDIAN(_xlfn._xlws.FILTER($W$6:$AN$6,($W$6:$AN$6<>"Unknown")))} -> 1
A8: 46231 | B8: =IF($A8<>"", MEDIAN($C8:$T8), "") -> 0.07986075 | C8: {=IF($A8<>"", IFERROR(_xlfn._xlws.FILTER(Log!$G:$G, (Log!$A:$A="Daily") * (Log!$C:$C=$A8) * (Log!$D:$D=C$4)), "Unknown"), "")} -> 0.0919579 | D8: {=IF($A8<>"", IFERROR(_xlfn._xlws.FILTER(Log!$G:$G, (Log!$A:$A="Daily") * (Log!$C:$C=$A8) * (Log!$D:$D=D$4)), "Unknown"), "")} -> 0.146714 | E8: {=IF($A8<>"", IFERROR(_xlfn._xlws.FILTER(Log!$G:$G, (Log!$A:$A="Daily") * (Log!$C:$C=$A8) * (Log!$D:$D=E$4)), "Unknown"), "")} -> 0.081952 | F8: {=IF($A8<>"", IFERROR(_xlfn._xlws.FILTER(Log!$G:$G, (Log!$A:$A="Daily") * (Log!$C:$C=$A8) * (Log!$D:$D=F$4)), "Unknown"), "")} -> 0.109685 | G8: {=IF($A8<>"", IFERROR(_xlfn._xlws.FILTER(Log!$G:$G, (Log!$A:$A="Daily") * (Log!$C:$C=$A8) * (Log!$D:$D=G$4)), "Unknown"), "")} -> 0.0777695 | H8: {=IF($A8<>"", IFERROR(_xlfn._xlws.FILTER(Log!$G:$G, (Log!$A:$A="Daily") * (Log!$C:$C=$A8) * (Log!$D:$D=H$4)), "Unknown"), "")} -> 0.0841181 | I8: {=IF($A8<>"", IFERROR(_xlfn._xlws.FILTER(Log!$G:$G, (Log!$A:$A="Daily") * (Log!$C:$C=$A8) * (Log!$D:$D=I$4)), "Unknown"), "")} -> 0.0892071 | J8: {=IF($A8<>"", IFERROR(_xlfn._xlws.FILTER(Log!$G:$G, (Log!$A:$A="Daily") * (Log!$C:$C=$A8) * (Log!$D:$D=J$4)), "Unknown"), "")} -> 0.0478596 | ... T8: {=IF($A8<>"", IFERROR(_xlfn._xlws.FILTER(Log!$G:$G, (Log!$A:$A="Daily") * (Log!$C:$C=$A8) * (Log!$D:$D=T$4)), "Unknown"), "")} -> 0.0952713 | U8: {=_xlfn._xlws.FILTER('Daily WE'!F:F, ('Daily WE'!$B:$B="n/a") * ('Daily WE'!$C:$C ='Daily IE'!$A8))} -> B | V8: {=_xlfn._xlws.FILTER('Daily WE'!G:G, ('Daily WE'!$B:$B="n/a") * ('Daily WE'!$C:$C ='Daily IE'!$A8))} -> 1000 | W8: =IF(ISBLANK($A8), "", IF(ISNUMBER(C8), C8/$B8, "Unknown")) -> 1.151478 | X8: =IF(ISBLANK($A8), "", IF(ISNUMBER(D8), D8/$B8, "Unknown")) -> 1.8371227 | Y8: =IF(ISBLANK($A8), "", IF(ISNUMBER(E8), E8/$B8, "Unknown")) -> 1.0261862 | Z8: =IF(ISBLANK($A8), "", IF(ISNUMBER(F8), F8/$B8, "Unknown")) -> 1.3734532 | AA8: =IF(ISBLANK($A8), "", IF(ISNUMBER(G8), G8/$B8, "Unknown")) -> 0.97381379 | AB8: =IF(ISBLANK($A8), "", IF(ISNUMBER(H8), H8/$B8, "Unknown")) -> 1.0533097 | AC8: =IF(ISBLANK($A8), "", IF(ISNUMBER(I8), I8/$B8, "Unknown")) -> 1.1170331 | AD8: =IF(ISBLANK($A8), "", IF(ISNUMBER(J8), J8/$B8, "Unknown")) -> 0.59928814 | ... AN8: =IF(ISBLANK($A8), "", IF(ISNUMBER(T8), T8/$B8, "Unknown")) -> 1.1929678 | AO8: {=MEDIAN(_xlfn._xlws.FILTER($W$6:$AN$6,($W$6:$AN$6<>"Unknown")))} -> 1
A9: 46232 | B9: =IF($A9<>"", MEDIAN($C9:$T9), "") -> 0.0818603 | C9: {=IF($A9<>"", IFERROR(_xlfn._xlws.FILTER(Log!$G:$G, (Log!$A:$A="Daily") * (Log!$C:$C=$A9) * (Log!$D:$D=C$4)), "Unknown"), "")} -> 0.0804794 | D9: {=IF($A9<>"", IFERROR(_xlfn._xlws.FILTER(Log!$G:$G, (Log!$A:$A="Daily") * (Log!$C:$C=$A9) * (Log!$D:$D=D$4)), "Unknown"), "")} -> 0.104628 | E9: {=IF($A9<>"", IFERROR(_xlfn._xlws.FILTER(Log!$G:$G, (Log!$A:$A="Daily") * (Log!$C:$C=$A9) * (Log!$D:$D=E$4)), "Unknown"), "")} -> 0.106193 | F9: {=IF($A9<>"", IFERROR(_xlfn._xlws.FILTER(Log!$G:$G, (Log!$A:$A="Daily") * (Log!$C:$C=$A9) * (Log!$D:$D=F$4)), "Unknown"), "")} -> 0.112651 | G9: {=IF($A9<>"", IFERROR(_xlfn._xlws.FILTER(Log!$G:$G, (Log!$A:$A="Daily") * (Log!$C:$C=$A9) * (Log!$D:$D=G$4)), "Unknown"), "")} -> 0.0645624 | H9: {=IF($A9<>"", IFERROR(_xlfn._xlws.FILTER(Log!$G:$G, (Log!$A:$A="Daily") * (Log!$C:$C=$A9) * (Log!$D:$D=H$4)), "Unknown"), "")} -> 0.0806085 | I9: {=IF($A9<>"", IFERROR(_xlfn._xlws.FILTER(Log!$G:$G, (Log!$A:$A="Daily") * (Log!$C:$C=$A9) * (Log!$D:$D=I$4)), "Unknown"), "")} -> 0.0831121 | J9: {=IF($A9<>"", IFERROR(_xlfn._xlws.FILTER(Log!$G:$G, (Log!$A:$A="Daily") * (Log!$C:$C=$A9) * (Log!$D:$D=J$4)), "Unknown"), "")} -> 0.0692319 | ... T9: {=IF($A9<>"", IFERROR(_xlfn._xlws.FILTER(Log!$G:$G, (Log!$A:$A="Daily") * (Log!$C:$C=$A9) * (Log!$D:$D=T$4)), "Unknown"), "")} -> 0.108565 | U9: {=_xlfn._xlws.FILTER('Daily WE'!F:F, ('Daily WE'!$B:$B="n/a") * ('Daily WE'!$C:$C ='Daily IE'!$A9))} -> A | V9: {=_xlfn._xlws.FILTER('Daily WE'!G:G, ('Daily WE'!$B:$B="n/a") * ('Daily WE'!$C:$C ='Daily IE'!$A9))} -> 1000 | W9: =IF(ISBLANK($A9), "", IF(ISNUMBER(C9), C9/$B9, "Unknown")) -> 0.98313102 | X9: =IF(ISBLANK($A9), "", IF(ISNUMBER(D9), D9/$B9, "Unknown")) -> 1.2781287 | Y9: =IF(ISBLANK($A9), "", IF(ISNUMBER(E9), E9/$B9, "Unknown")) -> 1.2972467 | Z9: =IF(ISBLANK($A9), "", IF(ISNUMBER(F9), F9/$B9, "Unknown")) -> 1.3761372 | AA9: =IF(ISBLANK($A9), "", IF(ISNUMBER(G9), G9/$B9, "Unknown")) -> 0.78869 | AB9: =IF(ISBLANK($A9), "", IF(ISNUMBER(H9), H9/$B9, "Unknown")) -> 0.98470809 | AC9: =IF(ISBLANK($A9), "", IF(ISNUMBER(I9), I9/$B9, "Unknown")) -> 1.0152919 | AD9: =IF(ISBLANK($A9), "", IF(ISNUMBER(J9), J9/$B9, "Unknown")) -> 0.8457323 | ... AN9: =IF(ISBLANK($A9), "", IF(ISNUMBER(T9), T9/$B9, "Unknown")) -> 1.3262228 | AO9: {=MEDIAN(_xlfn._xlws.FILTER($W$6:$AN$6,($W$6:$AN$6<>"Unknown")))} -> 1
A10: 46233 | B10: =IF($A10<>"", MEDIAN($C10:$T10), "") -> 0.076076 | C10: {=IF($A10<>"", IFERROR(_xlfn._xlws.FILTER(Log!$G:$G, (Log!$A:$A="Daily") * (Log!$C:$C=$A10) * (Log!$D:$D=C$4)), "Unknown"), "")} -> 0.0617744 | D10: {=IF($A10<>"", IFERROR(_xlfn._xlws.FILTER(Log!$G:$G, (Log!$A:$A="Daily") * (Log!$C:$C=$A10) * (Log!$D:$D=D$4)), "Unknown"), "")} -> 0.10016 | E10: {=IF($A10<>"", IFERROR(_xlfn._xlws.FILTER(Log!$G:$G, (Log!$A:$A="Daily") * (Log!$C:$C=$A10) * (Log!$D:$D=E$4)), "Unknown"), "")} -> 0.101578 | F10: {=IF($A10<>"", IFERROR(_xlfn._xlws.FILTER(Log!$G:$G, (Log!$A:$A="Daily") * (Log!$C:$C=$A10) * (Log!$D:$D=F$4)), "Unknown"), "")} -> 0.0898851 | G10: {=IF($A10<>"", IFERROR(_xlfn._xlws.FILTER(Log!$G:$G, (Log!$A:$A="Daily") * (Log!$C:$C=$A10) * (Log!$D:$D=G$4)), "Unknown"), "")} -> 0.061424 | H10: {=IF($A10<>"", IFERROR(_xlfn._xlws.FILTER(Log!$G:$G, (Log!$A:$A="Daily") * (Log!$C:$C=$A10) * (Log!$D:$D=H$4)), "Unknown"), "")} -> 0.0708343 | I10: {=IF($A10<>"", IFERROR(_xlfn._xlws.FILTER(Log!$G:$G, (Log!$A:$A="Daily") * (Log!$C:$C=$A10) * (Log!$D:$D=I$4)), "Unknown"), "")} -> 0.0796996 | J10: {=IF($A10<>"", IFERROR(_xlfn._xlws.FILTER(Log!$G:$G, (Log!$A:$A="Daily") * (Log!$C:$C=$A10) * (Log!$D:$D=J$4)), "Unknown"), "")} -> 0.0641978 | ... T10: {=IF($A10<>"", IFERROR(_xlfn._xlws.FILTER(Log!$G:$G, (Log!$A:$A="Daily") * (Log!$C:$C=$A10) * (Log!$D:$D=T$4)), "Unknown"), "")} -> 0.0895308 | U10: {=_xlfn._xlws.FILTER('Daily WE'!F:F, ('Daily WE'!$B:$B="n/a") * ('Daily WE'!$C:$C ='Daily IE'!$A10))} -> A | V10: {=_xlfn._xlws.FILTER('Daily WE'!G:G, ('Daily WE'!$B:$B="n/a") * ('Daily WE'!$C:$C ='Daily IE'!$A10))} -> 1000 | W10: =IF(ISBLANK($A10), "", IF(ISNUMBER(C10), C10/$B10, "Unknown")) -> 0.81200904 | X10: =IF(ISBLANK($A10), "", IF(ISNUMBER(D10), D10/$B10, "Unknown")) -> 1.3165782 | Y10: =IF(ISBLANK($A10), "", IF(ISNUMBER(E10), E10/$B10, "Unknown")) -> 1.3352174 | Z10: =IF(ISBLANK($A10), "", IF(ISNUMBER(F10), F10/$B10, "Unknown")) -> 1.1815172 | AA10: =IF(ISBLANK($A10), "", IF(ISNUMBER(G10), G10/$B10, "Unknown")) -> 0.80740312 | AB10: =IF(ISBLANK($A10), "", IF(ISNUMBER(H10), H10/$B10, "Unknown")) -> 0.93109916 | AC10: =IF(ISBLANK($A10), "", IF(ISNUMBER(I10), I10/$B10, "Unknown")) -> 1.0476313 | AD10: =IF(ISBLANK($A10), "", IF(ISNUMBER(J10), J10/$B10, "Unknown")) -> 0.84386403 | ... AN10: =IF(ISBLANK($A10), "", IF(ISNUMBER(T10), T10/$B10, "Unknown")) -> 1.17686 | AO10: {=MEDIAN(_xlfn._xlws.FILTER($W$6:$AN$6,($W$6:$AN$6<>"Unknown")))} -> 1
A11: 46234 | B11: =IF($A11<>"", MEDIAN($C11:$T11), "") -> 0.08749545 | C11: {=IF($A11<>"", IFERROR(_xlfn._xlws.FILTER(Log!$G:$G, (Log!$A:$A="Daily") * (Log!$C:$C=$A11) * (Log!$D:$D=C$4)), "Unknown"), "")} -> 0.147318 | D11: {=IF($A11<>"", IFERROR(_xlfn._xlws.FILTER(Log!$G:$G, (Log!$A:$A="Daily") * (Log!$C:$C=$A11) * (Log!$D:$D=D$4)), "Unknown"), "")} -> 0.119767 | E11: {=IF($A11<>"", IFERROR(_xlfn._xlws.FILTER(Log!$G:$G, (Log!$A:$A="Daily") * (Log!$C:$C=$A11) * (Log!$D:$D=E$4)), "Unknown"), "")} -> 0.0946352 | F11: {=IF($A11<>"", IFERROR(_xlfn._xlws.FILTER(Log!$G:$G, (Log!$A:$A="Daily") * (Log!$C:$C=$A11) * (Log!$D:$D=F$4)), "Unknown"), "")} -> 0.106142 | G11: {=IF($A11<>"", IFERROR(_xlfn._xlws.FILTER(Log!$G:$G, (Log!$A:$A="Daily") * (Log!$C:$C=$A11) * (Log!$D:$D=G$4)), "Unknown"), "")} -> 0.0520276 | H11: {=IF($A11<>"", IFERROR(_xlfn._xlws.FILTER(Log!$G:$G, (Log!$A:$A="Daily") * (Log!$C:$C=$A11) * (Log!$D:$D=H$4)), "Unknown"), "")} -> 0.0747 | I11: {=IF($A11<>"", IFERROR(_xlfn._xlws.FILTER(Log!$G:$G, (Log!$A:$A="Daily") * (Log!$C:$C=$A11) * (Log!$D:$D=I$4)), "Unknown"), "")} -> 0.0779429 | J11: {=IF($A11<>"", IFERROR(_xlfn._xlws.FILTER(Log!$G:$G, (Log!$A:$A="Daily") * (Log!$C:$C=$A11) * (Log!$D:$D=J$4)), "Unknown"), "")} -> 0.0801921 | ... T11: {=IF($A11<>"", IFERROR(_xlfn._xlws.FILTER(Log!$G:$G, (Log!$A:$A="Daily") * (Log!$C:$C=$A11) * (Log!$D:$D=T$4)), "Unknown"), "")} -> 0.104738 | U11: {=_xlfn._xlws.FILTER('Daily WE'!F:F, ('Daily WE'!$B:$B="n/a") * ('Daily WE'!$C:$C ='Daily IE'!$A11))} -> C | V11: {=_xlfn._xlws.FILTER('Daily WE'!G:G, ('Daily WE'!$B:$B="n/a") * ('Daily WE'!$C:$C ='Daily IE'!$A11))} -> 1500 | W11: =IF(ISBLANK($A11), "", IF(ISNUMBER(C11), C11/$B11, "Unknown")) -> 1.6837218 | X11: =IF(ISBLANK($A11), "", IF(ISNUMBER(D11), D11/$B11, "Unknown")) -> 1.3688369 | Y11: =IF(ISBLANK($A11), "", IF(ISNUMBER(E11), E11/$B11, "Unknown")) -> 1.0816014 | Z11: =IF(ISBLANK($A11), "", IF(ISNUMBER(F11), F11/$B11, "Unknown")) -> 1.2131145 | AA11: =IF(ISBLANK($A11), "", IF(ISNUMBER(G11), G11/$B11, "Unknown")) -> 0.59463206 | AB11: =IF(ISBLANK($A11), "", IF(ISNUMBER(H11), H11/$B11, "Unknown")) -> 0.85375868 | AC11: =IF(ISBLANK($A11), "", IF(ISNUMBER(I11), I11/$B11, "Unknown")) -> 0.89082232 | AD11: =IF(ISBLANK($A11), "", IF(ISNUMBER(J11), J11/$B11, "Unknown")) -> 0.9165288 | ... AN11: =IF(ISBLANK($A11), "", IF(ISNUMBER(T11), T11/$B11, "Unknown")) -> 1.197068 | AO11: {=MEDIAN(_xlfn._xlws.FILTER($W$6:$AN$6,($W$6:$AN$6<>"Unknown")))} -> 1
A12: 46235 | B12: =IF($A12<>"", MEDIAN($C12:$T12), "") -> 0.0989488 | C12: {=IF($A12<>"", IFERROR(_xlfn._xlws.FILTER(Log!$G:$G, (Log!$A:$A="Daily") * (Log!$C:$C=$A12) * (Log!$D:$D=C$4)), "Unknown"), "")} -> 0.108909 | D12: {=IF($A12<>"", IFERROR(_xlfn._xlws.FILTER(Log!$G:$G, (Log!$A:$A="Daily") * (Log!$C:$C=$A12) * (Log!$D:$D=D$4)), "Unknown"), "")} -> 0.127695 | E12: {=IF($A12<>"", IFERROR(_xlfn._xlws.FILTER(Log!$G:$G, (Log!$A:$A="Daily") * (Log!$C:$C=$A12) * (Log!$D:$D=E$4)), "Unknown"), "")} -> 0.127792 | F12: {=IF($A12<>"", IFERROR(_xlfn._xlws.FILTER(Log!$G:$G, (Log!$A:$A="Daily") * (Log!$C:$C=$A12) * (Log!$D:$D=F$4)), "Unknown"), "")} -> 0.0934126 | G12: {=IF($A12<>"", IFERROR(_xlfn._xlws.FILTER(Log!$G:$G, (Log!$A:$A="Daily") * (Log!$C:$C=$A12) * (Log!$D:$D=G$4)), "Unknown"), "")} -> 0.0918776 | H12: {=IF($A12<>"", IFERROR(_xlfn._xlws.FILTER(Log!$G:$G, (Log!$A:$A="Daily") * (Log!$C:$C=$A12) * (Log!$D:$D=H$4)), "Unknown"), "")} -> 0.310464 | I12: {=IF($A12<>"", IFERROR(_xlfn._xlws.FILTER(Log!$G:$G, (Log!$A:$A="Daily") * (Log!$C:$C=$A12) * (Log!$D:$D=I$4)), "Unknown"), "")} -> 0.169795 | J12: {=IF($A12<>"", IFERROR(_xlfn._xlws.FILTER(Log!$G:$G, (Log!$A:$A="Daily") * (Log!$C:$C=$A12) * (Log!$D:$D=J$4)), "Unknown"), "")} -> 0.0620463 | ... T12: {=IF($A12<>"", IFERROR(_xlfn._xlws.FILTER(Log!$G:$G, (Log!$A:$A="Daily") * (Log!$C:$C=$A12) * (Log!$D:$D=T$4)), "Unknown"), "")} -> 0.0948576 | U12: {=_xlfn._xlws.FILTER('Daily WE'!F:F, ('Daily WE'!$B:$B="n/a") * ('Daily WE'!$C:$C ='Daily IE'!$A12))} -> C | V12: {=_xlfn._xlws.FILTER('Daily WE'!G:G, ('Daily WE'!$B:$B="n/a") * ('Daily WE'!$C:$C ='Daily IE'!$A12))} -> 1500 | W12: =IF(ISBLANK($A12), "", IF(ISNUMBER(C12), C12/$B12, "Unknown")) -> 1.1006601 | X12: =IF(ISBLANK($A12), "", IF(ISNUMBER(D12), D12/$B12, "Unknown")) -> 1.2905159 | Y12: =IF(ISBLANK($A12), "", IF(ISNUMBER(E12), E12/$B12, "Unknown")) -> 1.2914962 | Z12: =IF(ISBLANK($A12), "", IF(ISNUMBER(F12), F12/$B12, "Unknown")) -> 0.94404985 | AA12: =IF(ISBLANK($A12), "", IF(ISNUMBER(G12), G12/$B12, "Unknown")) -> 0.92853678 | AB12: =IF(ISBLANK($A12), "", IF(ISNUMBER(H12), H12/$B12, "Unknown")) -> 3.1376227 | AC12: =IF(ISBLANK($A12), "", IF(ISNUMBER(I12), I12/$B12, "Unknown")) -> 1.7159885 | AD12: =IF(ISBLANK($A12), "", IF(ISNUMBER(J12), J12/$B12, "Unknown")) -> 0.6270546 | ... AN12: =IF(ISBLANK($A12), "", IF(ISNUMBER(T12), T12/$B12, "Unknown")) -> 0.95865336 | AO12: {=MEDIAN(_xlfn._xlws.FILTER($W$6:$AN$6,($W$6:$AN$6<>"Unknown")))} -> 1
A13: 46237 | B13: =IF($A13<>"", MEDIAN($C13:$T13), "") -> 0.08920925 | C13: {=IF($A13<>"", IFERROR(_xlfn._xlws.FILTER(Log!$G:$G, (Log!$A:$A="Daily") * (Log!$C:$C=$A13) * (Log!$D:$D=C$4)), "Unknown"), "")} -> 0.0574771 | D13: {=IF($A13<>"", IFERROR(_xlfn._xlws.FILTER(Log!$G:$G, (Log!$A:$A="Daily") * (Log!$C:$C=$A13) * (Log!$D:$D=D$4)), "Unknown"), "")} -> 0.106177 | E13: {=IF($A13<>"", IFERROR(_xlfn._xlws.FILTER(Log!$G:$G, (Log!$A:$A="Daily") * (Log!$C:$C=$A13) * (Log!$D:$D=E$4)), "Unknown"), "")} -> 0.118227 | F13: {=IF($A13<>"", IFERROR(_xlfn._xlws.FILTER(Log!$G:$G, (Log!$A:$A="Daily") * (Log!$C:$C=$A13) * (Log!$D:$D=F$4)), "Unknown"), "")} -> 0.0906257 | G13: {=IF($A13<>"", IFERROR(_xlfn._xlws.FILTER(Log!$G:$G, (Log!$A:$A="Daily") * (Log!$C:$C=$A13) * (Log!$D:$D=G$4)), "Unknown"), "")} -> 0.0716387 | H13: {=IF($A13<>"", IFERROR(_xlfn._xlws.FILTER(Log!$G:$G, (Log!$A:$A="Daily") * (Log!$C:$C=$A13) * (Log!$D:$D=H$4)), "Unknown"), "")} -> 0.0960344 | I13: {=IF($A13<>"", IFERROR(_xlfn._xlws.FILTER(Log!$G:$G, (Log!$A:$A="Daily") * (Log!$C:$C=$A13) * (Log!$D:$D=I$4)), "Unknown"), "")} -> 0.10152 | J13: {=IF($A13<>"", IFERROR(_xlfn._xlws.FILTER(Log!$G:$G, (Log!$A:$A="Daily") * (Log!$C:$C=$A13) * (Log!$D:$D=J$4)), "Unknown"), "")} -> 0.0877928 | ... T13: {=IF($A13<>"", IFERROR(_xlfn._xlws.FILTER(Log!$G:$G, (Log!$A:$A="Daily") * (Log!$C:$C=$A13) * (Log!$D:$D=T$4)), "Unknown"), "")} -> 0.15169 | U13: {=_xlfn._xlws.FILTER('Daily WE'!F:F, ('Daily WE'!$B:$B="n/a") * ('Daily WE'!$C:$C ='Daily IE'!$A13))} -> A | V13: {=_xlfn._xlws.FILTER('Daily WE'!G:G, ('Daily WE'!$B:$B="n/a") * ('Daily WE'!$C:$C ='Daily IE'!$A13))} -> 1000 | W13: =IF(ISBLANK($A13), "", IF(ISNUMBER(C13), C13/$B13, "Unknown")) -> 0.64429529 | X13: =IF(ISBLANK($A13), "", IF(ISNUMBER(D13), D13/$B13, "Unknown")) -> 1.1902017 | Y13: =IF(ISBLANK($A13), "", IF(ISNUMBER(E13), E13/$B13, "Unknown")) -> 1.3252774 | Z13: =IF(ISBLANK($A13), "", IF(ISNUMBER(F13), F13/$B13, "Unknown")) -> 1.0158778 | AA13: =IF(ISBLANK($A13), "", IF(ISNUMBER(G13), G13/$B13, "Unknown")) -> 0.80304116 | AB13: =IF(ISBLANK($A13), "", IF(ISNUMBER(H13), H13/$B13, "Unknown")) -> 1.0765072 | AC13: =IF(ISBLANK($A13), "", IF(ISNUMBER(I13), I13/$B13, "Unknown")) -> 1.1379986 | AD13: =IF(ISBLANK($A13), "", IF(ISNUMBER(J13), J13/$B13, "Unknown")) -> 0.98412216 | ... AN13: =IF(ISBLANK($A13), "", IF(ISNUMBER(T13), T13/$B13, "Unknown")) -> 1.7003842 | AO13: {=MEDIAN(_xlfn._xlws.FILTER($W$6:$AN$6,($W$6:$AN$6<>"Unknown")))} -> 1
A14: 46238 | B14: =IF($A14<>"", MEDIAN($C14:$T14), "") -> 0.1044055 | C14: {=IF($A14<>"", IFERROR(_xlfn._xlws.FILTER(Log!$G:$G, (Log!$A:$A="Daily") * (Log!$C:$C=$A14) * (Log!$D:$D=C$4)), "Unknown"), "")} -> 0.125044 | D14: {=IF($A14<>"", IFERROR(_xlfn._xlws.FILTER(Log!$G:$G, (Log!$A:$A="Daily") * (Log!$C:$C=$A14) * (Log!$D:$D=D$4)), "Unknown"), "")} -> 0.110958 | E14: {=IF($A14<>"", IFERROR(_xlfn._xlws.FILTER(Log!$G:$G, (Log!$A:$A="Daily") * (Log!$C:$C=$A14) * (Log!$D:$D=E$4)), "Unknown"), "")} -> 0.122268 | F14: {=IF($A14<>"", IFERROR(_xlfn._xlws.FILTER(Log!$G:$G, (Log!$A:$A="Daily") * (Log!$C:$C=$A14) * (Log!$D:$D=F$4)), "Unknown"), "")} -> 0.113594 | G14: {=IF($A14<>"", IFERROR(_xlfn._xlws.FILTER(Log!$G:$G, (Log!$A:$A="Daily") * (Log!$C:$C=$A14) * (Log!$D:$D=G$4)), "Unknown"), "")} -> 0.0717666 | H14: {=IF($A14<>"", IFERROR(_xlfn._xlws.FILTER(Log!$G:$G, (Log!$A:$A="Daily") * (Log!$C:$C=$A14) * (Log!$D:$D=H$4)), "Unknown"), "")} -> 0.103851 | I14: {=IF($A14<>"", IFERROR(_xlfn._xlws.FILTER(Log!$G:$G, (Log!$A:$A="Daily") * (Log!$C:$C=$A14) * (Log!$D:$D=I$4)), "Unknown"), "")} -> 0.10496 | J14: {=IF($A14<>"", IFERROR(_xlfn._xlws.FILTER(Log!$G:$G, (Log!$A:$A="Daily") * (Log!$C:$C=$A14) * (Log!$D:$D=J$4)), "Unknown"), "")} -> 0.0877466 | ... T14: {=IF($A14<>"", IFERROR(_xlfn._xlws.FILTER(Log!$G:$G, (Log!$A:$A="Daily") * (Log!$C:$C=$A14) * (Log!$D:$D=T$4)), "Unknown"), "")} -> 0.119522 | U14: {=_xlfn._xlws.FILTER('Daily WE'!F:F, ('Daily WE'!$B:$B="n/a") * ('Daily WE'!$C:$C ='Daily IE'!$A14))} -> A | V14: {=_xlfn._xlws.FILTER('Daily WE'!G:G, ('Daily WE'!$B:$B="n/a") * ('Daily WE'!$C:$C ='Daily IE'!$A14))} -> 1000 | W14: =IF(ISBLANK($A14), "", IF(ISNUMBER(C14), C14/$B14, "Unknown")) -> 1.1976764 | X14: =IF(ISBLANK($A14), "", IF(ISNUMBER(D14), D14/$B14, "Unknown")) -> 1.0627601 | Y14: =IF(ISBLANK($A14), "", IF(ISNUMBER(E14), E14/$B14, "Unknown")) -> 1.1710877 | Z14: =IF(ISBLANK($A14), "", IF(ISNUMBER(F14), F14/$B14, "Unknown")) -> 1.0880078 | AA14: =IF(ISBLANK($A14), "", IF(ISNUMBER(G14), G14/$B14, "Unknown")) -> 0.68738333 | AB14: =IF(ISBLANK($A14), "", IF(ISNUMBER(H14), H14/$B14, "Unknown")) -> 0.99468898 | AC14: =IF(ISBLANK($A14), "", IF(ISNUMBER(I14), I14/$B14, "Unknown")) -> 1.005311 | AD14: =IF(ISBLANK($A14), "", IF(ISNUMBER(J14), J14/$B14, "Unknown")) -> 0.8404404 | ... AN14: =IF(ISBLANK($A14), "", IF(ISNUMBER(T14), T14/$B14, "Unknown")) -> 1.1447864 | AO14: {=MEDIAN(_xlfn._xlws.FILTER($W$6:$AN$6,($W$6:$AN$6<>"Unknown")))} -> 1
A15: 46239 | B15: =IF($A15<>"", MEDIAN($C15:$T15), "") -> 0.0966666 | C15: {=IF($A15<>"", IFERROR(_xlfn._xlws.FILTER(Log!$G:$G, (Log!$A:$A="Daily") * (Log!$C:$C=$A15) * (Log!$D:$D=C$4)), "Unknown"), "")} -> 0.114288 | D15: {=IF($A15<>"", IFERROR(_xlfn._xlws.FILTER(Log!$G:$G, (Log!$A:$A="Daily") * (Log!$C:$C=$A15) * (Log!$D:$D=D$4)), "Unknown"), "")} -> 0.11281 | E15: {=IF($A15<>"", IFERROR(_xlfn._xlws.FILTER(Log!$G:$G, (Log!$A:$A="Daily") * (Log!$C:$C=$A15) * (Log!$D:$D=E$4)), "Unknown"), "")} -> 0.114023 | F15: {=IF($A15<>"", IFERROR(_xlfn._xlws.FILTER(Log!$G:$G, (Log!$A:$A="Daily") * (Log!$C:$C=$A15) * (Log!$D:$D=F$4)), "Unknown"), "")} -> 0.116208 | G15: {=IF($A15<>"", IFERROR(_xlfn._xlws.FILTER(Log!$G:$G, (Log!$A:$A="Daily") * (Log!$C:$C=$A15) * (Log!$D:$D=G$4)), "Unknown"), "")} -> 0.0630771 | H15: {=IF($A15<>"", IFERROR(_xlfn._xlws.FILTER(Log!$G:$G, (Log!$A:$A="Daily") * (Log!$C:$C=$A15) * (Log!$D:$D=H$4)), "Unknown"), "")} -> 0.097109 | I15: {=IF($A15<>"", IFERROR(_xlfn._xlws.FILTER(Log!$G:$G, (Log!$A:$A="Daily") * (Log!$C:$C=$A15) * (Log!$D:$D=I$4)), "Unknown"), "")} -> 0.0962242 | J15: {=IF($A15<>"", IFERROR(_xlfn._xlws.FILTER(Log!$G:$G, (Log!$A:$A="Daily") * (Log!$C:$C=$A15) * (Log!$D:$D=J$4)), "Unknown"), "")} -> 0.0577257 | ... T15: {=IF($A15<>"", IFERROR(_xlfn._xlws.FILTER(Log!$G:$G, (Log!$A:$A="Daily") * (Log!$C:$C=$A15) * (Log!$D:$D=T$4)), "Unknown"), "")} -> 0.107049 | U15: {=_xlfn._xlws.FILTER('Daily WE'!F:F, ('Daily WE'!$B:$B="n/a") * ('Daily WE'!$C:$C ='Daily IE'!$A15))} -> A | V15: {=_xlfn._xlws.FILTER('Daily WE'!G:G, ('Daily WE'!$B:$B="n/a") * ('Daily WE'!$C:$C ='Daily IE'!$A15))} -> 1000 | W15: =IF(ISBLANK($A15), "", IF(ISNUMBER(C15), C15/$B15, "Unknown")) -> 1.1822905 | X15: =IF(ISBLANK($A15), "", IF(ISNUMBER(D15), D15/$B15, "Unknown")) -> 1.1670008 | Y15: =IF(ISBLANK($A15), "", IF(ISNUMBER(E15), E15/$B15, "Unknown")) -> 1.1795491 | Z15: =IF(ISBLANK($A15), "", IF(ISNUMBER(F15), F15/$B15, "Unknown")) -> 1.2021526 | AA15: =IF(ISBLANK($A15), "", IF(ISNUMBER(G15), G15/$B15, "Unknown")) -> 0.65252217 | AB15: =IF(ISBLANK($A15), "", IF(ISNUMBER(H15), H15/$B15, "Unknown")) -> 1.0045766 | AC15: =IF(ISBLANK($A15), "", IF(ISNUMBER(I15), I15/$B15, "Unknown")) -> 0.99542345 | AD15: =IF(ISBLANK($A15), "", IF(ISNUMBER(J15), J15/$B15, "Unknown")) -> 0.59716283 | ... AN15: =IF(ISBLANK($A15), "", IF(ISNUMBER(T15), T15/$B15, "Unknown")) -> 1.1074042 | AO15: {=MEDIAN(_xlfn._xlws.FILTER($W$6:$AN$6,($W$6:$AN$6<>"Unknown")))} -> 1
A16: 46240 | B16: =IF($A16<>"", MEDIAN($C16:$T16), "") -> 0.09119725 | C16: {=IF($A16<>"", IFERROR(_xlfn._xlws.FILTER(Log!$G:$G, (Log!$A:$A="Daily") * (Log!$C:$C=$A16) * (Log!$D:$D=C$4)), "Unknown"), "")} -> 0.10691 | D16: {=IF($A16<>"", IFERROR(_xlfn._xlws.FILTER(Log!$G:$G, (Log!$A:$A="Daily") * (Log!$C:$C=$A16) * (Log!$D:$D=D$4)), "Unknown"), "")} -> 0.103111 | E16: {=IF($A16<>"", IFERROR(_xlfn._xlws.FILTER(Log!$G:$G, (Log!$A:$A="Daily") * (Log!$C:$C=$A16) * (Log!$D:$D=E$4)), "Unknown"), "")} -> 0.10941 | F16: {=IF($A16<>"", IFERROR(_xlfn._xlws.FILTER(Log!$G:$G, (Log!$A:$A="Daily") * (Log!$C:$C=$A16) * (Log!$D:$D=F$4)), "Unknown"), "")} -> 0.104373 | G16: {=IF($A16<>"", IFERROR(_xlfn._xlws.FILTER(Log!$G:$G, (Log!$A:$A="Daily") * (Log!$C:$C=$A16) * (Log!$D:$D=G$4)), "Unknown"), "")} -> 0.0701209 | H16: {=IF($A16<>"", IFERROR(_xlfn._xlws.FILTER(Log!$G:$G, (Log!$A:$A="Daily") * (Log!$C:$C=$A16) * (Log!$D:$D=H$4)), "Unknown"), "")} -> 0.0988203 | I16: {=IF($A16<>"", IFERROR(_xlfn._xlws.FILTER(Log!$G:$G, (Log!$A:$A="Daily") * (Log!$C:$C=$A16) * (Log!$D:$D=I$4)), "Unknown"), "")} -> 0.0929853 | J16: {=IF($A16<>"", IFERROR(_xlfn._xlws.FILTER(Log!$G:$G, (Log!$A:$A="Daily") * (Log!$C:$C=$A16) * (Log!$D:$D=J$4)), "Unknown"), "")} -> 0.0724495 | ... T16: {=IF($A16<>"", IFERROR(_xlfn._xlws.FILTER(Log!$G:$G, (Log!$A:$A="Daily") * (Log!$C:$C=$A16) * (Log!$D:$D=T$4)), "Unknown"), "")} -> 0.103296 | U16: {=_xlfn._xlws.FILTER('Daily WE'!F:F, ('Daily WE'!$B:$B="n/a") * ('Daily WE'!$C:$C ='Daily IE'!$A16))} -> A | V16: {=_xlfn._xlws.FILTER('Daily WE'!G:G, ('Daily WE'!$B:$B="n/a") * ('Daily WE'!$C:$C ='Daily IE'!$A16))} -> 1000 | W16: =IF(ISBLANK($A16), "", IF(ISNUMBER(C16), C16/$B16, "Unknown")) -> 1.1722941 | X16: =IF(ISBLANK($A16), "", IF(ISNUMBER(D16), D16/$B16, "Unknown")) -> 1.1306372 | Y16: =IF(ISBLANK($A16), "", IF(ISNUMBER(E16), E16/$B16, "Unknown")) -> 1.1997072 | Z16: =IF(ISBLANK($A16), "", IF(ISNUMBER(F16), F16/$B16, "Unknown")) -> 1.1444753 | AA16: =IF(ISBLANK($A16), "", IF(ISNUMBER(G16), G16/$B16, "Unknown")) -> 0.7688927 | AB16: =IF(ISBLANK($A16), "", IF(ISNUMBER(H16), H16/$B16, "Unknown")) -> 1.0835886 | AC16: =IF(ISBLANK($A16), "", IF(ISNUMBER(I16), I16/$B16, "Unknown")) -> 1.0196064 | AD16: =IF(ISBLANK($A16), "", IF(ISNUMBER(J16), J16/$B16, "Unknown")) -> 0.79442637 | ... AN16: =IF(ISBLANK($A16), "", IF(ISNUMBER(T16), T16/$B16, "Unknown")) -> 1.1326657 | AO16: {=MEDIAN(_xlfn._xlws.FILTER($W$6:$AN$6,($W$6:$AN$6<>"Unknown")))} -> 1
A17: 46242 | B17: =IF($A17<>"", MEDIAN($C17:$T17), "") -> 0.0899961 | C17: {=IF($A17<>"", IFERROR(_xlfn._xlws.FILTER(Log!$G:$G, (Log!$A:$A="Daily") * (Log!$C:$C=$A17) * (Log!$D:$D=C$4)), "Unknown"), "")} -> 0.121479 | D17: {=IF($A17<>"", IFERROR(_xlfn._xlws.FILTER(Log!$G:$G, (Log!$A:$A="Daily") * (Log!$C:$C=$A17) * (Log!$D:$D=D$4)), "Unknown"), "")} -> 0.107791 | E17: {=IF($A17<>"", IFERROR(_xlfn._xlws.FILTER(Log!$G:$G, (Log!$A:$A="Daily") * (Log!$C:$C=$A17) * (Log!$D:$D=E$4)), "Unknown"), "")} -> 0.113635 | F17: {=IF($A17<>"", IFERROR(_xlfn._xlws.FILTER(Log!$G:$G, (Log!$A:$A="Daily") * (Log!$C:$C=$A17) * (Log!$D:$D=F$4)), "Unknown"), "")} -> 0.110298 | G17: {=IF($A17<>"", IFERROR(_xlfn._xlws.FILTER(Log!$G:$G, (Log!$A:$A="Daily") * (Log!$C:$C=$A17) * (Log!$D:$D=G$4)), "Unknown"), "")} -> 0.0907495 | H17: {=IF($A17<>"", IFERROR(_xlfn._xlws.FILTER(Log!$G:$G, (Log!$A:$A="Daily") * (Log!$C:$C=$A17) * (Log!$D:$D=H$4)), "Unknown"), "")} -> 0.0816628 | I17: {=IF($A17<>"", IFERROR(_xlfn._xlws.FILTER(Log!$G:$G, (Log!$A:$A="Daily") * (Log!$C:$C=$A17) * (Log!$D:$D=I$4)), "Unknown"), "")} -> 0.0892427 | J17: {=IF($A17<>"", IFERROR(_xlfn._xlws.FILTER(Log!$G:$G, (Log!$A:$A="Daily") * (Log!$C:$C=$A17) * (Log!$D:$D=J$4)), "Unknown"), "")} -> 0.0815161 | ... T17: {=IF($A17<>"", IFERROR(_xlfn._xlws.FILTER(Log!$G:$G, (Log!$A:$A="Daily") * (Log!$C:$C=$A17) * (Log!$D:$D=T$4)), "Unknown"), "")} -> 0.11252 | U17: {=_xlfn._xlws.FILTER('Daily WE'!F:F, ('Daily WE'!$B:$B="n/a") * ('Daily WE'!$C:$C ='Daily IE'!$A17))} -> A | V17: {=_xlfn._xlws.FILTER('Daily WE'!G:G, ('Daily WE'!$B:$B="n/a") * ('Daily WE'!$C:$C ='Daily IE'!$A17))} -> 1000 | W17: =IF(ISBLANK($A17), "", IF(ISNUMBER(C17), C17/$B17, "Unknown")) -> 1.3498252 | X17: =IF(ISBLANK($A17), "", IF(ISNUMBER(D17), D17/$B17, "Unknown")) -> 1.1977297 | Y17: =IF(ISBLANK($A17), "", IF(ISNUMBER(E17), E17/$B17, "Unknown")) -> 1.2626658 | Z17: =IF(ISBLANK($A17), "", IF(ISNUMBER(F17), F17/$B17, "Unknown")) -> 1.2255864 | AA17: =IF(ISBLANK($A17), "", IF(ISNUMBER(G17), G17/$B17, "Unknown")) -> 1.0083715 | AB17: =IF(ISBLANK($A17), "", IF(ISNUMBER(H17), H17/$B17, "Unknown")) -> 0.90740377 | AC17: =IF(ISBLANK($A17), "", IF(ISNUMBER(I17), I17/$B17, "Unknown")) -> 0.99162853 | AD17: =IF(ISBLANK($A17), "", IF(ISNUMBER(J17), J17/$B17, "Unknown")) -> 0.90577369 | ... AN17: =IF(ISBLANK($A17), "", IF(ISNUMBER(T17), T17/$B17, "Unknown")) -> 1.2502764 | AO17: {=MEDIAN(_xlfn._xlws.FILTER($W$6:$AN$6,($W$6:$AN$6<>"Unknown")))} -> 1
A18: 46244 | B18: =IF($A18<>"", MEDIAN($C18:$T18), "") -> 0.125658 | C18: {=IF($A18<>"", IFERROR(_xlfn._xlws.FILTER(Log!$G:$G, (Log!$A:$A="Daily") * (Log!$C:$C=$A18) * (Log!$D:$D=C$4)), "Unknown"), "")} -> 0.145202 | D18: {=IF($A18<>"", IFERROR(_xlfn._xlws.FILTER(Log!$G:$G, (Log!$A:$A="Daily") * (Log!$C:$C=$A18) * (Log!$D:$D=D$4)), "Unknown"), "")} -> 0.139704 | E18: {=IF($A18<>"", IFERROR(_xlfn._xlws.FILTER(Log!$G:$G, (Log!$A:$A="Daily") * (Log!$C:$C=$A18) * (Log!$D:$D=E$4)), "Unknown"), "")} -> 0.142537 | F18: {=IF($A18<>"", IFERROR(_xlfn._xlws.FILTER(Log!$G:$G, (Log!$A:$A="Daily") * (Log!$C:$C=$A18) * (Log!$D:$D=F$4)), "Unknown"), "")} -> 0.113266 | G18: {=IF($A18<>"", IFERROR(_xlfn._xlws.FILTER(Log!$G:$G, (Log!$A:$A="Daily") * (Log!$C:$C=$A18) * (Log!$D:$D=G$4)), "Unknown"), "")} -> 0.10468 | H18: {=IF($A18<>"", IFERROR(_xlfn._xlws.FILTER(Log!$G:$G, (Log!$A:$A="Daily") * (Log!$C:$C=$A18) * (Log!$D:$D=H$4)), "Unknown"), "")} -> 0.14379 | I18: {=IF($A18<>"", IFERROR(_xlfn._xlws.FILTER(Log!$G:$G, (Log!$A:$A="Daily") * (Log!$C:$C=$A18) * (Log!$D:$D=I$4)), "Unknown"), "")} -> 0.143113 | J18: {=IF($A18<>"", IFERROR(_xlfn._xlws.FILTER(Log!$G:$G, (Log!$A:$A="Daily") * (Log!$C:$C=$A18) * (Log!$D:$D=J$4)), "Unknown"), "")} -> 0.069675 | ... T18: {=IF($A18<>"", IFERROR(_xlfn._xlws.FILTER(Log!$G:$G, (Log!$A:$A="Daily") * (Log!$C:$C=$A18) * (Log!$D:$D=T$4)), "Unknown"), "")} -> 0.0832332 | U18: {=_xlfn._xlws.FILTER('Daily WE'!F:F, ('Daily WE'!$B:$B="n/a") * ('Daily WE'!$C:$C ='Daily IE'!$A18))} -> D | V18: {=_xlfn._xlws.FILTER('Daily WE'!G:G, ('Daily WE'!$B:$B="n/a") * ('Daily WE'!$C:$C ='Daily IE'!$A18))} -> 1000 | W18: =IF(ISBLANK($A18), "", IF(ISNUMBER(C18), C18/$B18, "Unknown")) -> 1.1555333 | X18: =IF(ISBLANK($A18), "", IF(ISNUMBER(D18), D18/$B18, "Unknown")) -> 1.1117796 | Y18: =IF(ISBLANK($A18), "", IF(ISNUMBER(E18), E18/$B18, "Unknown")) -> 1.1343249 | Z18: =IF(ISBLANK($A18), "", IF(ISNUMBER(F18), F18/$B18, "Unknown")) -> 0.90138312 | AA18: =IF(ISBLANK($A18), "", IF(ISNUMBER(G18), G18/$B18, "Unknown")) -> 0.8330548 | AB18: =IF(ISBLANK($A18), "", IF(ISNUMBER(H18), H18/$B18, "Unknown")) -> 1.1442964 | AC18: =IF(ISBLANK($A18), "", IF(ISNUMBER(I18), I18/$B18, "Unknown")) -> 1.1389088 | AD18: =IF(ISBLANK($A18), "", IF(ISNUMBER(J18), J18/$B18, "Unknown")) -> 0.55448121 | ... AN18: =IF(ISBLANK($A18), "", IF(ISNUMBER(T18), T18/$B18, "Unknown")) -> 0.66237884 | AO18: {=MEDIAN(_xlfn._xlws.FILTER($W$6:$AN$6,($W$6:$AN$6<>"Unknown")))} -> 1
... A20: 46246 | B20: =IF($A20<>"", MEDIAN($C20:$T20), "") -> 0.1264915 | C20: {=IF($A20<>"", IFERROR(_xlfn._xlws.FILTER(Log!$G:$G, (Log!$A:$A="Daily") * (Log!$C:$C=$A20) * (Log!$D:$D=C$4)), "Unknown"), "")} -> 0.1021 | D20: {=IF($A20<>"", IFERROR(_xlfn._xlws.FILTER(Log!$G:$G, (Log!$A:$A="Daily") * (Log!$C:$C=$A20) * (Log!$D:$D=D$4)), "Unknown"), "")} -> 0.126891 | E20: {=IF($A20<>"", IFERROR(_xlfn._xlws.FILTER(Log!$G:$G, (Log!$A:$A="Daily") * (Log!$C:$C=$A20) * (Log!$D:$D=E$4)), "Unknown"), "")} -> 0.152672 | F20: {=IF($A20<>"", IFERROR(_xlfn._xlws.FILTER(Log!$G:$G, (Log!$A:$A="Daily") * (Log!$C:$C=$A20) * (Log!$D:$D=F$4)), "Unknown"), "")} -> 0.144092 | G20: {=IF($A20<>"", IFERROR(_xlfn._xlws.FILTER(Log!$G:$G, (Log!$A:$A="Daily") * (Log!$C:$C=$A20) * (Log!$D:$D=G$4)), "Unknown"), "")} -> 0.224774 | H20: {=IF($A20<>"", IFERROR(_xlfn._xlws.FILTER(Log!$G:$G, (Log!$A:$A="Daily") * (Log!$C:$C=$A20) * (Log!$D:$D=H$4)), "Unknown"), "")} -> 0.255786 | I20: {=IF($A20<>"", IFERROR(_xlfn._xlws.FILTER(Log!$G:$G, (Log!$A:$A="Daily") * (Log!$C:$C=$A20) * (Log!$D:$D=I$4)), "Unknown"), "")} -> 0.289818 | J20: {=IF($A20<>"", IFERROR(_xlfn._xlws.FILTER(Log!$G:$G, (Log!$A:$A="Daily") * (Log!$C:$C=$A20) * (Log!$D:$D=J$4)), "Unknown"), "")} -> 0.167485 | ... T20: {=IF($A20<>"", IFERROR(_xlfn._xlws.FILTER(Log!$G:$G, (Log!$A:$A="Daily") * (Log!$C:$C=$A20) * (Log!$D:$D=T$4)), "Unknown"), "")} -> 0.106762 | U20: {=_xlfn._xlws.FILTER('Daily WE'!F:F, ('Daily WE'!$B:$B="n/a") * ('Daily WE'!$C:$C ='Daily IE'!$A20))} -> G | V20: {=_xlfn._xlws.FILTER('Daily WE'!G:G, ('Daily WE'!$B:$B="n/a") * ('Daily WE'!$C:$C ='Daily IE'!$A20))} -> 1000 | W20: =IF(ISBLANK($A20), "", IF(ISNUMBER(C20), C20/$B20, "Unknown")) -> 0.80716886 | X20: =IF(ISBLANK($A20), "", IF(ISNUMBER(D20), D20/$B20, "Unknown")) -> 1.0031583 | Y20: =IF(ISBLANK($A20), "", IF(ISNUMBER(E20), E20/$B20, "Unknown")) -> 1.2069744 | Z20: =IF(ISBLANK($A20), "", IF(ISNUMBER(F20), F20/$B20, "Unknown")) -> 1.1391437 | AA20: =IF(ISBLANK($A20), "", IF(ISNUMBER(G20), G20/$B20, "Unknown")) -> 1.776989 | AB20: =IF(ISBLANK($A20), "", IF(ISNUMBER(H20), H20/$B20, "Unknown")) -> 2.0221596 | AC20: =IF(ISBLANK($A20), "", IF(ISNUMBER(I20), I20/$B20, "Unknown")) -> 2.2912053 | AD20: =IF(ISBLANK($A20), "", IF(ISNUMBER(J20), J20/$B20, "Unknown")) -> 1.3240811 | ... AN20: =IF(ISBLANK($A20), "", IF(ISNUMBER(T20), T20/$B20, "Unknown")) -> 0.84402509 | AO20: {=MEDIAN(_xlfn._xlws.FILTER($W$6:$AN$6,($W$6:$AN$6<>"Unknown")))} -> 1
A21: 46247 | B21: =IF($A21<>"", MEDIAN($C21:$T21), "") -> 0.0745968 | C21: {=IF($A21<>"", IFERROR(_xlfn._xlws.FILTER(Log!$G:$G, (Log!$A:$A="Daily") * (Log!$C:$C=$A21) * (Log!$D:$D=C$4)), "Unknown"), "")} -> 0.113922 | D21: {=IF($A21<>"", IFERROR(_xlfn._xlws.FILTER(Log!$G:$G, (Log!$A:$A="Daily") * (Log!$C:$C=$A21) * (Log!$D:$D=D$4)), "Unknown"), "")} -> 0.120023 | E21: {=IF($A21<>"", IFERROR(_xlfn._xlws.FILTER(Log!$G:$G, (Log!$A:$A="Daily") * (Log!$C:$C=$A21) * (Log!$D:$D=E$4)), "Unknown"), "")} -> 0.0885529 | F21: {=IF($A21<>"", IFERROR(_xlfn._xlws.FILTER(Log!$G:$G, (Log!$A:$A="Daily") * (Log!$C:$C=$A21) * (Log!$D:$D=F$4)), "Unknown"), "")} -> 0.0891205 | G21: {=IF($A21<>"", IFERROR(_xlfn._xlws.FILTER(Log!$G:$G, (Log!$A:$A="Daily") * (Log!$C:$C=$A21) * (Log!$D:$D=G$4)), "Unknown"), "")} -> 0.0516624 | H21: {=IF($A21<>"", IFERROR(_xlfn._xlws.FILTER(Log!$G:$G, (Log!$A:$A="Daily") * (Log!$C:$C=$A21) * (Log!$D:$D=H$4)), "Unknown"), "")} -> 0.0743878 | I21: {=IF($A21<>"", IFERROR(_xlfn._xlws.FILTER(Log!$G:$G, (Log!$A:$A="Daily") * (Log!$C:$C=$A21) * (Log!$D:$D=I$4)), "Unknown"), "")} -> 0.07398 | J21: {=IF($A21<>"", IFERROR(_xlfn._xlws.FILTER(Log!$G:$G, (Log!$A:$A="Daily") * (Log!$C:$C=$A21) * (Log!$D:$D=J$4)), "Unknown"), "")} -> 0.0552003 | ... T21: {=IF($A21<>"", IFERROR(_xlfn._xlws.FILTER(Log!$G:$G, (Log!$A:$A="Daily") * (Log!$C:$C=$A21) * (Log!$D:$D=T$4)), "Unknown"), "")} -> 0.0748058 | U21: {=_xlfn._xlws.FILTER('Daily WE'!F:F, ('Daily WE'!$B:$B="n/a") * ('Daily WE'!$C:$C ='Daily IE'!$A21))} -> F | V21: {=_xlfn._xlws.FILTER('Daily WE'!G:G, ('Daily WE'!$B:$B="n/a") * ('Daily WE'!$C:$C ='Daily IE'!$A21))} -> 1000 | W21: =IF(ISBLANK($A21), "", IF(ISNUMBER(C21), C21/$B21, "Unknown")) -> 1.5271701 | X21: =IF(ISBLANK($A21), "", IF(ISNUMBER(D21), D21/$B21, "Unknown")) -> 1.6089564 | Y21: =IF(ISBLANK($A21), "", IF(ISNUMBER(E21), E21/$B21, "Unknown")) -> 1.1870871 | Z21: =IF(ISBLANK($A21), "", IF(ISNUMBER(F21), F21/$B21, "Unknown")) -> 1.194696 | AA21: =IF(ISBLANK($A21), "", IF(ISNUMBER(G21), G21/$B21, "Unknown")) -> 0.69255518 | AB21: =IF(ISBLANK($A21), "", IF(ISNUMBER(H21), H21/$B21, "Unknown")) -> 0.99719827 | AC21: =IF(ISBLANK($A21), "", IF(ISNUMBER(I21), I21/$B21, "Unknown")) -> 0.99173155 | AD21: =IF(ISBLANK($A21), "", IF(ISNUMBER(J21), J21/$B21, "Unknown")) -> 0.73998214 | ... AN21: =IF(ISBLANK($A21), "", IF(ISNUMBER(T21), T21/$B21, "Unknown")) -> 1.0028017
A22: 46248 | B22: =IF($A22<>"", MEDIAN($C22:$T22), "") -> 0.0939804 | C22: {=IF($A22<>"", IFERROR(_xlfn._xlws.FILTER(Log!$G:$G, (Log!$A:$A="Daily") * (Log!$C:$C=$A22) * (Log!$D:$D=C$4)), "Unknown"), "")} -> 0.121454 | D22: {=IF($A22<>"", IFERROR(_xlfn._xlws.FILTER(Log!$G:$G, (Log!$A:$A="Daily") * (Log!$C:$C=$A22) * (Log!$D:$D=D$4)), "Unknown"), "")} -> 0.107267 | E22: {=IF($A22<>"", IFERROR(_xlfn._xlws.FILTER(Log!$G:$G, (Log!$A:$A="Daily") * (Log!$C:$C=$A22) * (Log!$D:$D=E$4)), "Unknown"), "")} -> 0.104221 | F22: {=IF($A22<>"", IFERROR(_xlfn._xlws.FILTER(Log!$G:$G, (Log!$A:$A="Daily") * (Log!$C:$C=$A22) * (Log!$D:$D=F$4)), "Unknown"), "")} -> 0.090715 | G22: {=IF($A22<>"", IFERROR(_xlfn._xlws.FILTER(Log!$G:$G, (Log!$A:$A="Daily") * (Log!$C:$C=$A22) * (Log!$D:$D=G$4)), "Unknown"), "")} -> 0.0690103 | H22: {=IF($A22<>"", IFERROR(_xlfn._xlws.FILTER(Log!$G:$G, (Log!$A:$A="Daily") * (Log!$C:$C=$A22) * (Log!$D:$D=H$4)), "Unknown"), "")} -> 0.101456 | I22: {=IF($A22<>"", IFERROR(_xlfn._xlws.FILTER(Log!$G:$G, (Log!$A:$A="Daily") * (Log!$C:$C=$A22) * (Log!$D:$D=I$4)), "Unknown"), "")} -> 0.10539 | J22: {=IF($A22<>"", IFERROR(_xlfn._xlws.FILTER(Log!$G:$G, (Log!$A:$A="Daily") * (Log!$C:$C=$A22) * (Log!$D:$D=J$4)), "Unknown"), "")} -> 0.0809096 | ... T22: {=IF($A22<>"", IFERROR(_xlfn._xlws.FILTER(Log!$G:$G, (Log!$A:$A="Daily") * (Log!$C:$C=$A22) * (Log!$D:$D=T$4)), "Unknown"), "")} -> 0.0799717 | U22: {=_xlfn._xlws.FILTER('Daily WE'!F:F, ('Daily WE'!$B:$B="n/a") * ('Daily WE'!$C:$C ='Daily IE'!$A22))} -> H | V22: {=_xlfn._xlws.FILTER('Daily WE'!G:G, ('Daily WE'!$B:$B="n/a") * ('Daily WE'!$C:$C ='Daily IE'!$A22))} -> 1000 | W22: =IF(ISBLANK($A22), "", IF(ISNUMBER(C22), C22/$B22, "Unknown")) -> 1.2923333 | X22: =IF(ISBLANK($A22), "", IF(ISNUMBER(D22), D22/$B22, "Unknown")) -> 1.1413763 | Y22: =IF(ISBLANK($A22), "", IF(ISNUMBER(E22), E22/$B22, "Unknown")) -> 1.1089653 | Z22: =IF(ISBLANK($A22), "", IF(ISNUMBER(F22), F22/$B22, "Unknown")) -> 0.96525446 | AA22: =IF(ISBLANK($A22), "", IF(ISNUMBER(G22), G22/$B22, "Unknown")) -> 0.73430524 | AB22: =IF(ISBLANK($A22), "", IF(ISNUMBER(H22), H22/$B22, "Unknown")) -> 1.0795442 | AC22: =IF(ISBLANK($A22), "", IF(ISNUMBER(I22), I22/$B22, "Unknown")) -> 1.121404 | AD22: =IF(ISBLANK($A22), "", IF(ISNUMBER(J22), J22/$B22, "Unknown")) -> 0.86091994 | ... AN22: =IF(ISBLANK($A22), "", IF(ISNUMBER(T22), T22/$B22, "Unknown")) -> 0.8509402
A23: 46251 | B23: =IF($A23<>"", MEDIAN($C23:$T23), "") -> 0.0968762 | C23: {=IF($A23<>"", IFERROR(_xlfn._xlws.FILTER(Log!$G:$G, (Log!$A:$A="Daily") * (Log!$B:$B="n/a") * (Log!$C:$C=$A23) * (Log!$D:$D=C$4)), "Unknown"), "")} -> 0.112145 | D23: {=IF($A23<>"", IFERROR(_xlfn._xlws.FILTER(Log!$G:$G, (Log!$A:$A="Daily") * (Log!$B:$B="n/a") * (Log!$C:$C=$A23) * (Log!$D:$D=D$4)), "Unknown"), "")} -> 0.0953259 | E23: {=IF($A23<>"", IFERROR(_xlfn._xlws.FILTER(Log!$G:$G, (Log!$A:$A="Daily") * (Log!$B:$B="n/a") * (Log!$C:$C=$A23) * (Log!$D:$D=E$4)), "Unknown"), "")} -> 0.114796 | F23: {=IF($A23<>"", IFERROR(_xlfn._xlws.FILTER(Log!$G:$G, (Log!$A:$A="Daily") * (Log!$B:$B="n/a") * (Log!$C:$C=$A23) * (Log!$D:$D=F$4)), "Unknown"), "")} -> 0.104508 | G23: {=IF($A23<>"", IFERROR(_xlfn._xlws.FILTER(Log!$G:$G, (Log!$A:$A="Daily") * (Log!$B:$B="n/a") * (Log!$C:$C=$A23) * (Log!$D:$D=G$4)), "Unknown"), "")} -> 0.0844692 | H23: {=IF($A23<>"", IFERROR(_xlfn._xlws.FILTER(Log!$G:$G, (Log!$A:$A="Daily") * (Log!$B:$B="n/a") * (Log!$C:$C=$A23) * (Log!$D:$D=H$4)), "Unknown"), "")} -> 0.11239 | I23: {=IF($A23<>"", IFERROR(_xlfn._xlws.FILTER(Log!$G:$G, (Log!$A:$A="Daily") * (Log!$B:$B="n/a") * (Log!$C:$C=$A23) * (Log!$D:$D=I$4)), "Unknown"), "")} -> 0.108448 | J23: {=IF($A23<>"", IFERROR(_xlfn._xlws.FILTER(Log!$G:$G, (Log!$A:$A="Daily") * (Log!$B:$B="n/a") * (Log!$C:$C=$A23) * (Log!$D:$D=J$4)), "Unknown"), "")} -> 0.0879742 | ... T23: {=IF($A23<>"", IFERROR(_xlfn._xlws.FILTER(Log!$G:$G, (Log!$A:$A="Daily") * (Log!$B:$B="n/a") * (Log!$C:$C=$A23) * (Log!$D:$D=T$4)), "Unknown"), "")} -> 0.120329 | U23: {=_xlfn._xlws.FILTER('Daily WE'!F:F, ('Daily WE'!$B:$B="n/a") * ('Daily WE'!$C:$C ='Daily IE'!$A23))} -> I | V23: {=_xlfn._xlws.FILTER('Daily WE'!G:G, ('Daily WE'!$B:$B="n/a") * ('Daily WE'!$C:$C ='Daily IE'!$A23))} -> 1000 | W23: =IF(ISBLANK($A23), "", IF(ISNUMBER(C23), C23/$B23, "Unknown")) -> 1.1576115 | X23: =IF(ISBLANK($A23), "", IF(ISNUMBER(D23), D23/$B23, "Unknown")) -> 0.9839971 | Y23: =IF(ISBLANK($A23), "", IF(ISNUMBER(E23), E23/$B23, "Unknown")) -> 1.1849763 | Z23: =IF(ISBLANK($A23), "", IF(ISNUMBER(F23), F23/$B23, "Unknown")) -> 1.0787789 | AA23: =IF(ISBLANK($A23), "", IF(ISNUMBER(G23), G23/$B23, "Unknown")) -> 0.87192933 | AB23: =IF(ISBLANK($A23), "", IF(ISNUMBER(H23), H23/$B23, "Unknown")) -> 1.1601405 | AC23: =IF(ISBLANK($A23), "", IF(ISNUMBER(I23), I23/$B23, "Unknown")) -> 1.1194494 | AD23: =IF(ISBLANK($A23), "", IF(ISNUMBER(J23), J23/$B23, "Unknown")) -> 0.90810953 | ... AN23: =IF(ISBLANK($A23), "", IF(ISNUMBER(T23), T23/$B23, "Unknown")) -> 1.2420904
