Workbook

Sheet Instructions
C2: Step | D2: Task
C3: 1 | D3: Open Nexus 2.18
C4: 1 new | D4: Open VSCodium and start the nexus temp reader script AFTER cameras online
C5: 2 | D5: Record to 'Daily Summary' the starting time and temperature (use INB0104 thermostat room temperature, turn it on to read then off again if previously off to maintain temp)
C7: 3 | D7: Wait for cameras to turn on (all cameras reading enabled ADD SCREENSHOT OF STARTUP) then record the initial log entry manually to 'Log' sheet (add lowest temperature and highest temperature for range as well as timestamp and date key
C8: 4 old | D8: Every x minutes record the temp range as a new entry (5-10 mins is usually good enough but when the range gets close to 50deg try to record the minute it reaches all cameras 50 or higher)
C9: 4 new | D9: Open VSCodium and start the nexus temp reader script AFTER cameras online
C12: WIP
C13: In case anyone else has to use this sheet
D15: Ranges that can be edited
D16: Ranges that are calculated & should not be edited
C17: todo add sheet protection to orange ranges

Sheet Log
A1: Blue columns are data to enter, orange columns are automatically calculated! | I1: Note: Dark/red rows (see column B) are invalid data, and keys in A column/daily summary should not be dates if there's a data problem
A2: Key usually date, but invalid data is labelled | B2: Is Invalid? Mark if data is broken | C2: Logging Start Time | D2: Timestamp | E2: Lowest Temperature | F2: Highest Temperature | G2: Minutes Passed | H2: Range
A3: 46228 | C3: =_xlfn.XLOOKUP(Log!A3, 'Daily Summary'!A:A, 'Daily Summary'!C:C, "Not found!") -> 0.78819444 | D3: 0.79027778 | E3: 32 | F3: 35 | G3: =IF(AND($D3<>"", $C3<>""), ($D3-$C3)*1440, "") -> 3 | H3: =IF(AND($F3<>"",$E3<>""), $F3-$E3, "") -> 3
A4: 46228 | C4: =_xlfn.XLOOKUP(Log!A4, 'Daily Summary'!A:A, 'Daily Summary'!C:C, "Not found!") -> 0.78819444 | D4: 0.79444444 | E4: 41 | F4: 44 | G4: =IF(AND($D4<>"", $C4<>""), ($D4-$C4)*1440, "") -> 9 | H4: =IF(AND($F4<>"",$E4<>""), $F4-$E4, "") -> 3
A5: 46228 | C5: =_xlfn.XLOOKUP(Log!A5, 'Daily Summary'!A:A, 'Daily Summary'!C:C, "Not found!") -> 0.78819444 | D5: 0.80138889 | E5: 49 | F5: 52 | G5: =IF(AND($D5<>"", $C5<>""), ($D5-$C5)*1440, "") -> 19 | H5: =IF(AND($F5<>"",$E5<>""), $F5-$E5, "") -> 3
A6: 46228 | C6: =_xlfn.XLOOKUP(Log!A6, 'Daily Summary'!A:A, 'Daily Summary'!C:C, "Not found!") -> 0.78819444 | D6: 0.80555556 | E6: 52 | F6: 55 | G6: =IF(AND($D6<>"", $C6<>""), ($D6-$C6)*1440, "") -> 25 | H6: =IF(AND($F6<>"",$E6<>""), $F6-$E6, "") -> 3
A7: 46228 | C7: =_xlfn.XLOOKUP(Log!A7, 'Daily Summary'!A:A, 'Daily Summary'!C:C, "Not found!") -> 0.78819444 | D7: 0.81597222 | E7: 57 | F7: 58 | G7: =IF(AND($D7<>"", $C7<>""), ($D7-$C7)*1440, "") -> 40 | H7: =IF(AND($F7<>"",$E7<>""), $F7-$E7, "") -> 1
A8: 46228 | C8: =_xlfn.XLOOKUP(Log!A8, 'Daily Summary'!A:A, 'Daily Summary'!C:C, "Not found!") -> 0.78819444 | D8: 0.83194444 | E8: 60 | F8: 61 | G8: =IF(AND($D8<>"", $C8<>""), ($D8-$C8)*1440, "") -> 63 | H8: =IF(AND($F8<>"",$E8<>""), $F8-$E8, "") -> 1
A9: 46230 | C9: =_xlfn.XLOOKUP(Log!A9, 'Daily Summary'!A:A, 'Daily Summary'!C:C, "Not found!") -> 0.42916667 | D9: 0.43125 | E9: 32 | F9: 33 | G9: =IF(AND($D9<>"", $C9<>""), ($D9-$C9)*1440, "") -> 3 | H9: =IF(AND($F9<>"",$E9<>""), $F9-$E9, "") -> 1
A10: 46230 | C10: =_xlfn.XLOOKUP(Log!A10, 'Daily Summary'!A:A, 'Daily Summary'!C:C, "Not found!") -> 0.42916667 | D10: 0.43611111 | E10: 42 | F10: 44 | G10: =IF(AND($D10<>"", $C10<>""), ($D10-$C10)*1440, "") -> 10 | H10: =IF(AND($F10<>"",$E10<>""), $F10-$E10, "") -> 2
A11: 46230 | C11: =_xlfn.XLOOKUP(Log!A11, 'Daily Summary'!A:A, 'Daily Summary'!C:C, "Not found!") -> 0.42916667 | D11: 0.44027778 | E11: 48 | F11: 49 | G11: =IF(AND($D11<>"", $C11<>""), ($D11-$C11)*1440, "") -> 16 | H11: =IF(AND($F11<>"",$E11<>""), $F11-$E11, "") -> 1
A12: 46230 | C12: =_xlfn.XLOOKUP(Log!A12, 'Daily Summary'!A:A, 'Daily Summary'!C:C, "Not found!") -> 0.42916667 | D12: 0.44583333 | E12: 51 | F12: 54 | G12: =IF(AND($D12<>"", $C12<>""), ($D12-$C12)*1440, "") -> 24 | H12: =IF(AND($F12<>"",$E12<>""), $F12-$E12, "") -> 3
A13: 46230 | C13: =_xlfn.XLOOKUP(Log!A13, 'Daily Summary'!A:A, 'Daily Summary'!C:C, "Not found!") -> 0.42916667 | D13: 0.45902778 | E13: 57 | F13: 60 | G13: =IF(AND($D13<>"", $C13<>""), ($D13-$C13)*1440, "") -> 43 | H13: =IF(AND($F13<>"",$E13<>""), $F13-$E13, "") -> 3
A14: 46231 | C14: =_xlfn.XLOOKUP(Log!A14, 'Daily Summary'!A:A, 'Daily Summary'!C:C, "Not found!") -> 0.38194444 | D14: 0.38402778 | E14: 31 | F14: 32 | G14: =IF(AND($D14<>"", $C14<>""), ($D14-$C14)*1440, "") -> 3 | H14: =IF(AND($F14<>"",$E14<>""), $F14-$E14, "") -> 1
... A37: 46234 | C37: =_xlfn.XLOOKUP(Log!A37, 'Daily Summary'!A:A, 'Daily Summary'!C:C, "Not found!") -> 0.43055556 | D37: 0.44861111 | E37: 54 | F37: 55 | G37: =IF(AND($D37<>"", $C37<>""), ($D37-$C37)*1440, "") -> 26 | H37: =IF(AND($F37<>"",$E37<>""), $F37-$E37, "") -> 1
A38: 46235 | C38: =_xlfn.XLOOKUP(Log!A38, 'Daily Summary'!A:A, 'Daily Summary'!C:C, "Not found!") -> 0.70625 | D38: 0.70763889 | E38: 28 | F38: 30 | G38: =IF(AND($D38<>"", $C38<>""), ($D38-$C38)*1440, "") -> 2 | H38: =IF(AND($F38<>"",$E38<>""), $F38-$E38, "") -> 2 | J38: from 01/08/26 started using camera script (more granular timestamps and regular measurements vs manual)
A39: 46235 | C39: =_xlfn.XLOOKUP(Log!A39, 'Daily Summary'!A:A, 'Daily Summary'!C:C, "Not found!") -> 0.70625 | D39: 0.70866898 | E39: 32 | F39: 35 | G39: =IF(AND($D39<>"", $C39<>""), ($D39-$C39)*1440, "") -> 3.4833333 | H39: =IF(AND($F39<>"",$E39<>""), $F39-$E39, "") -> 3
A40: 46235 | C40: =_xlfn.XLOOKUP(Log!A40, 'Daily Summary'!A:A, 'Daily Summary'!C:C, "Not found!") -> 0.70625 | D40: 0.71006944 | E40: 36 | F40: 39 | G40: =IF(AND($D40<>"", $C40<>""), ($D40-$C40)*1440, "") -> 5.5 | H40: =IF(AND($F40<>"",$E40<>""), $F40-$E40, "") -> 3
A41: 46235 | C41: =_xlfn.XLOOKUP(Log!A41, 'Daily Summary'!A:A, 'Daily Summary'!C:C, "Not found!") -> 0.70625 | D41: 0.71146991 | E41: 39 | F41: 42 | G41: =IF(AND($D41<>"", $C41<>""), ($D41-$C41)*1440, "") -> 7.5166667 | H41: =IF(AND($F41<>"",$E41<>""), $F41-$E41, "") -> 3
A42: 46235 | C42: =_xlfn.XLOOKUP(Log!A42, 'Daily Summary'!A:A, 'Daily Summary'!C:C, "Not found!") -> 0.70625 | D42: 0.7128588 | E42: 42 | F42: 45 | G42: =IF(AND($D42<>"", $C42<>""), ($D42-$C42)*1440, "") -> 9.5166667 | H42: =IF(AND($F42<>"",$E42<>""), $F42-$E42, "") -> 3
A43: 46235 | C43: =_xlfn.XLOOKUP(Log!A43, 'Daily Summary'!A:A, 'Daily Summary'!C:C, "Not found!") -> 0.70625 | D43: 0.71425926 | E43: 44 | F43: 45 | G43: =IF(AND($D43<>"", $C43<>""), ($D43-$C43)*1440, "") -> 11.533333 | H43: =IF(AND($F43<>"",$E43<>""), $F43-$E43, "") -> 1
A44: 46235 | C44: =_xlfn.XLOOKUP(Log!A44, 'Daily Summary'!A:A, 'Daily Summary'!C:C, "Not found!") -> 0.70625 | D44: 0.71564815 | E44: 45 | F44: 48 | G44: =IF(AND($D44<>"", $C44<>""), ($D44-$C44)*1440, "") -> 13.533333 | H44: =IF(AND($F44<>"",$E44<>""), $F44-$E44, "") -> 3
A45: 46235 | C45: =_xlfn.XLOOKUP(Log!A45, 'Daily Summary'!A:A, 'Daily Summary'!C:C, "Not found!") -> 0.70625 | D45: 0.71704861 | E45: 48 | F45: 49 | G45: =IF(AND($D45<>"", $C45<>""), ($D45-$C45)*1440, "") -> 15.55 | H45: =IF(AND($F45<>"",$E45<>""), $F45-$E45, "") -> 1
A46: 46235 | C46: =_xlfn.XLOOKUP(Log!A46, 'Daily Summary'!A:A, 'Daily Summary'!C:C, "Not found!") -> 0.70625 | D46: 0.7184375 | E46: 48 | F46: 51 | G46: =IF(AND($D46<>"", $C46<>""), ($D46-$C46)*1440, "") -> 17.55 | H46: =IF(AND($F46<>"",$E46<>""), $F46-$E46, "") -> 3
A47: 46235 | C47: =_xlfn.XLOOKUP(Log!A47, 'Daily Summary'!A:A, 'Daily Summary'!C:C, "Not found!") -> 0.70625 | D47: 0.71983796 | E47: 49 | F47: 52 | G47: =IF(AND($D47<>"", $C47<>""), ($D47-$C47)*1440, "") -> 19.566667 | H47: =IF(AND($F47<>"",$E47<>""), $F47-$E47, "") -> 3
A48: 46235 | C48: =_xlfn.XLOOKUP(Log!A48, 'Daily Summary'!A:A, 'Daily Summary'!C:C, "Not found!") -> 0.70625 | D48: 0.72123843 | E48: 51 | F48: 52 | G48: =IF(AND($D48<>"", $C48<>""), ($D48-$C48)*1440, "") -> 21.583333 | H48: =IF(AND($F48<>"",$E48<>""), $F48-$E48, "") -> 1
A49: 46235 | C49: =_xlfn.XLOOKUP(Log!A49, 'Daily Summary'!A:A, 'Daily Summary'!C:C, "Not found!") -> 0.70625 | D49: 0.72262731 | E49: 51 | F49: 54 | G49: =IF(AND($D49<>"", $C49<>""), ($D49-$C49)*1440, "") -> 23.583333 | H49: =IF(AND($F49<>"",$E49<>""), $F49-$E49, "") -> 3
A50: 46235 | C50: =_xlfn.XLOOKUP(Log!A50, 'Daily Summary'!A:A, 'Daily Summary'!C:C, "Not found!") -> 0.70625 | D50: 0.7240162 | E50: 52 | F50: 55 | G50: =IF(AND($D50<>"", $C50<>""), ($D50-$C50)*1440, "") -> 25.583333 | H50: =IF(AND($F50<>"",$E50<>""), $F50-$E50, "") -> 3
... A267: 46254 | C267: =_xlfn.XLOOKUP(Log!A267, 'Daily Summary'!A:A, 'Daily Summary'!C:C, "Not found!") -> 0.54236111 | D267: 0.56243056 | E267: 54 | F267: 57 | G267: =IF(AND($D267<>"", $C267<>""), ($D267-$C267)*1440, "") -> 28.9 | H267: =IF(AND($F267<>"",$E267<>""), $F267-$E267, "") -> 3
A268: 46254 | C268: =_xlfn.XLOOKUP(Log!A268, 'Daily Summary'!A:A, 'Daily Summary'!C:C, "Not found!") -> 0.54236111 | D268: 0.56381944 | E268: 54 | F268: 58 | G268: =IF(AND($D268<>"", $C268<>""), ($D268-$C268)*1440, "") -> 30.9 | H268: =IF(AND(F268<>"",E268<>""),F268-E268,"") -> 4
A269: 46255 | C269: =_xlfn.XLOOKUP(Log!A269, 'Daily Summary'!A:A, 'Daily Summary'!C:C, "Not found!") -> 0.59305556 | D269: 0.59375 | E269: 29 | F269: 31 | G269: =IF(AND($D269<>"", $C269<>""), ($D269-$C269)*1440, "") -> 1 | H269: =IF(AND(F269<>"",E269<>""),F269-E269,"") -> 2
A270: 46255 | C270: =_xlfn.XLOOKUP(Log!A270, 'Daily Summary'!A:A, 'Daily Summary'!C:C, "Not found!") -> 0.59305556 | D270: 0.60334491 | E270: 48 | F270: 49 | G270: =IF(AND($D270<>"", $C270<>""), ($D270-$C270)*1440, "") -> 14.816667 | H270: =IF(AND(F270<>"",E270<>""),F270-E270,"") -> 1
A271: 46255 | C271: =_xlfn.XLOOKUP(Log!A271, 'Daily Summary'!A:A, 'Daily Summary'!C:C, "Not found!") -> 0.59305556 | D271: 0.6047338 | E271: 49 | F271: 52 | G271: =IF(AND($D271<>"", $C271<>""), ($D271-$C271)*1440, "") -> 16.816667 | H271: =IF(AND(F271<>"",E271<>""),F271-E271,"") -> 3
A272: 46255 | C272: =_xlfn.XLOOKUP(Log!A272, 'Daily Summary'!A:A, 'Daily Summary'!C:C, "Not found!") -> 0.59305556 | D272: 0.60612269 | E272: 51 | F272: 52 | G272: =IF(AND($D272<>"", $C272<>""), ($D272-$C272)*1440, "") -> 18.816667 | H272: =IF(AND(F272<>"",E272<>""),F272-E272,"") -> 1
A273: 46255 | C273: =_xlfn.XLOOKUP(Log!A273, 'Daily Summary'!A:A, 'Daily Summary'!C:C, "Not found!") -> 0.59305556 | D273: 0.60752315 | E273: 51 | F273: 52 | G273: =IF(AND($D273<>"", $C273<>""), ($D273-$C273)*1440, "") -> 20.833333 | H273: =IF(AND(F273<>"",E273<>""),F273-E273,"") -> 1
A274: 46255 | C274: =_xlfn.XLOOKUP(Log!A274, 'Daily Summary'!A:A, 'Daily Summary'!C:C, "Not found!") -> 0.59305556 | D274: 0.60892361 | E274: 52 | F274: 55 | G274: =IF(AND($D274<>"", $C274<>""), ($D274-$C274)*1440, "") -> 22.85 | H274: =IF(AND(F274<>"",E274<>""),F274-E274,"") -> 3
A275: 46255 | C275: =_xlfn.XLOOKUP(Log!A275, 'Daily Summary'!A:A, 'Daily Summary'!C:C, "Not found!") -> 0.59305556 | D275: 0.6103125 | E275: 54 | F275: 55 | G275: =IF(AND($D275<>"", $C275<>""), ($D275-$C275)*1440, "") -> 24.85 | H275: =IF(AND(F275<>"",E275<>""),F275-E275,"") -> 1
A276: 46255 | C276: =_xlfn.XLOOKUP(Log!A276, 'Daily Summary'!A:A, 'Daily Summary'!C:C, "Not found!") -> 0.59305556 | D276: 0.61171296 | E276: 54 | F276: 55 | G276: =IF(AND($D276<>"", $C276<>""), ($D276-$C276)*1440, "") -> 26.866667 | H276: =IF(AND(F276<>"",E276<>""),F276-E276,"") -> 1
A277: 46255 | C277: =_xlfn.XLOOKUP(Log!A277, 'Daily Summary'!A:A, 'Daily Summary'!C:C, "Not found!") -> 0.59305556 | D277: 0.61311343 | E277: 54 | F277: 55 | G277: =IF(AND($D277<>"", $C277<>""), ($D277-$C277)*1440, "") -> 28.883333 | H277: =IF(AND(F277<>"",E277<>""),F277-E277,"") -> 1
A278: 46255 | C278: =_xlfn.XLOOKUP(Log!A278, 'Daily Summary'!A:A, 'Daily Summary'!C:C, "Not found!") -> 0.59305556 | D278: 0.61450231 | E278: 54 | F278: 58 | G278: =IF(AND($D278<>"", $C278<>""), ($D278-$C278)*1440, "") -> 30.883333 | H278: =IF(AND(F278<>"",E278<>""),F278-E278,"") -> 4
...

Sheet Daily Summary
A1: Key invalid data recorded as non-date instead | B1: Starting Temperature (°C) | C1: Starting Time | D1: Minutes to Ready (earliest minutes >= 50°) | E1: Notes
A2: {=_xlfn.UNIQUE(Log!$A$3:$A$2500)} -> 46228 | B2: 23.5 | C2: 0.78819444 | D2: =IF(C2="", "–", _xlfn.MINIFS(Log!$G$3:$G$2000, Log!$A$3:$A$2000, $A2, Log!$E$3:$E$2000,">=50")) -> 25
A3: 46230 | B3: 23.5 | C3: 0.42916667 | D3: =IF(C3="", "–", _xlfn.MINIFS(Log!$G$3:$G$2000, Log!$A$3:$A$2000, $A3, Log!$E$3:$E$2000,">=50")) -> 24
A4: 46231 | B4: 23.5 | C4: 0.38194444 | D4: =IF(C4="", "–", _xlfn.MINIFS(Log!$G$3:$G$2000, Log!$A$3:$A$2000, $A4, Log!$E$3:$E$2000,">=50")) -> 26
A5: 46232 | B5: 25.5 | C5: 0.73472222 | D5: =IF(C5="", "–", _xlfn.MINIFS(Log!$G$3:$G$2000, Log!$A$3:$A$2000, $A5, Log!$E$3:$E$2000,">=50")) -> 16 | E5: Cameras active 1m faster, at 'ready' temp 6-10m faster, 2° difference appears to have an impact on startup time
A6: 46233 | B6: 24.5 | C6: 0.40972222 | D6: =IF(C6="", "–", _xlfn.MINIFS(Log!$G$3:$G$2000, Log!$A$3:$A$2000, $A6, Log!$E$3:$E$2000,">=50")) -> 19 | E6: Also 2m vs 3m startup - is possible I'm reacting faster to camera startup now I'm used to it or is temperature diff minimal? (Starting at a lower temp would be good data)
A7: 46234 | B7: 24 | C7: 0.43055556 | D7: =IF(C7="", "–", _xlfn.MINIFS(Log!$G$3:$G$2000, Log!$A$3:$A$2000, $A7, Log!$E$3:$E$2000,">=50")) -> 21 | E7: About 2.5min startup
A8: 46235 | B8: 24 | C8: 0.70625 | D8: =IF(C8="", "–", _xlfn.MINIFS(Log!$G$3:$G$2000, Log!$A$3:$A$2000, $A8, Log!$E$3:$E$2000,">=50")) -> 21.583333 | E8: Recording with camera temperature tracking script from this day
A9: 46237 | B9: 23.5 | C9: 0.40972222 | D9: =IF(C9="", "–", _xlfn.MINIFS(Log!$G$3:$G$2000, Log!$A$3:$A$2000, $A9, Log!$E$3:$E$2000,">=50")) -> 21.216667
A10: 46238 | B10: 24.5 | C10: 0.42986111 | D10: =IF(C10="", "–", _xlfn.MINIFS(Log!$G$3:$G$2000, Log!$A$3:$A$2000, $A10, Log!$E$3:$E$2000,">=50")) -> 21.066667 | E10: (tested script against non-active system configs) - on selecting VCS on init, 1 cam active, temp not shown. Mix of auto & manual logs! note - polling errors with camera temp script (window not selected!) time to ready wasn't faster than yesterday despite higher starting temp
A11: 46239 | B11: 24.5 | C11: 0.48333333 | D11: =IF(C11="", "–", _xlfn.MINIFS(Log!$G$3:$G$2000, Log!$A$3:$A$2000, $A11, Log!$E$3:$E$2000,">=50")) -> 19.6 | E11: startup time may be off by 30 seconds, recorded after start
A12: 46240 | B12: 24 | C12: 0.43888889 | D12: =IF(C12="", "–", _xlfn.MINIFS(Log!$G$3:$G$2000, Log!$A$3:$A$2000, $A12, Log!$E$3:$E$2000,">=50")) -> 20.133333
A13: 46242 | B13: 24 | C13: 0.55833333 | D13: =IF(C13="", "–", _xlfn.MINIFS(Log!$G$3:$G$2000, Log!$A$3:$A$2000, $A13, Log!$E$3:$E$2000,">=50")) -> 19.616667
A14: 46244 | B14: 24 | C14: 0.44375 | D14: =IF(C14="", "–", _xlfn.MINIFS(Log!$G$3:$G$2000, Log!$A$3:$A$2000, $A14, Log!$E$3:$E$2000,">=50")) -> 18.85 | E14: Attempted to cool room prior to test but thermostat is locked to 23° range and does not cool room quickly - room temperature used
A15: 46245 | B15: 23.5 | C15: 0.38194444 | D15: =IF(C15="", "–", _xlfn.MINIFS(Log!$G$3:$G$2000, Log!$A$3:$A$2000, $A15, Log!$E$3:$E$2000,">=50")) -> 21.35 | E15: initial recording/camera startup time slightly delayed by interruption
A16: 46246 | B16: 24 | C16: 0.41597222 | D16: =IF(C16="", "–", _xlfn.MINIFS(Log!$G$3:$G$2000, Log!$A$3:$A$2000, $A16, Log!$E$3:$E$2000,">=50")) -> 21.45
A17: 46247 | B17: 24.5 | C17: 0.40972222 | D17: =IF(C17="", "–", _xlfn.MINIFS(Log!$G$3:$G$2000, Log!$A$3:$A$2000, $A17, Log!$E$3:$E$2000,">=50")) -> 19
A18: 46248 | B18: 25 | C18: 0.43472222 | D18: =IF(C18="", "–", _xlfn.MINIFS(Log!$G$3:$G$2000, Log!$A$3:$A$2000, $A18, Log!$E$3:$E$2000,">=50")) -> 17.9
A19: 46251 | B19: 24.5 | C19: 0.55902778 | D19: =IF(C19="", "–", _xlfn.MINIFS(Log!$G$3:$G$2000, Log!$A$3:$A$2000, $A19, Log!$E$3:$E$2000,">=50")) -> 21.483333
A20: 46252 | B20: 24.5 | C20: 0.42708333 | D20: =IF(C20="", "–", _xlfn.MINIFS(Log!$G$3:$G$2000, Log!$A$3:$A$2000, $A20, Log!$E$3:$E$2000,">=50")) -> 19.633333
A21: 46253 | B21: 24.5 | C21: 0.45902778 | D21: =IF(C21="", "–", _xlfn.MINIFS(Log!$G$3:$G$2000, Log!$A$3:$A$2000, $A21, Log!$E$3:$E$2000,">=50")) -> 20.116667
A22: 46254 | B22: 24.5 | C22: 0.54236111 | D22: =IF(C22="", "–", _xlfn.MINIFS(Log!$G$3:$G$2000, Log!$A$3:$A$2000, $A22, Log!$E$3:$E$2000,">=50")) -> 20.883333
A23: 46255 | B23: 23.5 | C23: 0.59305556 | D23: =IF(C23="", "–", _xlfn.MINIFS(Log!$G$3:$G$2000, Log!$A$3:$A$2000, $A23, Log!$E$3:$E$2000,">=50")) -> 18.816667 | E23: lab interruption, delay in starting reader & adjusting window - script read for 12 cameras instead of 18 for several read cycles
A24: 46258 | B24: 23 | C24: 0.49236111 | D24: =IF(C24="", "–", _xlfn.MINIFS(Log!$G$3:$G$2000, Log!$A$3:$A$2000, $A24, Log!$E$3:$E$2000,">=50")) -> 23.766667
A25: 46260 | B25: 23.5 | C25: 0.43472222 | D25: =IF(C25="", "–", _xlfn.MINIFS(Log!$G$3:$G$2000, Log!$A$3:$A$2000, $A25, Log!$E$3:$E$2000,">=50")) -> 21.116667
A26: 0 | D26: =IF(AND(C26<>"", B26<>""), IF(COUNTIFS(Log!$A$3:$A$10007,#REF!,Log!$E$3:$E$10007,">=50")=0,"–",_xlfn.MINIFS(Log!$G$3:$G$10007,Log!$A$3:$A$10007,#REF!,Log!$E$3:$E$10007,">=50")), "")
D27: =IF(AND(C27<>"", B27<>""), IF(COUNTIFS(Log!$A$3:$A$10007,#REF!,Log!$E$3:$E$10007,">=50")=0,"–",_xlfn.MINIFS(Log!$G$3:$G$10007,Log!$A$3:$A$10007,#REF!,Log!$E$3:$E$10007,">=50")), "")
D28: =IF(AND(C28<>"", B28<>""), IF(COUNTIFS(Log!$A$3:$A$10007,#REF!,Log!$E$3:$E$10007,">=50")=0,"–",_xlfn.MINIFS(Log!$G$3:$G$10007,Log!$A$3:$A$10007,#REF!,Log!$E$3:$E$10007,">=50")), "")
D29: =IF(AND(C29<>"", B29<>""), IF(COUNTIFS(Log!$A$3:$A$10007,#REF!,Log!$E$3:$E$10007,">=50")=0,"–",_xlfn.MINIFS(Log!$G$3:$G$10007,Log!$A$3:$A$10007,#REF!,Log!$E$3:$E$10007,">=50")), "")
D30: =IF(AND(C30<>"", B30<>""), IF(COUNTIFS(Log!$A$3:$A$10007,#REF!,Log!$E$3:$E$10007,">=50")=0,"–",_xlfn.MINIFS(Log!$G$3:$G$10007,Log!$A$3:$A$10007,#REF!,Log!$E$3:$E$10007,">=50")), "")
D31: =IF(AND(C31<>"", B31<>""), IF(COUNTIFS(Log!$A$3:$A$10007,#REF!,Log!$E$3:$E$10007,">=50")=0,"–",_xlfn.MINIFS(Log!$G$3:$G$10007,Log!$A$3:$A$10007,#REF!,Log!$E$3:$E$10007,">=50")), "")
D32: =IF(AND(C32<>"", B32<>""), IF(COUNTIFS(Log!$A$3:$A$10007,#REF!,Log!$E$3:$E$10007,">=50")=0,"–",_xlfn.MINIFS(Log!$G$3:$G$10007,Log!$A$3:$A$10007,#REF!,Log!$E$3:$E$10007,">=50")), "")
D33: =IF(AND(C33<>"", B33<>""), IF(COUNTIFS(Log!$A$3:$A$10007,#REF!,Log!$E$3:$E$10007,">=50")=0,"–",_xlfn.MINIFS(Log!$G$3:$G$10007,Log!$A$3:$A$10007,#REF!,Log!$E$3:$E$10007,">=50")), "")
D34: =IF(AND(C34<>"", B34<>""), IF(COUNTIFS(Log!$A$3:$A$10007,#REF!,Log!$E$3:$E$10007,">=50")=0,"–",_xlfn.MINIFS(Log!$G$3:$G$10007,Log!$A$3:$A$10007,#REF!,Log!$E$3:$E$10007,">=50")), "")
D35: =IF(AND(C35<>"", B35<>""), IF(COUNTIFS(Log!$A$3:$A$10007,#REF!,Log!$E$3:$E$10007,">=50")=0,"–",_xlfn.MINIFS(Log!$G$3:$G$10007,Log!$A$3:$A$10007,#REF!,Log!$E$3:$E$10007,">=50")), "")
D36: =IF(AND(C36<>"", B36<>""), IF(COUNTIFS(Log!$A$3:$A$10007,#REF!,Log!$E$3:$E$10007,">=50")=0,"–",_xlfn.MINIFS(Log!$G$3:$G$10007,Log!$A$3:$A$10007,#REF!,Log!$E$3:$E$10007,">=50")), "")
D37: =IF(AND(C37<>"", B37<>""), IF(COUNTIFS(Log!$A$3:$A$10007,#REF!,Log!$E$3:$E$10007,">=50")=0,"–",_xlfn.MINIFS(Log!$G$3:$G$10007,Log!$A$3:$A$10007,#REF!,Log!$E$3:$E$10007,">=50")), "")
D38: =IF(AND(C38<>"", B38<>""), IF(COUNTIFS(Log!$A$3:$A$10007,#REF!,Log!$E$3:$E$10007,">=50")=0,"–",_xlfn.MINIFS(Log!$G$3:$G$10007,Log!$A$3:$A$10007,#REF!,Log!$E$3:$E$10007,">=50")), "")
... D98: =IF(AND(C98<>"", B98<>""), IF(COUNTIFS(Log!$A$3:$A$10007,#REF!,Log!$E$3:$E$10007,">=50")=0,"–",_xlfn.MINIFS(Log!$G$3:$G$10007,Log!$A$3:$A$10007,#REF!,Log!$E$3:$E$10007,">=50")), "")

Sheet Visualisations
K19: Next chart - camera temperature at time (avg. between low/high no error data) cross-referenced against starting temperature
C22: Note on above chart: from 01/08 tracked by script not manual
C23: Earlier recordings are not as granular & have irregular time steps | K23: Need to recalculate 'Camera temperature vs minutes since start' ,
K24: Not clearly useful data and manually adding series daily is time-consuming
C25: What other charts to plot from this data?
C26: Measuring initial camera temperature against room/startup?

Sheet DevScriptErrors
A1: This is a dev troubleshooting record for the camera temperature script, checking which cameras are dropped from readings
A2: Cameras Missing from Temperature Script Log
A3: Date | B3: Camera by ID | C3: {=LEFT(TRANSPOSE(#REF!), 3)} -> #REF!
A4: 46238 | C4: 5 | D4: 5 | E4: 2 | F4: 2 | G4: 2 | H4: 2 | I4: 2 | J4: 2 | K4: 2 | R4: 1 | S4: 1 | T4: 2 | W4: (04/08 is first day recording these errors)
A8: no longer tracking - bug fixed
